Workbook

Sheet Yoriqnoma
A1: YO‘RIQNOMA / ИНСТРУКЦИЯ — Doya kabineti (QVP / oilaviy poliklinika)
A2: Кабинет доя (СВП / семейная поликлиника)
A3: MAXFIY / КОНФИДЕНЦИАЛЬНО — bu fayl shaxsiy va tibbiy ma’lumotlarni saqlaydi (shifokorlik siri). Faqat o‘zingizda saqlang, parol qo‘ying; o‘rinbosarga FAQAT «Chop_etish» varag‘i (qog‘oz) va «Eksport» qatori (yig‘ma sonlar) topshiriladi. / Файл хранит персональные и медицинские данные (врачебная тайна). Храните у себя, поставьте пароль; заместителю сдаются ТОЛЬКО лист «Chop_etish» (бумага) и строка «Eksport» (агрегаты).
B4: Kim to‘ldiradi / Кто заполняет | C4: Doya kabineti (QVP / oilaviy poliklinika) / Кабинет доя (СВП / семейная поликлиника)
B5: Kimga topshiriladi / Кому сдаётся | C5: Birlashma boshlig'ining onalik va bolalikni muhofaza qilish bo'yicha o'rinbosari / Заместитель начальника объединения по охране материнства и детства
B6: Muddat / Срок | C6: Har hafta juma kuni soat 12:00 gacha / каждую пятницу до 12:00
B7: Papkalar / Папки | C7: № 3, 7, 8, 9, 10, 11, 12
A9: 1. Qanday ishlash kerak / Как работать
A10: № | B10: Qadam / Шаг | C10: O‘zbekcha (lotin) | D10: Русский
A11: 1 | B11: Ayollarni bir marta yozing | C11: Yangi homilador — «Homiladorlar» varag‘iga; uchastkadagi boshqa ayollar — «Fertil_ayollar»ga; dispanser, nogiron — o‘z varag‘iga. F.I.Sh. va tug‘ilgan sanani yozing. | D11: Новую беременную — на лист «Homiladorlar»; остальных женщин участка — в «Fertil_ayollar»; диспансерных и инвалидов — на свои листы. Впишите ФИО и дату рождения.
A12: 2 | B12: Diagnozni hujjatdan ko‘chiring | C12: Xavf guruhi, diagnoz va MKB-10 — faqat davolovchi shifokor hujjatidan; hujjat raqami va shifokor F.I.Sh.ni yozing. | D12: Группа риска, диагноз и МКБ-10 — только из документа лечащего врача; укажите № документа и ФИО врача.
A13: 3 | B13: Har kuni va har tashrifda yozing | C13: Qabul kuni — «Qabul_jurnali»; patronaj — «Patronaj»; skrining — «Skrining»; uyga borish — «Nogiron_yordam»; suhbat — «Targibot». Ayolni ro‘yxatdan tanlang. | D13: Приём — «Qabul_jurnali»; патронаж — «Patronaj»; скрининг — «Skrining»; выезд на дом — «Nogiron_yordam»; беседа — «Targibot». Женщину выбирайте из списка.
A14: 4 | B14: Qizil qatorlar | C14: Qizil qator — ko‘rik/tashrif muddati o‘tgan ayol: unga bog‘laning. «Xavfli_homiladorlar» va «Voyaga_yetmaganlar» ro‘yxatlari o‘zi to‘ladi. | D14: Красная строка — просрочен осмотр/визит: свяжитесь с женщиной. Списки «Xavfli_homiladorlar» и «Voyaga_yetmaganlar» заполняются сами.
A15: 5 | B15: «Boshqaruv» varag‘i | C15: Davr boshi va oxirini (C9, C10), muassasa va F.I.Sh.ni kiriting. Ko‘rsatkichlar jurnallardan o‘zi hisoblanadi; sariq ko‘rsatkichlarni qo‘lda kiriting. «TAYYORLIK» qatori «✔ TAYYOR» bo‘lishi kerak. | D15: Введите начало и конец периода (C9, C10), учреждение и ФИО. Показатели считаются сами из журналов; жёлтые показатели введите вручную. Строка «ГОТОВНОСТЬ» должна показать «✔ ГОТОВО».
A16: 6 | B16: «Chop_etish» varag‘i | C16: A4 qog‘ozga bir bet qilib chop eting, «Tayyorladi»ga imzo qo‘ying, rahbarga imzolating, M.O. joyiga muhr bosdiring. Qog‘ozdagi raqamlar Excel bilan bir xil bo‘lsin. | D16: Распечатайте на одном листе А4, подпишите («Подготовил(а)»), заверьте у руководителя и поставьте печать в поле М.П. Цифры на бумаге должны совпадать с Excel.
A17: 7 | B17: «Eksport» qatori va yuborish | C17: «Eksport» varag‘ining 4-qatori — yig‘ma sonlar (shaxsiy ma’lumotsiz). Faylni EMAS, faqat shu qatorni (yoki «Chop_etish»ni) yuboring. Fayl nomi: Rol_Muassasa_Davr.xlsx. | D17: Строка 4 листа «Eksport» — агрегированные числа (без персональных данных). Отправляйте не файл, а только эту строку (или «Chop_etish»). Имя файла: Роль_Учреждение_Период.xlsx.
A19: 2. Varaqlar va jurnallar / Листы и журналы
A20: № | B20: Varaq / Лист | C20: Nima uchun / Для чего (uz) | D20: Для чего (ru)
A21: 1 | B21: Homiladorlar | C21: Uchastkadagi barcha homilador va tuqqan ayollar: kim, qachon hisobga olingan, xavf guruhi, diagnoz (hujjat bo‘yicha), ko‘riklar, skrining. Ko‘rsatkichlar 1–4, 14, 15, 18, 24, 25 shundan hisoblanadi. | D21: Все беременные и родильницы участка: кто, когда взята на учёт, группа риска, диагноз (по документам), осмотры, скрининг. Показатели 1–4, 14, 15, 18, 24, 25 считаются отсюда.
A22: 2 | B22: Xavfli_homiladorlar | C22: Xavf guruhidagi homiladorlar ro‘yxati (ism, diagnoz, ko‘rik muddati) — avtomatik; qog‘ozga chiqarish mumkin. | D22: Список беременных группы риска (ФИО, диагноз, сроки осмотра) — автоматически; можно печатать.
A23: 3 | B23: Voyaga_yetmaganlar | C23: 18 yoshgacha homiladorlar ro‘yxati — avtomatik. | D23: Список беременных до 18 лет — автоматически.
A24: 4 | B24: Fertil_ayollar | C24: Uchastka ayollari ro‘yxati: tug‘ish yoshidagilar soni (5), kontratseptiv qo‘llayotganlar (6), qamrab olish choralari (17). | D24: Список женщин участка: число женщин фертильного возраста (5), использующих контрацепцию (6), меры по охвату (17).
A25: 5 | B25: Dispanser | C25: Dispanser nazoratidagi ayollar va o‘smir qizlar (ko‘rsatkichlar 7, 8): diagnoz, sog‘lomlashtirish rejasi, ko‘rik muddati. | D25: Женщины и девочки-подростки на диспансерном учёте (показатели 7, 8): диагноз, план оздоровления, сроки осмотров.
A26: 6 | B26: Nogiron_ayollar | C26: Uchastkadagi nogiron ayollar (ko‘rsatkich 9). Uyga borib ko‘rsatilgan yordam «Nogiron_yordam» varag‘ida yoziladi. | D26: Женщины-инвалиды участка (показатель 9). Выезды с помощью на дом записываются на листе «Nogiron_yordam».
A27: 7 | B27: Nogiron_yordam | C27: Har bir uyga borish yozuvi: sana, qaysi ayol, qanday yordam, dalolatnoma raqami (ko‘rsatkich 10). | D27: Журнал выездов на дом: дата, женщина, вид помощи, № акта (показатель 10).
A28: 8 | B28: Patronaj | C28: Patronaj tashriflari: sana, ayol, turi, universal-progressiv patronajmi. Ko‘rsatkichlar 11 va 13 shundan hisoblanadi (13 — har bir ayol bir marta). | D28: Патронажные посещения: дата, женщина, тип, универсально-прогрессивный ли. Показатели 11 и 13 считаются отсюда (13 — каждая женщина один раз).
A29: 9 | B29: Skrining | C29: Saraton skriningi: kim, qachon, qaysi tur, natija, xavf guruhimi. Ko‘rsatkichlar 16, 22, 23 shundan hisoblanadi. | D29: Скрининг рака: кто, когда, какой вид, результат, группа риска ли. Показатели 16, 22, 23 считаются отсюда.
A30: 10 | B30: Qabul_jurnali | C30: Qabul kunlari: rejalashtirilgan va haqiqiy tashriflar (ko‘rsatkichlar 19–21, reja bajarilishi % avtomatik). | D30: Дни приёма: запланированные и фактические визиты (показатели 19–21, % выполнения плана — авто).
A31: 11 | B31: Targibot | C31: Targ‘ibot suhbatlari (ko‘rsatkich 12) va «Qizlar salomatlik markazi» bilan tadbirlar (27). | D31: Пропагандистские беседы (показатель 12) и мероприятия с «Центром здоровья девочек» (27).
A32: 12 | B32: Qizlar_maslahat | C32: Reproduktiv salomatlik bo‘yicha maslahat olgan 15–17 yoshli qizlar (ko‘rsatkich 26). | D32: Девочки 15–17 лет, получившие консультацию по репродуктивному здоровью (показатель 26).
... A36: 16 | B36: Eksport | C36: O‘rinbosarga yuboriladigan bir qator. | D36: Строка для отправки заместителю.
A38: 3. Qoidalar / Правила
A39: № | B39: Qoida / Правило | C39: O‘zbekcha (lotin) | D39: Русский
A40: 1 | B40: Ranglar | C40: Sariq katak — kiritiladi. Yashil — avtomatik (tegmang). Kulrang — yordamchi ustun. Qizil — xato/muddat o‘tgan. Ustun sarlavhasi: ko‘k — kiritish, yashil — avtomatik. | D40: Жёлтая — ввод. Зелёная — авто (не трогать). Серая — вспомогательная. Красная — ошибка/просрочка. Заголовок: синий — ввод, зелёный — авто.
A41: 2 | B41: Bir marta yozing | C41: Har bir shaxs/hodisa bitta qatorga yoziladi; takror yozuv qizil bo‘ladi. Sanani kun.oy.yil ko‘rinishida kiriting. | D41: Каждый человек/событие — одна строка; дубль подсвечивается красным. Даты вводите как дд.мм.гггг.
A42: 3 | B42: Tashxis va xavf | C42: Tashxis va xavf sababini faqat davolovchi shifokor hujjatidan (karta, xulosa) ko‘chiring — o‘zingizdan yozmang; hujjat raqamini ham yozing. | D42: Диагноз и причину риска переписывайте только из документа лечащего врача (карта, заключение), не от себя; укажите № документа.
A43: 4 | B43: Maxfiylik | C43: Fayl faqat sizda; guruhga yubormang. PINFL — 14 ta raqam, «PINFL» ustuniga; faylni parol bilan himoyalang. Yig‘ma ma’lumot — «Eksport» va «Chop_etish». | D43: Файл только у вас; в группы не отправлять. ПИНФЛ — 14 цифр, в столбец «ПИНФЛ»; защитите файл паролем. Агрегаты — «Eksport» и «Chop_etish».
A44: 5 | B44: Nusxa | C44: Har oy oxirida faylning zaxira nusxasini saqlang (Fayl → Boshqacha saqlash). | D44: В конце каждого месяца сохраняйте резервную копию файла.
A45: 6 | B45: Eng ko‘p xatolar | C45: Sanani matn qilib yozish; yashil katakni o‘zgartirish; ro‘yxatdan tashqari qiymat; davrni (C9, C10) kiritmaslik; qog‘oz va Excel raqamlari mos kelmasligi; imzo/muhrsiz topshirish. | D45: Дата текстом; правка зелёных ячеек; значение не из списка; не введён период (C9, C10); цифры на бумаге и в Excel не совпадают; сдача без подписи/печати.
A47: 4. Eslatmalar / Примечания
...

Sheet Boshqaruv
A1: BOSHQARUV VA KO‘RSATKICHLAR / УПРАВЛЕНИЕ И ПОКАЗАТЕЛИ — Doya kabineti (QVP / oilaviy poliklinika)
A2: Кабинет доя (СВП / семейная поликлиника)
A3: Bu yerda faqat davr va ma’lumotlarni kiriting; ko‘rsatkichlar jurnallardan O‘ZI hisoblanadi (yashil). Sariq katak — qo‘lda kiritiladi. / Здесь вводятся период и реквизиты; показатели считаются САМИ из журналов (зелёные). Жёлтая ячейка — вводится вручную.
B5: Muassasa (nomi, №) / Учреждение | C5: СВП №3 (тест)
B6: F.I.Sh. (to‘ldiruvchi) / Ф.И.О. (заполняющий) | C6: Тестова Дильфуза
B7: Lavozimi / Должность | C7: Doya (QVP / oilaviy poliklinika) / Доя (СВП)
B8: Telefon / Телефон | C8: +998900000001
B9: Davr boshi (sana) / Начало периода (дата) | C9: 46311 | D9: ← masalan / напр.: 01.09.2026
B10: Davr oxiri (sana) / Конец периода (дата) | C10: 46318 | D10: ← masalan / напр.: 30.09.2026
B11: Davr (avto) / Период (авто) | C11: =IF(OR(C9="",C10=""),"",DAY(C9)&"."&MONTH(C9)&"."&YEAR(C9)&" – "&DAY(C10)&"."&MONTH(C10)&"."&YEAR(C10)) -> 16.10.2026 – 23.10.2026
B12: Hisob sanasi (avto: davr oxiri, bo‘sh bo‘lsa — bugun) / Дата расчёта (авто: конец периода, иначе сегодня) | C12: =IF(C10="",TODAY(),C10) -> 46318
B13: TAYYORLIK / ГОТОВНОСТЬ | C13: =IF(IF(OR(C9="",C10=""),"davrni kiriting (C9, C10); ","")&IF(AND(C9<>"",C10<>"",C10<C9),"davr oxiri boshidan oldin; ","")&IF(OR(C5="",C6=""),"muassasa va F.I.Sh.; ","")&IF(SUM(D47,D48,D49,D50,D52,D53,D56,D57,D60,D61,D62,D63,D64,D66,D67,D68,D69,D71)>0,"jurnallarda xatolar bor (pastga qarang); ","")="","✔ TAYYOR / ГОТОВО","✖ TO‘LIQ EMAS / НЕ ПОЛНО: "&IF(OR(C9="",C10=""),"davrni kiriting (C9, C10); ","")&IF(AND(C9<>"",C10<>"",C10<C9),"davr oxiri boshidan oldin; ","")&IF(OR(C5="",C6=""),"muassasa va F.I.Sh.; ","")&IF(SUM(D47,D48,D49,D50,D52,D53,D56,D57,D60,D61,D62,D63,D64,D66,D67,D68,D69,D71)>0,"jurnallarda xatolar bor (pastga qarang); ","")) -> ✖ TO‘LIQ EMAS / НЕ ПОЛНО: jurnallarda xatolar bor (pastga qarang);
B14: HUJJATLAR / ДОКУМЕНТЫ | C14: =IF(COUNTBLANK(Hujjatlar!E5:E19)=0,"✔ Hammasi belgilangan / Всё отмечено","✖ Hujjatlar varag‘ida belgilanmagan: "&COUNTBLANK(Hujjatlar!E5:E19)&" ta") -> ✖ Hujjatlar varag‘ida belgilanmagan: 15 ta
A16: T/r | B16: Ko‘rsatkich | C16: Показатель | D16: Birlik | E16: Papka | F16: Qiymat / Значение | G16: Manba / Источник и как считается
A17: 1 | B17: Hisobdagi homilador ayollar soni | C17: Число беременных на учёте | D17: nafar | E17: 10 | F17: =IF(OR(Boshqaruv!$C$9="",Boshqaruv!$C$10=""),"",(COUNTIFS(Homiladorlar!$I$5:$I$404,"<="&Boshqaruv!$C$10,Homiladorlar!$AG$5:$AG$404,"")+COUNTIFS(Homiladorlar!$I$5:$I$404,"<="&Boshqaruv!$C$10,Homiladorlar!$AG$5:$AG$404,">"&Boshqaruv!$C$10))) -> 12 | G17: AVTOMATIK: «Homiladorlar»: davr oxiriga hisobda turgan homiladorlar (hisobga olingan ≤ davr oxiri, chiqish sanasi yo‘q yoki undan keyin). / АВТОМАТИЧЕСКИ: «Homiladorlar»: состоящие на учёте на конец периода (взята ≤ конца периода, нет даты выбытия или она позже).
A18: 2 | B18: Shundan 12 haftagacha hisobga olinganlar | C18: Из них взято на учёт до 12 недель | D18: nafar | E18: 10 | F18: =IF(OR(Boshqaruv!$C$9="",Boshqaruv!$C$10=""),"",(COUNTIFS(Homiladorlar!$I$5:$I$404,"<="&Boshqaruv!$C$10,Homiladorlar!$AG$5:$AG$404,"",Homiladorlar!$N$5:$N$404,"Ha")+COUNTIFS(Homiladorlar!$I$5:$I$404,"<="&Boshqaruv!$C$10,Homiladorlar!$AG$5:$AG$404,">"&Boshqaruv!$C$10,Homiladorlar!$N$5:$N$404,"Ha"))) -> 12 | G18: AVTOMATIK: «Homiladorlar»: shundan «12 haftagacha hisobga olingan = Ha». / АВТОМАТИЧЕСКИ: «Homiladorlar»: из них «взята до 12 нед. = Ha».
A19: 3 | B19: Erta hisobga olish ulushi | C19: Доля раннего учёта | D19: % | E19: 10 | F19: =IF(OR(Boshqaruv!$C$9="",Boshqaruv!$C$10=""),"",IF(N($F$17)=0,"",$F$18/$F$17)) -> 1 | G19: AVTOMATIK: 2-qator / 1-qator. / АВТОМАТИЧЕСКИ: Строка 2 / строка 1.
A20: 4 | B20: Xavf guruhidagi homiladorlar | C20: Беременные группы риска | D20: nafar | E20: 7 | F20: =IF(OR(Boshqaruv!$C$9="",Boshqaruv!$C$10=""),"",(COUNTIFS(Homiladorlar!$I$5:$I$404,"<="&Boshqaruv!$C$10,Homiladorlar!$AG$5:$AG$404,"",Homiladorlar!$Q$5:$Q$404,"Ha")+COUNTIFS(Homiladorlar!$I$5:$I$404,"<="&Boshqaruv!$C$10,Homiladorlar!$AG$5:$AG$404,">"&Boshqaruv!$C$10,Homiladorlar!$Q$5:$Q$404,"Ha"))) -> 4 | G20: AVTOMATIK: «Homiladorlar»: xavf guruhi = Ha (davr oxiriga hisobda). / АВТОМАТИЧЕСКИ: «Homiladorlar»: группа риска = Ha (на учёте на конец периода).
A21: 5 | B21: Tug'ish yoshidagi ayollar soni (uchastkada) | C21: Женщин фертильного возраста на участке | D21: nafar | E21: 13 | F21: =IF(OR(Boshqaruv!$C$9="",Boshqaruv!$C$10=""),"",(COUNTIFS(Fertil_ayollar!$B$5:$B$2504,"<>",Fertil_ayollar!$K$5:$K$2504,"",Fertil_ayollar!$L$5:$L$2504,"",Fertil_ayollar!$I$5:$I$2504,"Ha")+COUNTIFS(Fertil_ayollar!$B$5:$B$2504,"<>",Fertil_ayollar!$K$5:$K$2504,"",Fertil_ayollar!$L$5:$L$2504,">"&Boshqaruv!$C$10,Fertil_ayollar!$I$5:$I$2504,"Ha")+COUNTIFS(Fertil_ayollar!$B$5:$B$2504,"<>",Fertil_ayollar!$K$5:$K$2504,"<="&Boshqaruv!$C$10,Fertil_ayollar!$L$5:$L$2504,"",Fertil_ayollar!$I$5:$I$2504,"Ha")+COUNTIFS(Fertil_ayollar!$B$5:$B$2504,"<>",Fertil_ayollar!$K$5:$K$2504,"<="&Boshqaruv!$C$10,Fertil_ayollar!$L$5:$L$2504,">"&Boshqaruv!$C$10,Fertil_ayollar!$I$5:$I$2504,"Ha"))) -> 0 | G21: AVTOMATIK: «Fertil_ayollar»: 15–49 yoshdagi ayollar (davr oxiriga yosh). / АВТОМАТИЧЕСКИ: «Fertil_ayollar»: женщины 15–49 лет (возраст на конец периода).
A22: 6 | B22: Kontratseptiv qo'llayotgan ayollar | C22: Женщины, использующие контрацептивы | D22: nafar | E22: 12 | F22: =IF(OR(Boshqaruv!$C$9="",Boshqaruv!$C$10=""),"",(COUNTIFS(Fertil_ayollar!$B$5:$B$2504,"<>",Fertil_ayollar!$N$5:$N$2504,"",Fertil_ayollar!$O$5:$O$2504,"",Fertil_ayollar!$I$5:$I$2504,"Ha",Fertil_ayollar!$M$5:$M$2504,"<>")+COUNTIFS(Fertil_ayollar!$B$5:$B$2504,"<>",Fertil_ayollar!$N$5:$N$2504,"",Fertil_ayollar!$O$5:$O$2504,">"&Boshqaruv!$C$10,Fertil_ayollar!$I$5:$I$2504,"Ha",Fertil_ayollar!$M$5:$M$2504,"<>")+COUNTIFS(Fertil_ayollar!$B$5:$B$2504,"<>",Fertil_ayollar!$N$5:$N$2504,"<="&Boshqaruv!$C$10,Fertil_ayollar!$O$5:$O$2504,"",Fertil_ayollar!$I$5:$I$2504,"Ha",Fertil_ayollar!$M$5:$M$2504,"<>")+COUNTIFS(Fertil_ayollar!$B$5:$B$2504,"<>",Fertil_ayollar!$N$5:$N$2504,"<="&Boshqaruv!$C$10,Fertil_ayollar!$O$5:$O$2504,">"&Boshqaruv!$C$10,Fertil_ayollar!$I$5:$I$2504,"Ha",Fertil_ayollar!$M$5:$M$2504,"<>"))) -> 0 | G22: AVTOMATIK: «Fertil_ayollar»: usuli tanlangan, to‘xtatilmagan (boshlangan ≤ davr oxiri). / АВТОМАТИЧЕСКИ: «Fertil_ayollar»: метод выбран, не прекращён (начало ≤ конца периода).
A23: 7 | B23: Dispanser hisobidagi ayollar | C23: Женщины на диспансерном учёте | D23: nafar | E23: 9 | F23: =IF(OR(Boshqaruv!$C$9="",Boshqaruv!$C$10=""),"",(COUNTIFS(Dispanser!$B$5:$B$304,"<>",Dispanser!$M$5:$M$304,"",Dispanser!$S$5:$S$304,"",Dispanser!$I$5:$I$304,"Ayol")+COUNTIFS(Dispanser!$B$5:$B$304,"<>",Dispanser!$M$5:$M$304,"",Dispanser!$S$5:$S$304,">"&Boshqaruv!$C$10,Dispanser!$I$5:$I$304,"Ayol")+COUNTIFS(Dispanser!$B$5:$B$304,"<>",Dispanser!$M$5:$M$304,"<="&Boshqaruv!$C$10,Dispanser!$S$5:$S$304,"",Dispanser!$I$5:$I$304,"Ayol")+COUNTIFS(Dispanser!$B$5:$B$304,"<>",Dispanser!$M$5:$M$304,"<="&Boshqaruv!$C$10,Dispanser!$S$5:$S$304,">"&Boshqaruv!$C$10,Dispanser!$I$5:$I$304,"Ayol"))) -> 0 | G23: AVTOMATIK: «Dispanser»: toifa = Ayol, hisobda. / АВТОМАТИЧЕСКИ: «Dispanser»: категория = Ayol, на учёте.
A24: 8 | B24: Dispanser hisobidagi o'smir qizlar | C24: Девочки-подростки на диспансерном учёте | D24: nafar | E24: 9 | F24: =IF(OR(Boshqaruv!$C$9="",Boshqaruv!$C$10=""),"",(COUNTIFS(Dispanser!$B$5:$B$304,"<>",Dispanser!$M$5:$M$304,"",Dispanser!$S$5:$S$304,"",Dispanser!$I$5:$I$304,"O'smir qiz")+COUNTIFS(Dispanser!$B$5:$B$304,"<>",Dispanser!$M$5:$M$304,"",Dispanser!$S$5:$S$304,">"&Boshqaruv!$C$10,Dispanser!$I$5:$I$304,"O'smir qiz")+COUNTIFS(Dispanser!$B$5:$B$304,"<>",Dispanser!$M$5:$M$304,"<="&Boshqaruv!$C$10,Dispanser!$S$5:$S$304,"",Dispanser!$I$5:$I$304,"O'smir qiz")+COUNTIFS(Dispanser!$B$5:$B$304,"<>",Dispanser!$M$5:$M$304,"<="&Boshqaruv!$C$10,Dispanser!$S$5:$S$304,">"&Boshqaruv!$C$10,Dispanser!$I$5:$I$304,"O'smir qiz"))) -> 0 | G24: AVTOMATIK: «Dispanser»: toifa = O‘smir qiz, hisobda. / АВТОМАТИЧЕСКИ: «Dispanser»: категория = O‘smir qiz, на учёте.
A25: 9 | B25: Nogiron ayollar soni | C25: Число женщин-инвалидов | D25: nafar | E25: 8 | F25: =IF(OR(Boshqaruv!$C$9="",Boshqaruv!$C$10=""),"",(COUNTIFS(Nogiron_ayollar!$B$5:$B$124,"<>",Nogiron_ayollar!$J$5:$J$124,"",Nogiron_ayollar!$K$5:$K$124,"")+COUNTIFS(Nogiron_ayollar!$B$5:$B$124,"<>",Nogiron_ayollar!$J$5:$J$124,"",Nogiron_ayollar!$K$5:$K$124,">"&Boshqaruv!$C$10)+COUNTIFS(Nogiron_ayollar!$B$5:$B$124,"<>",Nogiron_ayollar!$J$5:$J$124,"<="&Boshqaruv!$C$10,Nogiron_ayollar!$K$5:$K$124,"")+COUNTIFS(Nogiron_ayollar!$B$5:$B$124,"<>",Nogiron_ayollar!$J$5:$J$124,"<="&Boshqaruv!$C$10,Nogiron_ayollar!$K$5:$K$124,">"&Boshqaruv!$C$10))) -> 0 | G25: AVTOMATIK: «Nogiron_ayollar»: ro‘yxatda turganlar. / АВТОМАТИЧЕСКИ: «Nogiron_ayollar»: состоящие в списке.
A26: 10 | B26: Nogiron ayollarga uyga borib ko'rsatilgan yordam | C26: Выезды к женщинам-инвалидам | D26: marta | E26: 8 | F26: =IF(OR(Boshqaruv!$C$9="",Boshqaruv!$C$10=""),"",COUNTIFS(Nogiron_yordam!$B$5:$B$504,">="&Boshqaruv!$C$9,Nogiron_yordam!$B$5:$B$504,"<="&Boshqaruv!$C$10,Nogiron_yordam!$C$5:$C$504,"<>")) -> 0 | G26: AVTOMATIK: «Nogiron_yordam»: davrdagi borishlar soni. / АВТОМАТИЧЕСКИ: «Nogiron_yordam»: число выездов за период.
A27: 11 | B27: Patronaj tashriflari (homilador va tuqqan ayollar) | C27: Патронажные посещения (беременные и родильницы) | D27: marta | E27: 7 | F27: =IF(OR(Boshqaruv!$C$9="",Boshqaruv!$C$10=""),"",COUNTIFS(Patronaj!$B$5:$B$1504,">="&Boshqaruv!$C$9,Patronaj!$B$5:$B$1504,"<="&Boshqaruv!$C$10,Patronaj!$C$5:$C$1504,"<>")) -> 0 | G27: AVTOMATIK: «Patronaj»: davrdagi tashriflar soni. / АВТОМАТИЧЕСКИ: «Patronaj»: число посещений за период.
A28: 12 | B28: Targ'ibot suhbatlari (kontratseptsiya, sog'lom turmush) | C28: Беседы-пропаганда (контрацепция, ЗОЖ) | D28: marta | E28: 10 | F28: =IF(OR(Boshqaruv!$C$9="",Boshqaruv!$C$10=""),"",COUNTIFS(Targibot!$B$5:$B$304,">="&Boshqaruv!$C$9,Targibot!$B$5:$B$304,"<="&Boshqaruv!$C$10,Targibot!$C$5:$C$304,"Targ'ibot suhbati")) -> 0 | G28: AVTOMATIK: «Targibot»: turi = Targ‘ibot suhbati, davrda. / АВТОМАТИЧЕСКИ: «Targibot»: вид = Targ‘ibot suhbati, за период.
A29: 13 | B29: Universal-progressiv patronaj bilan qamrab olingan homilador va tuqqan ayollar | C29: Охвачено универсально-прогрессивным патронажем беременных и родильниц | D29: nafar | E29: 10 | F29: =IF(OR(Boshqaruv!$C$9="",Boshqaruv!$C$10=""),"",COUNTIFS(Patronaj!$L$5:$L$1504,1)) -> 0 | G29: AVTOMATIK: «Patronaj»: universal-progressiv = Ha bo‘lgan ayollar (har biri 1 marta). / АВТОМАТИЧЕСКИ: «Patronaj»: женщины с УПП = Ha (каждая один раз). [Asos: 263-son buyruq (2022), doya vazifalari]
A30: 14 | B30: Antenatal ko‘rikka yo‘llangan homiladorlar | C30: Направлено беременных на антенатальные осмотры | D30: nafar | E30: 10 | F30: =IF(OR(Boshqaruv!$C$9="",Boshqaruv!$C$10=""),"",COUNTIFS(Homiladorlar!$Y$5:$Y$404,">="&Boshqaruv!$C$9,Homiladorlar!$Y$5:$Y$404,"<="&Boshqaruv!$C$10,Homiladorlar!$B$5:$B$404,"<>")) -> 0 | G30: AVTOMATIK: «Homiladorlar»: antenatal ko‘rikka yo‘llangan sana davrda. / АВТОМАТИЧЕСКИ: «Homiladorlar»: дата направления на антенат. осмотр в периоде. [Asos: 263-son buyruq (2022), doya vazifalari]
A31: 15 | B31: Prenatal skriningdan o‘z vaqtida o‘tgan homiladorlar | C31: Прошли пренатальный скрининг в срок | D31: nafar | E31: 11 | F31: =IF(OR(Boshqaruv!$C$9="",Boshqaruv!$C$10=""),"",COUNTIFS(Homiladorlar!$Z$5:$Z$404,">="&Boshqaruv!$C$9,Homiladorlar!$Z$5:$Z$404,"<="&Boshqaruv!$C$10,Homiladorlar!$AB$5:$AB$404,"Ha")) -> 0 | G31: AVTOMATIK: «Homiladorlar»: skrining sanasi davrda va muddat oynasida (parametr: Spravochnik). / АВТОМАТИЧЕСКИ: «Homiladorlar»: дата скрининга в периоде и в окне сроков (параметр на Spravochnik). [Asos: 263-son buyruq (2022), doya vazifalari]
A32: 16 | B32: Xavf guruhidagi ayollardan skrining ko‘rigidan o‘tganlar | C32: Женщин группы риска, прошедших скрининг-осмотр | D32: nafar | E32: 9 | F32: =IF(OR(Boshqaruv!$C$9="",Boshqaruv!$C$10=""),"",COUNTIFS(Skrining!$B$5:$B$1504,">="&Boshqaruv!$C$9,Skrining!$B$5:$B$1504,"<="&Boshqaruv!$C$10,Skrining!$M$5:$M$1504,"Ha")) -> 0 | G32: AVTOMATIK: «Skrining»: xavf guruhi = Ha, davrda. / АВТОМАТИЧЕСКИ: «Skrining»: группа риска = Ha, за период. [Asos: 263-son buyruq (2022), doya vazifalari]
A33: 17 | B33: Kontratseptiv bilan qamrab olish choralari ko‘rilgan fertil yoshdagi ayollar | C33: Женщин фертильного возраста, охваченных мерами по контрацепции | D33: nafar | E33: 12 | F33: =IF(OR(Boshqaruv!$C$9="",Boshqaruv!$C$10=""),"",COUNTIFS(Fertil_ayollar!$S$5:$S$2504,">="&Boshqaruv!$C$9,Fertil_ayollar!$S$5:$S$2504,"<="&Boshqaruv!$C$10,Fertil_ayollar!$B$5:$B$2504,"<>",Fertil_ayollar!$I$5:$I$2504,"Ha")) -> 0 | G33: AVTOMATIK: «Fertil_ayollar»: qamrab olish chorasi sanasi davrda (15–49 yosh). / АВТОМАТИЧЕСКИ: «Fertil_ayollar»: дата меры по охвату в периоде (15–49 лет). [Asos: 263-son buyruq (2022), doya vazifalari]
A34: 18 | B34: Xavf omillari aniqlanib, individual kuzatuv rejasi tuzilgan homilador va tuqqan ayollar | C34: Выявлены факторы риска и составлен индивидуальный план наблюдения | D34: nafar | E34: 7 | F34: =IF(OR(Boshqaruv!$C$9="",Boshqaruv!$C$10=""),"",COUNTIFS(Homiladorlar!$X$5:$X$404,">="&Boshqaruv!$C$9,Homiladorlar!$X$5:$X$404,"<="&Boshqaruv!$C$10,Homiladorlar!$W$5:$W$404,"Ha")) -> 0 | G34: AVTOMATIK: «Homiladorlar»: individual reja tuzilgan sana davrda. / АВТОМАТИЧЕСКИ: «Homiladorlar»: дата составления индивид. плана в периоде. [Asos: 263-son buyruq (2022), doya vazifalari]
A35: 19 | B35: Doya qabuliga rejalashtirilgan tashriflar | C35: Запланировано визитов на приём доя | D35: ta | E35: 3 | F35: =IF(OR(Boshqaruv!$C$9="",Boshqaruv!$C$10=""),"",SUMIFS(Qabul_jurnali!$C$5:$C$404,Qabul_jurnali!$B$5:$B$404,">="&Boshqaruv!$C$9,Qabul_jurnali!$B$5:$B$404,"<="&Boshqaruv!$C$10)) -> 0 | G35: AVTOMATIK: «Qabul_jurnali»: rejalashtirilgan tashriflar yig‘indisi. / АВТОМАТИЧЕСКИ: «Qabul_jurnali»: сумма запланированных визитов. [Asos: 178-son buyruq (2023), reyting mezonlari]
A36: 20 | B36: Doya qabuliga haqiqiy tashriflar | C36: Фактические визиты на приём доя | D36: ta | E36: 3 | F36: =IF(OR(Boshqaruv!$C$9="",Boshqaruv!$C$10=""),"",SUMIFS(Qabul_jurnali!$D$5:$D$404,Qabul_jurnali!$B$5:$B$404,">="&Boshqaruv!$C$9,Qabul_jurnali!$B$5:$B$404,"<="&Boshqaruv!$C$10)) -> 0 | G36: AVTOMATIK: «Qabul_jurnali»: haqiqiy tashriflar yig‘indisi. / АВТОМАТИЧЕСКИ: «Qabul_jurnali»: сумма фактических визитов. [Asos: 178-son buyruq (2023), reyting mezonlari]
A37: 21 | B37: Doya qabuli rejasi bajarilishi | C37: Выполнение плана приёма доя | D37: % | E37: 3 | F37: =IF(OR(Boshqaruv!$C$9="",Boshqaruv!$C$10=""),"",IF(N($F$35)=0,"",$F$36/$F$35)) | G37: AVTOMATIK: 20-qator / 19-qator. / АВТОМАТИЧЕСКИ: Строка 20 / строка 19. [Asos: 178-son buyruq (2023), reyting mezonlari]
A38: 22 | B38: Bachadon bo‘yni saratoni skriningi bilan qamrab olingan ayollar (35–55 yosh) | C38: Охвачено скринингом рака шейки матки (женщины 35–55 лет) | D38: nafar | E38: 9 | F38: =IF(OR(Boshqaruv!$C$9="",Boshqaruv!$C$10=""),"",COUNTIFS(Skrining!$B$5:$B$1504,">="&Boshqaruv!$C$9,Skrining!$B$5:$B$1504,"<="&Boshqaruv!$C$10,Skrining!$I$5:$I$1504,"Bachadon bo'yni",Skrining!$K$5:$K$1504,"Ha")) -> 0 | G38: AVTOMATIK: «Skrining»: bachadon bo‘yni, 35–55 yosh, davrda. / АВТОМАТИЧЕСКИ: «Skrining»: шейка матки, 35–55 лет, за период. [Asos: 47-T buyrug‘i (Surxondaryo, 2024), skrining shtabi]
A39: 23 | B39: Ko‘krak bezi saratoni skriningi bilan qamrab olingan ayollar (45–65 yosh) | C39: Охвачено скринингом рака молочной железы (женщины 45–65 лет) | D39: nafar | E39: 9 | F39: =IF(OR(Boshqaruv!$C$9="",Boshqaruv!$C$10=""),"",COUNTIFS(Skrining!$B$5:$B$1504,">="&Boshqaruv!$C$9,Skrining!$B$5:$B$1504,"<="&Boshqaruv!$C$10,Skrining!$I$5:$I$1504,"Ko'krak bezi",Skrining!$K$5:$K$1504,"Ha")) -> 0 | G39: AVTOMATIK: «Skrining»: ko‘krak bezi, 45–65 yosh, davrda. / АВТОМАТИЧЕСКИ: «Skrining»: молочная железа, 45–65 лет, за период. [Asos: 47-T buyrug‘i (Surxondaryo, 2024), skrining shtabi]
A40: 24 | B40: [Voyaga yetmaganlar] Hisobdagi homilador qizlar (18 yoshgacha) | C40: [Несовершеннолетние] Беременные девочки на учёте (до 18 лет) | D40: nafar | E40: 10 | F40: =IF(OR(Boshqaruv!$C$9="",Boshqaruv!$C$10=""),"",(COUNTIFS(Homiladorlar!$I$5:$I$404,"<="&Boshqaruv!$C$10,Homiladorlar!$AG$5:$AG$404,"",Homiladorlar!$P$5:$P$404,"Ha")+COUNTIFS(Homiladorlar!$I$5:$I$404,"<="&Boshqaruv!$C$10,Homiladorlar!$AG$5:$AG$404,">"&Boshqaruv!$C$10,Homiladorlar!$P$5:$P$404,"Ha"))) -> 0 | G40: AVTOMATIK: «Homiladorlar»: hisobga olishda 18 yoshdan kichik, davr oxiriga hisobda. / АВТОМАТИЧЕСКИ: «Homiladorlar»: младше 18 при постановке, на учёте на конец периода. [Asos: 363-son buyruq (2020), tibbiy hisob shakllari]
A41: 25 | B41: [Voyaga yetmaganlar] Davr ichida tuqqan qizlar (18 yoshgacha) | C41: [Несовершеннолетние] Родившие за период (до 18 лет) | D41: nafar | E41: 7 | F41: =IF(OR(Boshqaruv!$C$9="",Boshqaruv!$C$10=""),"",COUNTIFS(Homiladorlar!$AG$5:$AG$404,">="&Boshqaruv!$C$9,Homiladorlar!$AG$5:$AG$404,"<="&Boshqaruv!$C$10,Homiladorlar!$P$5:$P$404,"Ha",Homiladorlar!$AF$5:$AF$404,"Tug'di")) -> 0 | G41: AVTOMATIK: «Homiladorlar»: 18 yoshgacha, holati Tug‘di, chiqish sanasi davrda. / АВТОМАТИЧЕСКИ: «Homiladorlar»: до 18 лет, статус Tug‘di, дата выбытия в периоде. [Asos: 263-son buyruq (2022), doya vazifalari]
A42: 26 | B42: [Voyaga yetmaganlar] Reproduktiv salomatlik bo‘yicha maslahat olgan o‘smir qizlar (15–17 yosh) | C42: [Несовершеннолетние] Подростки 15–17 лет, получившие консультацию по репродуктивному здоровью | D42: nafar | E42: 9 | F42: =IF(OR(Boshqaruv!$C$9="",Boshqaruv!$C$10=""),"",COUNTIFS(Qizlar_maslahat!$B$5:$B$304,">="&Boshqaruv!$C$9,Qizlar_maslahat!$B$5:$B$304,"<="&Boshqaruv!$C$10,Qizlar_maslahat!$H$5:$H$304,">="&15,Qizlar_maslahat!$H$5:$H$304,"<="&17)) -> 0 | G42: AVTOMATIK: «Qizlar_maslahat»: 15–17 yosh, davrda. / АВТОМАТИЧЕСКИ: «Qizlar_maslahat»: 15–17 лет, за период. [Asos: 263-son buyruq (2022), doya vazifalari]
...

Sheet Homiladorlar
A1: HOMILADORLAR REYESTRI / РЕЕСТР БЕРЕМЕННЫХ (doya uchastkasi)
A2: Sariq — kiritish; yashil — avtomatik. Diagnoz va xavf sababini faqat davolovchi shifokor hujjatidan ko‘chiring. / Жёлтое — ввод; зелёное — авто. Диагноз и причину риска — только из документа лечащего врача.
A3: MAXFIY / КОНФИДЕНЦИАЛЬНО — shaxsiy va tibbiy ma’lumotlar (shifokorlik siri). Faylni parol bilan himoyalang, ochiq guruhlarga yubormang. / Персональные и медицинские данные (врачебная тайна). Защитите файл паролем, не отправляйте в открытые группы.
A4: № | B4: F.I.Sh. (to‘liq) Ф.И.О. | C4: Tug‘ilgan sana Дата рождения | D4: PINFL (14 raqam) ПИНФЛ (14 цифр) | E4: Telefon Телефон | F4: Mahalla Махалля | G4: Manzil Адрес | H4: Yorliq (avto) — boshqa varaqlarda tanlanadi Метка (авто) | I4: Hisobga olingan sana Дата постановки на учёт | J4: Oxirgi hayz 1-kuni Первый день последних месячных | K4: Taxminiy tug‘ruq sanasi (avto) Предп. дата родов | L4: Hozirgi muddat, hafta (avto) Срок сейчас, нед. | M4: Hisobga olishdagi muddat, hafta (avto) Срок при постановке, нед. | N4: 12 haftagacha hisobga olingan? (avto) Взята до 12 нед.? | O4: Hisobga olishdagi yosh (avto) Возраст при постановке | P4: Voyaga yetmagan? (avto) Несоверш.? | Q4: Xavf guruhida? Группа риска? | R4: Og‘irlik darajasi Тяжесть | S4: Asosiy xavf omili Основной фактор риска | T4: Asosiy diagnoz (hujjat bo‘yicha) Основной диагноз (по документам) | U4: MKB-10 kodi Код МКБ-10 | V4: Diagnozni qo‘ygan shifokor / hujjat №, sanasi Кто поставил диагноз / № и дата документа | W4: Individual kuzatuv rejasi tuzilganmi? Индивид. план наблюдения составлен? | X4: Reja tuzilgan sana Дата составления плана | Y4: Antenatal ko‘rikka yo‘llangan sana Дата направления на антенат. осмотр | Z4: Prenatal skrining o‘tgan sana Дата пренатального скрининга | AA4: Skrining muddati, hafta (avto) Срок скрининга, нед. | AB4: Skrining o‘z vaqtidami? (avto) Скрининг в срок? | AC4: Oxirgi ko‘rik sanasi Дата последнего осмотра | AD4: Keyingi ko‘rik sanasi Дата следующего осмотра | AE4: Ko‘rik muddati o‘tgan? (avto) Просрочен осмотр? | AF4: Holati Статус | AG4: Chiqish sanasi (tug‘ruq / boshqa) Дата выбытия (роды / иное) | AH4: Tug‘ruq muassasasi Учреждение родов | AI4: Tibbiy karta / hujjat № № мед. карты / документа | AJ4: Oilaviy shifokor Семейный врач | AK4: Izoh Примечание | AL4: Takror? (avto) Дубль? | AM4: № (xavfli ro‘yxat) № (риск) | AN4: № (voyaga yetm.) № (несоверш.)
A5: 1 | B5: Тестова Анна Ивановна | C5: 34768 | D5: 30000000000000 | E5: +998900000000 | F5: Тестовая махалля | H5: =IF(OR($B5="",$C5=""),"",$B5&" ("&DAY($C5)&"."&MONTH($C5)&"."&YEAR($C5)&")") -> Тестова Анна Ивановна (10.3.1995) | I5: 46278 | J5: 46208 | K5: =IF($J5="","",$J5+280) -> 46488 | L5: =IF(OR($J5="",$AG5<>""),"",INT((Boshqaruv!$C$12-$J5)/7)) -> 15 | M5: =IF(OR($I5="",$J5=""),"",INT(($I5-$J5)/7)) -> 10 | N5: =IF($M5="","",IF($M5<=12,"Ha","Yo'q")) -> Ha | O5: =IF(OR($C5="",$I5=""),"",INT(($I5-$C5)/365.25)) -> 31 | P5: =IF($O5="","",IF($O5<18,"Ha","Yo'q")) -> Yo'q | Q5: Ha | AA5: =IF(OR($Z5="",$J5=""),"",INT(($Z5-$J5)/7)) | AB5: =IF($AA5="","",IF(AND($AA5>=Spravochnik!$G$5,$AA5<=Spravochnik!$G$6),"Ha","Yo'q")) | AE5: =IF(AND($B5<>"",$AG5="",$AD5<>"",$AD5<Boshqaruv!$C$12),"Ha","") | AL5: =IF(OR($B5="",$C5="",$I5=""),"",IF(COUNTIFS($B$5:$B$404,$B5,$C$5:$C$404,$C5,$I$5:$I$404,$I5)>1,"Takror","")) | AM5: =IF(AND($B5<>"",$Q5="Ha",$I5<>"",$I5<=Boshqaruv!$C$12,OR($AG5="",$AG5>Boshqaruv!$C$12)),MAX($AM$4:$AM4)+1,"") -> 1 | AN5: =IF(AND($B5<>"",$P5="Ha",$I5<>"",$I5<=Boshqaruv!$C$12,OR($AG5="",$AG5>Boshqaruv!$C$12)),MAX($AN$4:$AN4)+1,"")
A6: 2 | B6: Пробная Мария Петровна | C6: 35166 | D6: 30000000000001 | E6: +998900000001 | F6: Тестовая махалля | H6: =IF(OR($B6="",$C6=""),"",$B6&" ("&DAY($C6)&"."&MONTH($C6)&"."&YEAR($C6)&")") -> Пробная Мария Петровна (11.4.1996) | I6: 46273 | J6: 46203 | K6: =IF($J6="","",$J6+280) -> 46483 | L6: =IF(OR($J6="",$AG6<>""),"",INT((Boshqaruv!$C$12-$J6)/7)) -> 16 | M6: =IF(OR($I6="",$J6=""),"",INT(($I6-$J6)/7)) -> 10 | N6: =IF($M6="","",IF($M6<=12,"Ha","Yo'q")) -> Ha | O6: =IF(OR($C6="",$I6=""),"",INT(($I6-$C6)/365.25)) -> 30 | P6: =IF($O6="","",IF($O6<18,"Ha","Yo'q")) -> Yo'q | Q6: Yo'q | AA6: =IF(OR($Z6="",$J6=""),"",INT(($Z6-$J6)/7)) | AB6: =IF($AA6="","",IF(AND($AA6>=Spravochnik!$G$5,$AA6<=Spravochnik!$G$6),"Ha","Yo'q")) | AE6: =IF(AND($B6<>"",$AG6="",$AD6<>"",$AD6<Boshqaruv!$C$12),"Ha","") | AL6: =IF(OR($B6="",$C6="",$I6=""),"",IF(COUNTIFS($B$5:$B$404,$B6,$C$5:$C$404,$C6,$I$5:$I$404,$I6)>1,"Takror","")) | AM6: =IF(AND($B6<>"",$Q6="Ha",$I6<>"",$I6<=Boshqaruv!$C$12,OR($AG6="",$AG6>Boshqaruv!$C$12)),MAX($AM$4:$AM5)+1,"") | AN6: =IF(AND($B6<>"",$P6="Ha",$I6<>"",$I6<=Boshqaruv!$C$12,OR($AG6="",$AG6>Boshqaruv!$C$12)),MAX($AN$4:$AN5)+1,"")
A7: 3 | B7: Образцова Зилола Каримовна | C7: 35562 | D7: 30000000000002 | E7: +998900000002 | F7: Тестовая махалля | H7: =IF(OR($B7="",$C7=""),"",$B7&" ("&DAY($C7)&"."&MONTH($C7)&"."&YEAR($C7)&")") -> Образцова Зилола Каримовна (12.5.1997) | I7: 46268 | J7: 46198 | K7: =IF($J7="","",$J7+280) -> 46478 | L7: =IF(OR($J7="",$AG7<>""),"",INT((Boshqaruv!$C$12-$J7)/7)) -> 17 | M7: =IF(OR($I7="",$J7=""),"",INT(($I7-$J7)/7)) -> 10 | N7: =IF($M7="","",IF($M7<=12,"Ha","Yo'q")) -> Ha | O7: =IF(OR($C7="",$I7=""),"",INT(($I7-$C7)/365.25)) -> 29 | P7: =IF($O7="","",IF($O7<18,"Ha","Yo'q")) -> Yo'q | Q7: Yo'q | AA7: =IF(OR($Z7="",$J7=""),"",INT(($Z7-$J7)/7)) | AB7: =IF($AA7="","",IF(AND($AA7>=Spravochnik!$G$5,$AA7<=Spravochnik!$G$6),"Ha","Yo'q")) | AE7: =IF(AND($B7<>"",$AG7="",$AD7<>"",$AD7<Boshqaruv!$C$12),"Ha","") | AL7: =IF(OR($B7="",$C7="",$I7=""),"",IF(COUNTIFS($B$5:$B$404,$B7,$C$5:$C$404,$C7,$I$5:$I$404,$I7)>1,"Takror","")) | AM7: =IF(AND($B7<>"",$Q7="Ha",$I7<>"",$I7<=Boshqaruv!$C$12,OR($AG7="",$AG7>Boshqaruv!$C$12)),MAX($AM$4:$AM6)+1,"") | AN7: =IF(AND($B7<>"",$P7="Ha",$I7<>"",$I7<=Boshqaruv!$C$12,OR($AG7="",$AG7>Boshqaruv!$C$12)),MAX($AN$4:$AN6)+1,"")
A8: 4 | B8: Вымышленная Нигора Алиевна | C8: 35959 | D8: 30000000000003 | E8: +998900000003 | F8: Тестовая махалля | H8: =IF(OR($B8="",$C8=""),"",$B8&" ("&DAY($C8)&"."&MONTH($C8)&"."&YEAR($C8)&")") -> Вымышленная Нигора Алиевна (13.6.1998) | I8: 46263 | J8: 46193 | K8: =IF($J8="","",$J8+280) -> 46473 | L8: =IF(OR($J8="",$AG8<>""),"",INT((Boshqaruv!$C$12-$J8)/7)) -> 17 | M8: =IF(OR($I8="",$J8=""),"",INT(($I8-$J8)/7)) -> 10 | N8: =IF($M8="","",IF($M8<=12,"Ha","Yo'q")) -> Ha | O8: =IF(OR($C8="",$I8=""),"",INT(($I8-$C8)/365.25)) -> 28 | P8: =IF($O8="","",IF($O8<18,"Ha","Yo'q")) -> Yo'q | Q8: Ha | AA8: =IF(OR($Z8="",$J8=""),"",INT(($Z8-$J8)/7)) | AB8: =IF($AA8="","",IF(AND($AA8>=Spravochnik!$G$5,$AA8<=Spravochnik!$G$6),"Ha","Yo'q")) | AE8: =IF(AND($B8<>"",$AG8="",$AD8<>"",$AD8<Boshqaruv!$C$12),"Ha","") | AL8: =IF(OR($B8="",$C8="",$I8=""),"",IF(COUNTIFS($B$5:$B$404,$B8,$C$5:$C$404,$C8,$I$5:$I$404,$I8)>1,"Takror","")) | AM8: =IF(AND($B8<>"",$Q8="Ha",$I8<>"",$I8<=Boshqaruv!$C$12,OR($AG8="",$AG8>Boshqaruv!$C$12)),MAX($AM$4:$AM7)+1,"") -> 2 | AN8: =IF(AND($B8<>"",$P8="Ha",$I8<>"",$I8<=Boshqaruv!$C$12,OR($AG8="",$AG8>Boshqaruv!$C$12)),MAX($AN$4:$AN7)+1,"")
A9: 5 | B9: Условная Дилноза Рустамовна | C9: 36355 | D9: 30000000000004 | E9: +998900000004 | F9: Тестовая махалля | H9: =IF(OR($B9="",$C9=""),"",$B9&" ("&DAY($C9)&"."&MONTH($C9)&"."&YEAR($C9)&")") -> Условная Дилноза Рустамовна (14.7.1999) | I9: 46258 | J9: 46188 | K9: =IF($J9="","",$J9+280) -> 46468 | L9: =IF(OR($J9="",$AG9<>""),"",INT((Boshqaruv!$C$12-$J9)/7)) -> 18 | M9: =IF(OR($I9="",$J9=""),"",INT(($I9-$J9)/7)) -> 10 | N9: =IF($M9="","",IF($M9<=12,"Ha","Yo'q")) -> Ha | O9: =IF(OR($C9="",$I9=""),"",INT(($I9-$C9)/365.25)) -> 27 | P9: =IF($O9="","",IF($O9<18,"Ha","Yo'q")) -> Yo'q | Q9: Yo'q | AA9: =IF(OR($Z9="",$J9=""),"",INT(($Z9-$J9)/7)) | AB9: =IF($AA9="","",IF(AND($AA9>=Spravochnik!$G$5,$AA9<=Spravochnik!$G$6),"Ha","Yo'q")) | AE9: =IF(AND($B9<>"",$AG9="",$AD9<>"",$AD9<Boshqaruv!$C$12),"Ha","") | AL9: =IF(OR($B9="",$C9="",$I9=""),"",IF(COUNTIFS($B$5:$B$404,$B9,$C$5:$C$404,$C9,$I$5:$I$404,$I9)>1,"Takror","")) | AM9: =IF(AND($B9<>"",$Q9="Ha",$I9<>"",$I9<=Boshqaruv!$C$12,OR($AG9="",$AG9>Boshqaruv!$C$12)),MAX($AM$4:$AM8)+1,"") | AN9: =IF(AND($B9<>"",$P9="Ha",$I9<>"",$I9<=Boshqaruv!$C$12,OR($AG9="",$AG9>Boshqaruv!$C$12)),MAX($AN$4:$AN8)+1,"")
A10: 6 | B10: Примерова Гулнора Саидовна | C10: 36753 | D10: 30000000000005 | E10: +998900000005 | F10: Тестовая махалля | H10: =IF(OR($B10="",$C10=""),"",$B10&" ("&DAY($C10)&"."&MONTH($C10)&"."&YEAR($C10)&")") -> Примерова Гулнора Саидовна (15.8.2000) | I10: 46253 | J10: 46183 | K10: =IF($J10="","",$J10+280) -> 46463 | L10: =IF(OR($J10="",$AG10<>""),"",INT((Boshqaruv!$C$12-$J10)/7)) -> 19 | M10: =IF(OR($I10="",$J10=""),"",INT(($I10-$J10)/7)) -> 10 | N10: =IF($M10="","",IF($M10<=12,"Ha","Yo'q")) -> Ha | O10: =IF(OR($C10="",$I10=""),"",INT(($I10-$C10)/365.25)) -> 26 | P10: =IF($O10="","",IF($O10<18,"Ha","Yo'q")) -> Yo'q | Q10: Yo'q | AA10: =IF(OR($Z10="",$J10=""),"",INT(($Z10-$J10)/7)) | AB10: =IF($AA10="","",IF(AND($AA10>=Spravochnik!$G$5,$AA10<=Spravochnik!$G$6),"Ha","Yo'q")) | AE10: =IF(AND($B10<>"",$AG10="",$AD10<>"",$AD10<Boshqaruv!$C$12),"Ha","") | AL10: =IF(OR($B10="",$C10="",$I10=""),"",IF(COUNTIFS($B$5:$B$404,$B10,$C$5:$C$404,$C10,$I$5:$I$404,$I10)>1,"Takror","")) | AM10: =IF(AND($B10<>"",$Q10="Ha",$I10<>"",$I10<=Boshqaruv!$C$12,OR($AG10="",$AG10>Boshqaruv!$C$12)),MAX($AM$4:$AM9)+1,"") | AN10: =IF(AND($B10<>"",$P10="Ha",$I10<>"",$I10<=Boshqaruv!$C$12,OR($AG10="",$AG10>Boshqaruv!$C$12)),MAX($AN$4:$AN9)+1,"")
A11: 7 | B11: Демонстрационная Лола Акбаровна | C11: 36966 | D11: 30000000000006 | E11: +998900000006 | F11: Тестовая махалля | H11: =IF(OR($B11="",$C11=""),"",$B11&" ("&DAY($C11)&"."&MONTH($C11)&"."&YEAR($C11)&")") -> Демонстрационная Лола Акбаровна (16.3.2001) | I11: 46248 | J11: 46178 | K11: =IF($J11="","",$J11+280) -> 46458 | L11: =IF(OR($J11="",$AG11<>""),"",INT((Boshqaruv!$C$12-$J11)/7)) -> 20 | M11: =IF(OR($I11="",$J11=""),"",INT(($I11-$J11)/7)) -> 10 | N11: =IF($M11="","",IF($M11<=12,"Ha","Yo'q")) -> Ha | O11: =IF(OR($C11="",$I11=""),"",INT(($I11-$C11)/365.25)) -> 25 | P11: =IF($O11="","",IF($O11<18,"Ha","Yo'q")) -> Yo'q | Q11: Ha | AA11: =IF(OR($Z11="",$J11=""),"",INT(($Z11-$J11)/7)) | AB11: =IF($AA11="","",IF(AND($AA11>=Spravochnik!$G$5,$AA11<=Spravochnik!$G$6),"Ha","Yo'q")) | AE11: =IF(AND($B11<>"",$AG11="",$AD11<>"",$AD11<Boshqaruv!$C$12),"Ha","") | AL11: =IF(OR($B11="",$C11="",$I11=""),"",IF(COUNTIFS($B$5:$B$404,$B11,$C$5:$C$404,$C11,$I$5:$I$404,$I11)>1,"Takror","")) | AM11: =IF(AND($B11<>"",$Q11="Ha",$I11<>"",$I11<=Boshqaruv!$C$12,OR($AG11="",$AG11>Boshqaruv!$C$12)),MAX($AM$4:$AM10)+1,"") -> 3 | AN11: =IF(AND($B11<>"",$P11="Ha",$I11<>"",$I11<=Boshqaruv!$C$12,OR($AG11="",$AG11>Boshqaruv!$C$12)),MAX($AN$4:$AN10)+1,"")
A12: 8 | B12: Учебная Саида Баховадиновна | C12: 37363 | D12: 30000000000007 | E12: +998900000007 | F12: Тестовая махалля | H12: =IF(OR($B12="",$C12=""),"",$B12&" ("&DAY($C12)&"."&MONTH($C12)&"."&YEAR($C12)&")") -> Учебная Саида Баховадиновна (17.4.2002) | I12: 46243 | J12: 46173 | K12: =IF($J12="","",$J12+280) -> 46453 | L12: =IF(OR($J12="",$AG12<>""),"",INT((Boshqaruv!$C$12-$J12)/7)) -> 20 | M12: =IF(OR($I12="",$J12=""),"",INT(($I12-$J12)/7)) -> 10 | N12: =IF($M12="","",IF($M12<=12,"Ha","Yo'q")) -> Ha | O12: =IF(OR($C12="",$I12=""),"",INT(($I12-$C12)/365.25)) -> 24 | P12: =IF($O12="","",IF($O12<18,"Ha","Yo'q")) -> Yo'q | Q12: Yo'q | AA12: =IF(OR($Z12="",$J12=""),"",INT(($Z12-$J12)/7)) | AB12: =IF($AA12="","",IF(AND($AA12>=Spravochnik!$G$5,$AA12<=Spravochnik!$G$6),"Ha","Yo'q")) | AE12: =IF(AND($B12<>"",$AG12="",$AD12<>"",$AD12<Boshqaruv!$C$12),"Ha","") | AL12: =IF(OR($B12="",$C12="",$I12=""),"",IF(COUNTIFS($B$5:$B$404,$B12,$C$5:$C$404,$C12,$I$5:$I$404,$I12)>1,"Takror","")) | AM12: =IF(AND($B12<>"",$Q12="Ha",$I12<>"",$I12<=Boshqaruv!$C$12,OR($AG12="",$AG12>Boshqaruv!$C$12)),MAX($AM$4:$AM11)+1,"") | AN12: =IF(AND($B12<>"",$P12="Ha",$I12<>"",$I12<=Boshqaruv!$C$12,OR($AG12="",$AG12>Boshqaruv!$C$12)),MAX($AN$4:$AN11)+1,"")
A13: 9 | B13: Тестова Малика Олимовна | C13: 34837 | D13: 30000000000008 | E13: +998900000008 | F13: Тестовая махалля | H13: =IF(OR($B13="",$C13=""),"",$B13&" ("&DAY($C13)&"."&MONTH($C13)&"."&YEAR($C13)&")") -> Тестова Малика Олимовна (18.5.1995) | I13: 46238 | J13: 46168 | K13: =IF($J13="","",$J13+280) -> 46448 | L13: =IF(OR($J13="",$AG13<>""),"",INT((Boshqaruv!$C$12-$J13)/7)) -> 21 | M13: =IF(OR($I13="",$J13=""),"",INT(($I13-$J13)/7)) -> 10 | N13: =IF($M13="","",IF($M13<=12,"Ha","Yo'q")) -> Ha | O13: =IF(OR($C13="",$I13=""),"",INT(($I13-$C13)/365.25)) -> 31 | P13: =IF($O13="","",IF($O13<18,"Ha","Yo'q")) -> Yo'q | Q13: Yo'q | AA13: =IF(OR($Z13="",$J13=""),"",INT(($Z13-$J13)/7)) | AB13: =IF($AA13="","",IF(AND($AA13>=Spravochnik!$G$5,$AA13<=Spravochnik!$G$6),"Ha","Yo'q")) | AE13: =IF(AND($B13<>"",$AG13="",$AD13<>"",$AD13<Boshqaruv!$C$12),"Ha","") | AL13: =IF(OR($B13="",$C13="",$I13=""),"",IF(COUNTIFS($B$5:$B$404,$B13,$C$5:$C$404,$C13,$I$5:$I$404,$I13)>1,"Takror","")) | AM13: =IF(AND($B13<>"",$Q13="Ha",$I13<>"",$I13<=Boshqaruv!$C$12,OR($AG13="",$AG13>Boshqaruv!$C$12)),MAX($AM$4:$AM12)+1,"") | AN13: =IF(AND($B13<>"",$P13="Ha",$I13<>"",$I13<=Boshqaruv!$C$12,OR($AG13="",$AG13>Boshqaruv!$C$12)),MAX($AN$4:$AN12)+1,"")
A14: 10 | B14: Фиктивная Дильбар Юсуфовна | C14: 35235 | D14: 30000000000009 | E14: +998900000009 | F14: Тестовая махалля | H14: =IF(OR($B14="",$C14=""),"",$B14&" ("&DAY($C14)&"."&MONTH($C14)&"."&YEAR($C14)&")") -> Фиктивная Дильбар Юсуфовна (19.6.1996) | I14: 46233 | J14: 46163 | K14: =IF($J14="","",$J14+280) -> 46443 | L14: =IF(OR($J14="",$AG14<>""),"",INT((Boshqaruv!$C$12-$J14)/7)) -> 22 | M14: =IF(OR($I14="",$J14=""),"",INT(($I14-$J14)/7)) -> 10 | N14: =IF($M14="","",IF($M14<=12,"Ha","Yo'q")) -> Ha | O14: =IF(OR($C14="",$I14=""),"",INT(($I14-$C14)/365.25)) -> 30 | P14: =IF($O14="","",IF($O14<18,"Ha","Yo'q")) -> Yo'q | Q14: Ha | AA14: =IF(OR($Z14="",$J14=""),"",INT(($Z14-$J14)/7)) | AB14: =IF($AA14="","",IF(AND($AA14>=Spravochnik!$G$5,$AA14<=Spravochnik!$G$6),"Ha","Yo'q")) | AE14: =IF(AND($B14<>"",$AG14="",$AD14<>"",$AD14<Boshqaruv!$C$12),"Ha","") | AL14: =IF(OR($B14="",$C14="",$I14=""),"",IF(COUNTIFS($B$5:$B$404,$B14,$C$5:$C$404,$C14,$I$5:$I$404,$I14)>1,"Takror","")) | AM14: =IF(AND($B14<>"",$Q14="Ha",$I14<>"",$I14<=Boshqaruv!$C$12,OR($AG14="",$AG14>Boshqaruv!$C$12)),MAX($AM$4:$AM13)+1,"") -> 4 | AN14: =IF(AND($B14<>"",$P14="Ha",$I14<>"",$I14<=Boshqaruv!$C$12,OR($AG14="",$AG14>Boshqaruv!$C$12)),MAX($AN$4:$AN13)+1,"")
A15: 11 | B15: Тестова Анна Ивановна | C15: 35631 | D15: 30000000000010 | E15: +998900000010 | F15: Тестовая махалля | H15: =IF(OR($B15="",$C15=""),"",$B15&" ("&DAY($C15)&"."&MONTH($C15)&"."&YEAR($C15)&")") -> Тестова Анна Ивановна (20.7.1997) | I15: 46228 | J15: 46158 | K15: =IF($J15="","",$J15+280) -> 46438 | L15: =IF(OR($J15="",$AG15<>""),"",INT((Boshqaruv!$C$12-$J15)/7)) -> 22 | M15: =IF(OR($I15="",$J15=""),"",INT(($I15-$J15)/7)) -> 10 | N15: =IF($M15="","",IF($M15<=12,"Ha","Yo'q")) -> Ha | O15: =IF(OR($C15="",$I15=""),"",INT(($I15-$C15)/365.25)) -> 29 | P15: =IF($O15="","",IF($O15<18,"Ha","Yo'q")) -> Yo'q | Q15: Yo'q | AA15: =IF(OR($Z15="",$J15=""),"",INT(($Z15-$J15)/7)) | AB15: =IF($AA15="","",IF(AND($AA15>=Spravochnik!$G$5,$AA15<=Spravochnik!$G$6),"Ha","Yo'q")) | AE15: =IF(AND($B15<>"",$AG15="",$AD15<>"",$AD15<Boshqaruv!$C$12),"Ha","") | AL15: =IF(OR($B15="",$C15="",$I15=""),"",IF(COUNTIFS($B$5:$B$404,$B15,$C$5:$C$404,$C15,$I$5:$I$404,$I15)>1,"Takror","")) | AM15: =IF(AND($B15<>"",$Q15="Ha",$I15<>"",$I15<=Boshqaruv!$C$12,OR($AG15="",$AG15>Boshqaruv!$C$12)),MAX($AM$4:$AM14)+1,"") | AN15: =IF(AND($B15<>"",$P15="Ha",$I15<>"",$I15<=Boshqaruv!$C$12,OR($AG15="",$AG15>Boshqaruv!$C$12)),MAX($AN$4:$AN14)+1,"")
A16: 12 | B16: Пробная Мария Петровна | C16: 36028 | D16: 30000000000011 | E16: +998900000011 | F16: Тестовая махалля | H16: =IF(OR($B16="",$C16=""),"",$B16&" ("&DAY($C16)&"."&MONTH($C16)&"."&YEAR($C16)&")") -> Пробная Мария Петровна (21.8.1998) | I16: 46223 | J16: 46153 | K16: =IF($J16="","",$J16+280) -> 46433 | L16: =IF(OR($J16="",$AG16<>""),"",INT((Boshqaruv!$C$12-$J16)/7)) -> 23 | M16: =IF(OR($I16="",$J16=""),"",INT(($I16-$J16)/7)) -> 10 | N16: =IF($M16="","",IF($M16<=12,"Ha","Yo'q")) -> Ha | O16: =IF(OR($C16="",$I16=""),"",INT(($I16-$C16)/365.25)) -> 27 | P16: =IF($O16="","",IF($O16<18,"Ha","Yo'q")) -> Yo'q | Q16: Yo'q | AA16: =IF(OR($Z16="",$J16=""),"",INT(($Z16-$J16)/7)) | AB16: =IF($AA16="","",IF(AND($AA16>=Spravochnik!$G$5,$AA16<=Spravochnik!$G$6),"Ha","Yo'q")) | AE16: =IF(AND($B16<>"",$AG16="",$AD16<>"",$AD16<Boshqaruv!$C$12),"Ha","") | AL16: =IF(OR($B16="",$C16="",$I16=""),"",IF(COUNTIFS($B$5:$B$404,$B16,$C$5:$C$404,$C16,$I$5:$I$404,$I16)>1,"Takror","")) | AM16: =IF(AND($B16<>"",$Q16="Ha",$I16<>"",$I16<=Boshqaruv!$C$12,OR($AG16="",$AG16>Boshqaruv!$C$12)),MAX($AM$4:$AM15)+1,"") | AN16: =IF(AND($B16<>"",$P16="Ha",$I16<>"",$I16<=Boshqaruv!$C$12,OR($AG16="",$AG16>Boshqaruv!$C$12)),MAX($AN$4:$AN15)+1,"")
A17: 13 | H17: =IF(OR($B17="",$C17=""),"",$B17&" ("&DAY($C17)&"."&MONTH($C17)&"."&YEAR($C17)&")") | K17: =IF($J17="","",$J17+280) | L17: =IF(OR($J17="",$AG17<>""),"",INT((Boshqaruv!$C$12-$J17)/7)) | M17: =IF(OR($I17="",$J17=""),"",INT(($I17-$J17)/7)) | N17: =IF($M17="","",IF($M17<=12,"Ha","Yo'q")) | O17: =IF(OR($C17="",$I17=""),"",INT(($I17-$C17)/365.25)) | P17: =IF($O17="","",IF($O17<18,"Ha","Yo'q")) | AA17: =IF(OR($Z17="",$J17=""),"",INT(($Z17-$J17)/7)) | AB17: =IF($AA17="","",IF(AND($AA17>=Spravochnik!$G$5,$AA17<=Spravochnik!$G$6),"Ha","Yo'q")) | AE17: =IF(AND($B17<>"",$AG17="",$AD17<>"",$AD17<Boshqaruv!$C$12),"Ha","") | AL17: =IF(OR($B17="",$C17="",$I17=""),"",IF(COUNTIFS($B$5:$B$404,$B17,$C$5:$C$404,$C17,$I$5:$I$404,$I17)>1,"Takror","")) | AM17: =IF(AND($B17<>"",$Q17="Ha",$I17<>"",$I17<=Boshqaruv!$C$12,OR($AG17="",$AG17>Boshqaruv!$C$12)),MAX($AM$4:$AM16)+1,"") | AN17: =IF(AND($B17<>"",$P17="Ha",$I17<>"",$I17<=Boshqaruv!$C$12,OR($AG17="",$AG17>Boshqaruv!$C$12)),MAX($AN$4:$AN16)+1,"")
A18: 14 | H18: =IF(OR($B18="",$C18=""),"",$B18&" ("&DAY($C18)&"."&MONTH($C18)&"."&YEAR($C18)&")") | K18: =IF($J18="","",$J18+280) | L18: =IF(OR($J18="",$AG18<>""),"",INT((Boshqaruv!$C$12-$J18)/7)) | M18: =IF(OR($I18="",$J18=""),"",INT(($I18-$J18)/7)) | N18: =IF($M18="","",IF($M18<=12,"Ha","Yo'q")) | O18: =IF(OR($C18="",$I18=""),"",INT(($I18-$C18)/365.25)) | P18: =IF($O18="","",IF($O18<18,"Ha","Yo'q")) | AA18: =IF(OR($Z18="",$J18=""),"",INT(($Z18-$J18)/7)) | AB18: =IF($AA18="","",IF(AND($AA18>=Spravochnik!$G$5,$AA18<=Spravochnik!$G$6),"Ha","Yo'q")) | AE18: =IF(AND($B18<>"",$AG18="",$AD18<>"",$AD18<Boshqaruv!$C$12),"Ha","") | AL18: =IF(OR($B18="",$C18="",$I18=""),"",IF(COUNTIFS($B$5:$B$404,$B18,$C$5:$C$404,$C18,$I$5:$I$404,$I18)>1,"Takror","")) | AM18: =IF(AND($B18<>"",$Q18="Ha",$I18<>"",$I18<=Boshqaruv!$C$12,OR($AG18="",$AG18>Boshqaruv!$C$12)),MAX($AM$4:$AM17)+1,"") | AN18: =IF(AND($B18<>"",$P18="Ha",$I18<>"",$I18<=Boshqaruv!$C$12,OR($AG18="",$AG18>Boshqaruv!$C$12)),MAX($AN$4:$AN17)+1,"")
A19: 15 | H19: =IF(OR($B19="",$C19=""),"",$B19&" ("&DAY($C19)&"."&MONTH($C19)&"."&YEAR($C19)&")") | K19: =IF($J19="","",$J19+280) | L19: =IF(OR($J19="",$AG19<>""),"",INT((Boshqaruv!$C$12-$J19)/7)) | M19: =IF(OR($I19="",$J19=""),"",INT(($I19-$J19)/7)) | N19: =IF($M19="","",IF($M19<=12,"Ha","Yo'q")) | O19: =IF(OR($C19="",$I19=""),"",INT(($I19-$C19)/365.25)) | P19: =IF($O19="","",IF($O19<18,"Ha","Yo'q")) | AA19: =IF(OR($Z19="",$J19=""),"",INT(($Z19-$J19)/7)) | AB19: =IF($AA19="","",IF(AND($AA19>=Spravochnik!$G$5,$AA19<=Spravochnik!$G$6),"Ha","Yo'q")) | AE19: =IF(AND($B19<>"",$AG19="",$AD19<>"",$AD19<Boshqaruv!$C$12),"Ha","") | AL19: =IF(OR($B19="",$C19="",$I19=""),"",IF(COUNTIFS($B$5:$B$404,$B19,$C$5:$C$404,$C19,$I$5:$I$404,$I19)>1,"Takror","")) | AM19: =IF(AND($B19<>"",$Q19="Ha",$I19<>"",$I19<=Boshqaruv!$C$12,OR($AG19="",$AG19>Boshqaruv!$C$12)),MAX($AM$4:$AM18)+1,"") | AN19: =IF(AND($B19<>"",$P19="Ha",$I19<>"",$I19<=Boshqaruv!$C$12,OR($AG19="",$AG19>Boshqaruv!$C$12)),MAX($AN$4:$AN18)+1,"")
A20: 16 | H20: =IF(OR($B20="",$C20=""),"",$B20&" ("&DAY($C20)&"."&MONTH($C20)&"."&YEAR($C20)&")") | K20: =IF($J20="","",$J20+280) | L20: =IF(OR($J20="",$AG20<>""),"",INT((Boshqaruv!$C$12-$J20)/7)) | M20: =IF(OR($I20="",$J20=""),"",INT(($I20-$J20)/7)) | N20: =IF($M20="","",IF($M20<=12,"Ha","Yo'q")) | O20: =IF(OR($C20="",$I20=""),"",INT(($I20-$C20)/365.25)) | P20: =IF($O20="","",IF($O20<18,"Ha","Yo'q")) | AA20: =IF(OR($Z20="",$J20=""),"",INT(($Z20-$J20)/7)) | AB20: =IF($AA20="","",IF(AND($AA20>=Spravochnik!$G$5,$AA20<=Spravochnik!$G$6),"Ha","Yo'q")) | AE20: =IF(AND($B20<>"",$AG20="",$AD20<>"",$AD20<Boshqaruv!$C$12),"Ha","") | AL20: =IF(OR($B20="",$C20="",$I20=""),"",IF(COUNTIFS($B$5:$B$404,$B20,$C$5:$C$404,$C20,$I$5:$I$404,$I20)>1,"Takror","")) | AM20: =IF(AND($B20<>"",$Q20="Ha",$I20<>"",$I20<=Boshqaruv!$C$12,OR($AG20="",$AG20>Boshqaruv!$C$12)),MAX($AM$4:$AM19)+1,"") | AN20: =IF(AND($B20<>"",$P20="Ha",$I20<>"",$I20<=Boshqaruv!$C$12,OR($AG20="",$AG20>Boshqaruv!$C$12)),MAX($AN$4:$AN19)+1,"")
A21: 17 | H21: =IF(OR($B21="",$C21=""),"",$B21&" ("&DAY($C21)&"."&MONTH($C21)&"."&YEAR($C21)&")") | K21: =IF($J21="","",$J21+280) | L21: =IF(OR($J21="",$AG21<>""),"",INT((Boshqaruv!$C$12-$J21)/7)) | M21: =IF(OR($I21="",$J21=""),"",INT(($I21-$J21)/7)) | N21: =IF($M21="","",IF($M21<=12,"Ha","Yo'q")) | O21: =IF(OR($C21="",$I21=""),"",INT(($I21-$C21)/365.25)) | P21: =IF($O21="","",IF($O21<18,"Ha","Yo'q")) | AA21: =IF(OR($Z21="",$J21=""),"",INT(($Z21-$J21)/7)) | AB21: =IF($AA21="","",IF(AND($AA21>=Spravochnik!$G$5,$AA21<=Spravochnik!$G$6),"Ha","Yo'q")) | AE21: =IF(AND($B21<>"",$AG21="",$AD21<>"",$AD21<Boshqaruv!$C$12),"Ha","") | AL21: =IF(OR($B21="",$C21="",$I21=""),"",IF(COUNTIFS($B$5:$B$404,$B21,$C$5:$C$404,$C21,$I$5:$I$404,$I21)>1,"Takror","")) | AM21: =IF(AND($B21<>"",$Q21="Ha",$I21<>"",$I21<=Boshqaruv!$C$12,OR($AG21="",$AG21>Boshqaruv!$C$12)),MAX($AM$4:$AM20)+1,"") | AN21: =IF(AND($B21<>"",$P21="Ha",$I21<>"",$I21<=Boshqaruv!$C$12,OR($AG21="",$AG21>Boshqaruv!$C$12)),MAX($AN$4:$AN20)+1,"")
A22: 18 | H22: =IF(OR($B22="",$C22=""),"",$B22&" ("&DAY($C22)&"."&MONTH($C22)&"."&YEAR($C22)&")") | K22: =IF($J22="","",$J22+280) | L22: =IF(OR($J22="",$AG22<>""),"",INT((Boshqaruv!$C$12-$J22)/7)) | M22: =IF(OR($I22="",$J22=""),"",INT(($I22-$J22)/7)) | N22: =IF($M22="","",IF($M22<=12,"Ha","Yo'q")) | O22: =IF(OR($C22="",$I22=""),"",INT(($I22-$C22)/365.25)) | P22: =IF($O22="","",IF($O22<18,"Ha","Yo'q")) | AA22: =IF(OR($Z22="",$J22=""),"",INT(($Z22-$J22)/7)) | AB22: =IF($AA22="","",IF(AND($AA22>=Spravochnik!$G$5,$AA22<=Spravochnik!$G$6),"Ha","Yo'q")) | AE22: =IF(AND($B22<>"",$AG22="",$AD22<>"",$AD22<Boshqaruv!$C$12),"Ha","") | AL22: =IF(OR($B22="",$C22="",$I22=""),"",IF(COUNTIFS($B$5:$B$404,$B22,$C$5:$C$404,$C22,$I$5:$I$404,$I22)>1,"Takror","")) | AM22: =IF(AND($B22<>"",$Q22="Ha",$I22<>"",$I22<=Boshqaruv!$C$12,OR($AG22="",$AG22>Boshqaruv!$C$12)),MAX($AM$4:$AM21)+1,"") | AN22: =IF(AND($B22<>"",$P22="Ha",$I22<>"",$I22<=Boshqaruv!$C$12,OR($AG22="",$AG22>Boshqaruv!$C$12)),MAX($AN$4:$AN21)+1,"")
A23: 19 | H23: =IF(OR($B23="",$C23=""),"",$B23&" ("&DAY($C23)&"."&MONTH($C23)&"."&YEAR($C23)&")") | K23: =IF($J23="","",$J23+280) | L23: =IF(OR($J23="",$AG23<>""),"",INT((Boshqaruv!$C$12-$J23)/7)) | M23: =IF(OR($I23="",$J23=""),"",INT(($I23-$J23)/7)) | N23: =IF($M23="","",IF($M23<=12,"Ha","Yo'q")) | O23: =IF(OR($C23="",$I23=""),"",INT(($I23-$C23)/365.25)) | P23: =IF($O23="","",IF($O23<18,"Ha","Yo'q")) | AA23: =IF(OR($Z23="",$J23=""),"",INT(($Z23-$J23)/7)) | AB23: =IF($AA23="","",IF(AND($AA23>=Spravochnik!$G$5,$AA23<=Spravochnik!$G$6),"Ha","Yo'q")) | AE23: =IF(AND($B23<>"",$AG23="",$AD23<>"",$AD23<Boshqaruv!$C$12),"Ha","") | AL23: =IF(OR($B23="",$C23="",$I23=""),"",IF(COUNTIFS($B$5:$B$404,$B23,$C$5:$C$404,$C23,$I$5:$I$404,$I23)>1,"Takror","")) | AM23: =IF(AND($B23<>"",$Q23="Ha",$I23<>"",$I23<=Boshqaruv!$C$12,OR($AG23="",$AG23>Boshqaruv!$C$12)),MAX($AM$4:$AM22)+1,"") | AN23: =IF(AND($B23<>"",$P23="Ha",$I23<>"",$I23<=Boshqaruv!$C$12,OR($AG23="",$AG23>Boshqaruv!$C$12)),MAX($AN$4:$AN22)+1,"")
A24: 20 | H24: =IF(OR($B24="",$C24=""),"",$B24&" ("&DAY($C24)&"."&MONTH($C24)&"."&YEAR($C24)&")") | K24: =IF($J24="","",$J24+280) | L24: =IF(OR($J24="",$AG24<>""),"",INT((Boshqaruv!$C$12-$J24)/7)) | M24: =IF(OR($I24="",$J24=""),"",INT(($I24-$J24)/7)) | N24: =IF($M24="","",IF($M24<=12,"Ha","Yo'q")) | O24: =IF(OR($C24="",$I24=""),"",INT(($I24-$C24)/365.25)) | P24: =IF($O24="","",IF($O24<18,"Ha","Yo'q")) | AA24: =IF(OR($Z24="",$J24=""),"",INT(($Z24-$J24)/7)) | AB24: =IF($AA24="","",IF(AND($AA24>=Spravochnik!$G$5,$AA24<=Spravochnik!$G$6),"Ha","Yo'q")) | AE24: =IF(AND($B24<>"",$AG24="",$AD24<>"",$AD24<Boshqaruv!$C$12),"Ha","") | AL24: =IF(OR($B24="",$C24="",$I24=""),"",IF(COUNTIFS($B$5:$B$404,$B24,$C$5:$C$404,$C24,$I$5:$I$404,$I24)>1,"Takror","")) | AM24: =IF(AND($B24<>"",$Q24="Ha",$I24<>"",$I24<=Boshqaruv!$C$12,OR($AG24="",$AG24>Boshqaruv!$C$12)),MAX($AM$4:$AM23)+1,"") | AN24: =IF(AND($B24<>"",$P24="Ha",$I24<>"",$I24<=Boshqaruv!$C$12,OR($AG24="",$AG24>Boshqaruv!$C$12)),MAX($AN$4:$AN23)+1,"")
A25: 21 | H25: =IF(OR($B25="",$C25=""),"",$B25&" ("&DAY($C25)&"."&MONTH($C25)&"."&YEAR($C25)&")") | K25: =IF($J25="","",$J25+280) | L25: =IF(OR($J25="",$AG25<>""),"",INT((Boshqaruv!$C$12-$J25)/7)) | M25: =IF(OR($I25="",$J25=""),"",INT(($I25-$J25)/7)) | N25: =IF($M25="","",IF($M25<=12,"Ha","Yo'q")) | O25: =IF(OR($C25="",$I25=""),"",INT(($I25-$C25)/365.25)) | P25: =IF($O25="","",IF($O25<18,"Ha","Yo'q")) | AA25: =IF(OR($Z25="",$J25=""),"",INT(($Z25-$J25)/7)) | AB25: =IF($AA25="","",IF(AND($AA25>=Spravochnik!$G$5,$AA25<=Spravochnik!$G$6),"Ha","Yo'q")) | AE25: =IF(AND($B25<>"",$AG25="",$AD25<>"",$AD25<Boshqaruv!$C$12),"Ha","") | AL25: =IF(OR($B25="",$C25="",$I25=""),"",IF(COUNTIFS($B$5:$B$404,$B25,$C$5:$C$404,$C25,$I$5:$I$404,$I25)>1,"Takror","")) | AM25: =IF(AND($B25<>"",$Q25="Ha",$I25<>"",$I25<=Boshqaruv!$C$12,OR($AG25="",$AG25>Boshqaruv!$C$12)),MAX($AM$4:$AM24)+1,"") | AN25: =IF(AND($B25<>"",$P25="Ha",$I25<>"",$I25<=Boshqaruv!$C$12,OR($AG25="",$AG25>Boshqaruv!$C$12)),MAX($AN$4:$AN24)+1,"")
A26: 22 | H26: =IF(OR($B26="",$C26=""),"",$B26&" ("&DAY($C26)&"."&MONTH($C26)&"."&YEAR($C26)&")") | K26: =IF($J26="","",$J26+280) | L26: =IF(OR($J26="",$AG26<>""),"",INT((Boshqaruv!$C$12-$J26)/7)) | M26: =IF(OR($I26="",$J26=""),"",INT(($I26-$J26)/7)) | N26: =IF($M26="","",IF($M26<=12,"Ha","Yo'q")) | O26: =IF(OR($C26="",$I26=""),"",INT(($I26-$C26)/365.25)) | P26: =IF($O26="","",IF($O26<18,"Ha","Yo'q")) | AA26: =IF(OR($Z26="",$J26=""),"",INT(($Z26-$J26)/7)) | AB26: =IF($AA26="","",IF(AND($AA26>=Spravochnik!$G$5,$AA26<=Spravochnik!$G$6),"Ha","Yo'q")) | AE26: =IF(AND($B26<>"",$AG26="",$AD26<>"",$AD26<Boshqaruv!$C$12),"Ha","") | AL26: =IF(OR($B26="",$C26="",$I26=""),"",IF(COUNTIFS($B$5:$B$404,$B26,$C$5:$C$404,$C26,$I$5:$I$404,$I26)>1,"Takror","")) | AM26: =IF(AND($B26<>"",$Q26="Ha",$I26<>"",$I26<=Boshqaruv!$C$12,OR($AG26="",$AG26>Boshqaruv!$C$12)),MAX($AM$4:$AM25)+1,"") | AN26: =IF(AND($B26<>"",$P26="Ha",$I26<>"",$I26<=Boshqaruv!$C$12,OR($AG26="",$AG26>Boshqaruv!$C$12)),MAX($AN$4:$AN25)+1,"")
A27: 23 | H27: =IF(OR($B27="",$C27=""),"",$B27&" ("&DAY($C27)&"."&MONTH($C27)&"."&YEAR($C27)&")") | K27: =IF($J27="","",$J27+280) | L27: =IF(OR($J27="",$AG27<>""),"",INT((Boshqaruv!$C$12-$J27)/7)) | M27: =IF(OR($I27="",$J27=""),"",INT(($I27-$J27)/7)) | N27: =IF($M27="","",IF($M27<=12,"Ha","Yo'q")) | O27: =IF(OR($C27="",$I27=""),"",INT(($I27-$C27)/365.25)) | P27: =IF($O27="","",IF($O27<18,"Ha","Yo'q")) | AA27: =IF(OR($Z27="",$J27=""),"",INT(($Z27-$J27)/7)) | AB27: =IF($AA27="","",IF(AND($AA27>=Spravochnik!$G$5,$AA27<=Spravochnik!$G$6),"Ha","Yo'q")) | AE27: =IF(AND($B27<>"",$AG27="",$AD27<>"",$AD27<Boshqaruv!$C$12),"Ha","") | AL27: =IF(OR($B27="",$C27="",$I27=""),"",IF(COUNTIFS($B$5:$B$404,$B27,$C$5:$C$404,$C27,$I$5:$I$404,$I27)>1,"Takror","")) | AM27: =IF(AND($B27<>"",$Q27="Ha",$I27<>"",$I27<=Boshqaruv!$C$12,OR($AG27="",$AG27>Boshqaruv!$C$12)),MAX($AM$4:$AM26)+1,"") | AN27: =IF(AND($B27<>"",$P27="Ha",$I27<>"",$I27<=Boshqaruv!$C$12,OR($AG27="",$AG27>Boshqaruv!$C$12)),MAX($AN$4:$AN26)+1,"")
A28: 24 | H28: =IF(OR($B28="",$C28=""),"",$B28&" ("&DAY($C28)&"."&MONTH($C28)&"."&YEAR($C28)&")") | K28: =IF($J28="","",$J28+280) | L28: =IF(OR($J28="",$AG28<>""),"",INT((Boshqaruv!$C$12-$J28)/7)) | M28: =IF(OR($I28="",$J28=""),"",INT(($I28-$J28)/7)) | N28: =IF($M28="","",IF($M28<=12,"Ha","Yo'q")) | O28: =IF(OR($C28="",$I28=""),"",INT(($I28-$C28)/365.25)) | P28: =IF($O28="","",IF($O28<18,"Ha","Yo'q")) | AA28: =IF(OR($Z28="",$J28=""),"",INT(($Z28-$J28)/7)) | AB28: =IF($AA28="","",IF(AND($AA28>=Spravochnik!$G$5,$AA28<=Spravochnik!$G$6),"Ha","Yo'q")) | AE28: =IF(AND($B28<>"",$AG28="",$AD28<>"",$AD28<Boshqaruv!$C$12),"Ha","") | AL28: =IF(OR($B28="",$C28="",$I28=""),"",IF(COUNTIFS($B$5:$B$404,$B28,$C$5:$C$404,$C28,$I$5:$I$404,$I28)>1,"Takror","")) | AM28: =IF(AND($B28<>"",$Q28="Ha",$I28<>"",$I28<=Boshqaruv!$C$12,OR($AG28="",$AG28>Boshqaruv!$C$12)),MAX($AM$4:$AM27)+1,"") | AN28: =IF(AND($B28<>"",$P28="Ha",$I28<>"",$I28<=Boshqaruv!$C$12,OR($AG28="",$AG28>Boshqaruv!$C$12)),MAX($AN$4:$AN27)+1,"")
... A404: 400 | H404: =IF(OR($B404="",$C404=""),"",$B404&" ("&DAY($C404)&"."&MONTH($C404)&"."&YEAR($C404)&")") | K404: =IF($J404="","",$J404+280) | L404: =IF(OR($J404="",$AG404<>""),"",INT((Boshqaruv!$C$12-$J404)/7)) | M404: =IF(OR($I404="",$J404=""),"",INT(($I404-$J404)/7)) | N404: =IF($M404="","",IF($M404<=12,"Ha","Yo'q")) | O404: =IF(OR($C404="",$I404=""),"",INT(($I404-$C404)/365.25)) | P404: =IF($O404="","",IF($O404<18,"Ha","Yo'q")) | AA404: =IF(OR($Z404="",$J404=""),"",INT(($Z404-$J404)/7)) | AB404: =IF($AA404="","",IF(AND($AA404>=Spravochnik!$G$5,$AA404<=Spravochnik!$G$6),"Ha","Yo'q")) | AE404: =IF(AND($B404<>"",$AG404="",$AD404<>"",$AD404<Boshqaruv!$C$12),"Ha","") | AL404: =IF(OR($B404="",$C404="",$I404=""),"",IF(COUNTIFS($B$5:$B$404,$B404,$C$5:$C$404,$C404,$I$5:$I$404,$I404)>1,"Takror","")) | AM404: =IF(AND($B404<>"",$Q404="Ha",$I404<>"",$I404<=Boshqaruv!$C$12,OR($AG404="",$AG404>Boshqaruv!$C$12)),MAX($AM$4:$AM403)+1,"") | AN404: =IF(AND($B404<>"",$P404="Ha",$I404<>"",$I404<=Boshqaruv!$C$12,OR($AG404="",$AG404>Boshqaruv!$C$12)),MAX($AN$4:$AN403)+1,"")

Sheet Xavfli_homiladorlar
A1: XAVFLI HOMILADORLAR / БЕРЕМЕННЫЕ ГРУППЫ РИСКА — avtomatik ro‘yxat
A2: «Homiladorlar»da «Xavf guruhida? = Ha» va chiqish sanasi yo‘q bo‘lganlar bu yerda o‘zi chiqadi. / Список строится сам: группа риска = Ha и нет даты выбытия.
A3: MAXFIY / КОНФИДЕНЦИАЛЬНО — shaxsiy va tibbiy ma’lumotlar (shifokorlik siri). Faylni parol bilan himoyalang, ochiq guruhlarga yubormang. / Персональные и медицинские данные (врачебная тайна). Защитите файл паролем, не отправляйте в открытые группы.
A4: № | B4: (qator) | C4: F.I.Sh. Ф.И.О. | D4: Tug‘ilgan sana Дата рожд. | E4: Mahalla Махалля | F4: Telefon Телефон | G4: Og‘irlik Тяжесть | H4: Asosiy diagnoz Диагноз | I4: MKB-10 | J4: Xavf omili Фактор риска | K4: Muddat, hafta Срок, нед. | L4: Taxminiy tug‘ruq Предп. роды | M4: Oxirgi ko‘rik Посл. осмотр | N4: Keyingi ko‘rik След. осмотр | O4: Muddati o‘tgan? Просрочен? | P4: Hujjat № № документа
A5: 1 | B5: =IFERROR(MATCH(A5,Homiladorlar!$AM$5:$AM$404,0),"") -> 1 | C5: =IF($B5="","",IF(INDEX(Homiladorlar!$B$5:$B$404,$B5)="","",INDEX(Homiladorlar!$B$5:$B$404,$B5))) -> Тестова Анна Ивановна | D5: =IF($B5="","",IF(INDEX(Homiladorlar!$C$5:$C$404,$B5)="","",INDEX(Homiladorlar!$C$5:$C$404,$B5))) -> 34768 | E5: =IF($B5="","",IF(INDEX(Homiladorlar!$F$5:$F$404,$B5)="","",INDEX(Homiladorlar!$F$5:$F$404,$B5))) -> Тестовая махалля | F5: =IF($B5="","",IF(INDEX(Homiladorlar!$E$5:$E$404,$B5)="","",INDEX(Homiladorlar!$E$5:$E$404,$B5))) -> +998900000000 | G5: =IF($B5="","",IF(INDEX(Homiladorlar!$R$5:$R$404,$B5)="","",INDEX(Homiladorlar!$R$5:$R$404,$B5))) | H5: =IF($B5="","",IF(INDEX(Homiladorlar!$T$5:$T$404,$B5)="","",INDEX(Homiladorlar!$T$5:$T$404,$B5))) | I5: =IF($B5="","",IF(INDEX(Homiladorlar!$U$5:$U$404,$B5)="","",INDEX(Homiladorlar!$U$5:$U$404,$B5))) | J5: =IF($B5="","",IF(INDEX(Homiladorlar!$S$5:$S$404,$B5)="","",INDEX(Homiladorlar!$S$5:$S$404,$B5))) | K5: =IF($B5="","",IF(INDEX(Homiladorlar!$L$5:$L$404,$B5)="","",INDEX(Homiladorlar!$L$5:$L$404,$B5))) -> 15 | L5: =IF($B5="","",IF(INDEX(Homiladorlar!$K$5:$K$404,$B5)="","",INDEX(Homiladorlar!$K$5:$K$404,$B5))) -> 46488 | M5: =IF($B5="","",IF(INDEX(Homiladorlar!$AC$5:$AC$404,$B5)="","",INDEX(Homiladorlar!$AC$5:$AC$404,$B5))) | N5: =IF($B5="","",IF(INDEX(Homiladorlar!$AD$5:$AD$404,$B5)="","",INDEX(Homiladorlar!$AD$5:$AD$404,$B5))) | O5: =IF($B5="","",IF(INDEX(Homiladorlar!$AE$5:$AE$404,$B5)="","",INDEX(Homiladorlar!$AE$5:$AE$404,$B5))) | P5: =IF($B5="","",IF(INDEX(Homiladorlar!$AI$5:$AI$404,$B5)="","",INDEX(Homiladorlar!$AI$5:$AI$404,$B5)))
