Workbook

Sheet Yoriqnoma
A1: YO‘RIQNOMA / ИНСТРУКЦИЯ — Vrach akusher-ginekolog
A2: Врач акушер-гинеколог
A3: MAXFIY / КОНФИДЕНЦИАЛЬНО — bu fayl shaxsiy va tibbiy ma’lumotlarni saqlaydi (shifokorlik siri). Faqat o‘zingizda saqlang, parol qo‘ying; o‘rinbosarga FAQAT «Chop_etish» varag‘i (qog‘oz) va «Eksport» qatori (yig‘ma sonlar) topshiriladi. / Файл хранит персональные и медицинские данные (врачебная тайна). Храните у себя, поставьте пароль; заместителю сдаются ТОЛЬКО лист «Chop_etish» (бумага) и строка «Eksport» (агрегаты).
B4: Kim to‘ldiradi / Кто заполняет | C4: Vrach akusher-ginekolog / Врач акушер-гинеколог
B5: Kimga topshiriladi / Кому сдаётся | C5: Birlashma boshlig'ining onalik va bolalikni muhofaza qilish bo'yicha o'rinbosari / Заместитель начальника объединения по охране материнства и детства
B6: Muddat / Срок | C6: Har hafta dushanba kuni soat 12:00 gacha / каждый понедельник до 12:00
B7: Papkalar / Папки | C7: № 7, 10, 11, 12, 13, 14, 15
A9: 1. Qanday ishlash kerak / Как работать
A10: № | B10: Qadam / Шаг | C10: O‘zbekcha (lotin) | D10: Русский
A11: 1 | B11: Tug‘ruqlarni kiriting | C11: Har bir tug‘ruq «Tugruqlar»ga yoziladi. Kesarcha bo‘lsa — 4513-son buyruq ro‘yxatidan tibbiy ko‘rsatmani tanlang yoki ixtiyoriy rozilik arizasi «Ha» deb belgilang; bo‘lmasa qator qizil bo‘ladi. | D11: Каждые роды — на лист «Tugruqlar». При кесаревом выберите показание из перечня приказа № 4513 или отметьте заявление о добровольном согласии «Ha»; иначе строка станет красной.
A12: 2 | B12: Homiladorlar nazorati | C12: Xavf guruhidagi homiladorlarni «Homiladorlar»da yuriting: diagnoz (hujjat raqami bilan), stasionarga yo‘llanma, ko‘riklar soni. Standart bajarilishi o‘zi hisoblanadi. | D12: Ведите беременных группы риска на «Homiladorlar»: диагноз (с № документа), направление в стационар, число осмотров. Выполнение стандарта считается само.
A13: 3 | B13: Boshqa jurnallar | C13: Ko‘rik №154, ginekologik kasalliklar, sitologiya, kontratseptiv berilishi, kunlik qabul — har biri o‘z varag‘ida. O‘lim holatlari — F.I.Sh.siz. | D13: Осмотр №154, гинекологические заболевания, цитология, выдача контрацептивов, ежедневный приём — каждое на своём листе. Случаи смерти — без ФИО.
A14: 4 | B14: «Boshqaruv» varag‘i | C14: Davr boshi va oxirini (C9, C10), muassasa va F.I.Sh.ni kiriting. Ko‘rsatkichlar jurnallardan o‘zi hisoblanadi; sariq ko‘rsatkichlarni qo‘lda kiriting. «TAYYORLIK» qatori «✔ TAYYOR» bo‘lishi kerak. | D14: Введите начало и конец периода (C9, C10), учреждение и ФИО. Показатели считаются сами из журналов; жёлтые показатели введите вручную. Строка «ГОТОВНОСТЬ» должна показать «✔ ГОТОВО».
A15: 5 | B15: «Chop_etish» varag‘i | C15: A4 qog‘ozga bir bet qilib chop eting, «Tayyorladi»ga imzo qo‘ying, rahbarga imzolating, M.O. joyiga muhr bosdiring. Qog‘ozdagi raqamlar Excel bilan bir xil bo‘lsin. | D15: Распечатайте на одном листе А4, подпишите («Подготовил(а)»), заверьте у руководителя и поставьте печать в поле М.П. Цифры на бумаге должны совпадать с Excel.
A16: 6 | B16: «Eksport» qatori va yuborish | C16: «Eksport» varag‘ining 4-qatori — yig‘ma sonlar (shaxsiy ma’lumotsiz). Faylni EMAS, faqat shu qatorni (yoki «Chop_etish»ni) yuboring. Fayl nomi: Rol_Muassasa_Davr.xlsx. | D16: Строка 4 листа «Eksport» — агрегированные числа (без персональных данных). Отправляйте не файл, а только эту строку (или «Chop_etish»). Имя файла: Роль_Учреждение_Период.xlsx.
A18: 2. Varaqlar va jurnallar / Листы и журналы
A19: № | B19: Varaq / Лист | C19: Nima uchun / Для чего (uz) | D19: Для чего (ru)
A20: 1 | B20: Tugruqlar | C20: Tug‘ruqlar: sana, tug‘ruq tarixi №, turi, asorat, kesarcha uchun tibbiy ko‘rsatma (31 ta ro‘yxat) yoki ixtiyoriy rozilik arizasi. Ko‘rsatkichlar 1, 2, 15–18, 21 shundan. | D20: Роды: дата, № истории родов, тип, осложнение, показание к кесареву (перечень из 31) или заявление о добровольном согласии. Показатели 1, 2, 15–18, 21 — отсюда.
A21: 2 | B21: Homiladorlar | C21: Nazoratdagi homiladorlar: xavf guruhi, diagnoz, stasionarga yo‘llanma, antenatal ko‘riklar soni (standart avto), skrining. Ko‘rsatkichlar 8, 11–14, 20, 22. | D21: Беременные под наблюдением: группа риска, диагноз, направление в стационар, число антенатальных осмотров (стандарт — авто), скрининг. Показатели 8, 11–14, 20, 22.
A22: 3 | B22: Xavfli_homiladorlar | C22: Yuqori xavfli homiladorlar ro‘yxati (avto). | D22: Список беременных высокого риска (авто).
A23: 4 | B23: Korik_154 | C23: Tug‘ish yoshidagi ayollar tibbiy ko‘rigi (№154): ko‘rsatkich 4. | D23: Медосмотр женщин фертильного возраста (№154): показатель 4.
A24: 5 | B24: Ginekologik | C24: Aniqlangan kasalliklar (ko‘rsatkich 5) va sog‘lomlashtirilganlar (6). | D24: Выявленные заболевания (показатель 5) и оздоровленные (6).
A25: 6 | B25: Sitologiya | C25: Surtma olingan ayollar (ko‘rsatkich 19). | D25: Женщины, у которых взят мазок (показатель 19).
A26: 7 | B26: Kontratseptiv | C26: Berilgan / qo‘yilgan kontratseptiv vositalar (ko‘rsatkich 7). | D26: Выданные / установленные контрацептивы (показатель 7).
A27: 8 | B27: Qabul_kunlik | C27: Ambulator qabullar soni (ko‘rsatkich 3). | D27: Число амбулаторных приёмов (показатель 3).
A28: 9 | B28: Olim_holatlari | C28: Ayollar va onalar o‘limi (ko‘rsatkichlar 9, 10). F.I.Sh. kiritilmaydi. | D28: Случаи смерти женщин и матерей (показатели 9, 10). ФИО не вносится.
A29: 10 | B29: Boshqaruv | C29: Davr, ko‘rsatkichlar (avto), tekshiruvlar, tayyorlik. | D29: Период, показатели (авто), проверки, готовность.
A30: 11 | B30: Hujjatlar | C30: Topshiriladigan hujjatlar ro‘yxati va ularning holati. | D30: Перечень сдаваемых документов и их статус.
A31: 12 | B31: Chop_etish | C31: Qog‘oz nusxa (imzo va muhr uchun). | D31: Бумажный экземпляр (для подписи и печати).
A32: 13 | B32: Eksport | C32: O‘rinbosarga yuboriladigan bir qator. | D32: Строка для отправки заместителю.
A34: 3. Qoidalar / Правила
A35: № | B35: Qoida / Правило | C35: O‘zbekcha (lotin) | D35: Русский
A36: 1 | B36: Ranglar | C36: Sariq katak — kiritiladi. Yashil — avtomatik (tegmang). Kulrang — yordamchi ustun. Qizil — xato/muddat o‘tgan. Ustun sarlavhasi: ko‘k — kiritish, yashil — avtomatik. | D36: Жёлтая — ввод. Зелёная — авто (не трогать). Серая — вспомогательная. Красная — ошибка/просрочка. Заголовок: синий — ввод, зелёный — авто.
A37: 2 | B37: Bir marta yozing | C37: Har bir shaxs/hodisa bitta qatorga yoziladi; takror yozuv qizil bo‘ladi. Sanani kun.oy.yil ko‘rinishida kiriting. | D37: Каждый человек/событие — одна строка; дубль подсвечивается красным. Даты вводите как дд.мм.гггг.
A38: 3 | B38: Tashxis va xavf | C38: Tashxis va xavf sababini faqat davolovchi shifokor hujjatidan (karta, xulosa) ko‘chiring — o‘zingizdan yozmang; hujjat raqamini ham yozing. | D38: Диагноз и причину риска переписывайте только из документа лечащего врача (карта, заключение), не от себя; укажите № документа.
A39: 4 | B39: Maxfiylik | C39: Fayl faqat sizda; guruhga yubormang. PINFL — 14 ta raqam, «PINFL» ustuniga; faylni parol bilan himoyalang. Yig‘ma ma’lumot — «Eksport» va «Chop_etish». | D39: Файл только у вас; в группы не отправлять. ПИНФЛ — 14 цифр, в столбец «ПИНФЛ»; защитите файл паролем. Агрегаты — «Eksport» и «Chop_etish».
A40: 5 | B40: Nusxa | C40: Har oy oxirida faylning zaxira nusxasini saqlang (Fayl → Boshqacha saqlash). | D40: В конце каждого месяца сохраняйте резервную копию файла.
A41: 6 | B41: Eng ko‘p xatolar | C41: Sanani matn qilib yozish; yashil katakni o‘zgartirish; ro‘yxatdan tashqari qiymat; davrni (C9, C10) kiritmaslik; qog‘oz va Excel raqamlari mos kelmasligi; imzo/muhrsiz topshirish. | D41: Дата текстом; правка зелёных ячеек; значение не из списка; не введён период (C9, C10); цифры на бумаге и в Excel не совпадают; сдача без подписи/печати.
A43: 4. Eslatmalar / Примечания
A44: 1 | B44: Kesarcha ro‘yxati | C44: Tibbiy ko‘rsatmalar ro‘yxati — O‘zbekiston Respublikasi Sog‘liqni saqlash vazirining 2026-yil 10-sentabrdagi 4513-son buyrug‘i (Adliya vazirligida 28.09.2026-y. da 3945 bilan ro‘yxatdan o‘tgan). Ma’lumotlar shifokorlik siri hisoblanadi. | D44: Перечень показаний — приказ Министра здравоохранения № 4513 от 10.09.2026 (зарегистрирован в Минюсте 28.09.2026 за № 3945). Сведения составляют врачебную тайну.

Sheet Boshqaruv
A1: BOSHQARUV VA KO‘RSATKICHLAR / УПРАВЛЕНИЕ И ПОКАЗАТЕЛИ — Vrach akusher-ginekolog
A2: Врач акушер-гинеколог
A3: Bu yerda faqat davr va ma’lumotlarni kiriting; ko‘rsatkichlar jurnallardan O‘ZI hisoblanadi (yashil). Sariq katak — qo‘lda kiritiladi. / Здесь вводятся период и реквизиты; показатели считаются САМИ из журналов (зелёные). Жёлтая ячейка — вводится вручную.
B5: Muassasa (nomi, №) / Учреждение | C5: Район. больница (тест)
B6: F.I.Sh. (to‘ldiruvchi) / Ф.И.О. (заполняющий) | C6: Акушерова Тест
B7: Lavozimi / Должность | C7: Vrach akusher-ginekolog / Врач акушер-гинеколог
B8: Telefon / Телефон | C8: +998900000004
B9: Davr boshi (sana) / Начало периода (дата) | C9: 46307 | D9: ← masalan / напр.: 01.09.2026
B10: Davr oxiri (sana) / Конец периода (дата) | C10: 46313 | D10: ← masalan / напр.: 30.09.2026
B11: Davr (avto) / Период (авто) | C11: =IF(OR(C9="",C10=""),"",DAY(C9)&"."&MONTH(C9)&"."&YEAR(C9)&" – "&DAY(C10)&"."&MONTH(C10)&"."&YEAR(C10)) -> 12.10.2026 – 18.10.2026
B12: Hisob sanasi (avto: davr oxiri, bo‘sh bo‘lsa — bugun) / Дата расчёта (авто: конец периода, иначе сегодня) | C12: =IF(C10="",TODAY(),C10) -> 46313
B13: TAYYORLIK / ГОТОВНОСТЬ | C13: =IF(IF(OR(C9="",C10=""),"davrni kiriting (C9, C10); ","")&IF(AND(C9<>"",C10<>"",C10<C9),"davr oxiri boshidan oldin; ","")&IF(OR(C5="",C6=""),"muassasa va F.I.Sh.; ","")&IF(SUM(D42,D44,D45,D46,D47,D48,D50,D51,D52,D53,D54,D55,D56,D57,D58,D59,D60)>0,"jurnallarda xatolar bor (pastga qarang); ","")="","✔ TAYYOR / ГОТОВО","✖ TO‘LIQ EMAS / НЕ ПОЛНО: "&IF(OR(C9="",C10=""),"davrni kiriting (C9, C10); ","")&IF(AND(C9<>"",C10<>"",C10<C9),"davr oxiri boshidan oldin; ","")&IF(OR(C5="",C6=""),"muassasa va F.I.Sh.; ","")&IF(SUM(D42,D44,D45,D46,D47,D48,D50,D51,D52,D53,D54,D55,D56,D57,D58,D59,D60)>0,"jurnallarda xatolar bor (pastga qarang); ","")) -> ✖ TO‘LIQ EMAS / НЕ ПОЛНО: jurnallarda xatolar bor (pastga qarang);
B14: HUJJATLAR / ДОКУМЕНТЫ | C14: =IF(COUNTBLANK(Hujjatlar!E5:E17)=0,"✔ Hammasi belgilangan / Всё отмечено","✖ Hujjatlar varag‘ida belgilanmagan: "&COUNTBLANK(Hujjatlar!E5:E17)&" ta") -> ✖ Hujjatlar varag‘ida belgilanmagan: 13 ta
A16: T/r | B16: Ko‘rsatkich | C16: Показатель | D16: Birlik | E16: Papka | F16: Qiymat / Значение | G16: Manba / Источник и как считается
A17: 1 | B17: Tug'ruqlar soni | C17: Число родов | D17: ta | E17: 7 | F17: =IF(OR(Boshqaruv!$C$9="",Boshqaruv!$C$10=""),"",COUNTIFS(Tugruqlar!$B$5:$B$604,">="&Boshqaruv!$C$9,Tugruqlar!$B$5:$B$604,"<="&Boshqaruv!$C$10,Tugruqlar!$C$5:$C$604,"<>")) -> 0 | G17: AVTOMATIK: «Tugruqlar»: davrdagi tug‘ruqlar soni. / АВТОМАТИЧЕСКИ: «Tugruqlar»: число родов за период.
A18: 2 | B18: Shundan asoratli tug'ruqlar | C18: Из них с осложнениями | D18: ta | E18: 7 | F18: =IF(OR(Boshqaruv!$C$9="",Boshqaruv!$C$10=""),"",COUNTIFS(Tugruqlar!$B$5:$B$604,">="&Boshqaruv!$C$9,Tugruqlar!$B$5:$B$604,"<="&Boshqaruv!$C$10,Tugruqlar!$L$5:$L$604,"Ha")) -> 0 | G18: AVTOMATIK: «Tugruqlar»: asoratli tug‘ruq = Ha. / АВТОМАТИЧЕСКИ: «Tugruqlar»: осложнённые роды = Ha.
A19: 3 | B19: Ayollarning ambulator qabullari | C19: Амбулаторные приёмы женщин | D19: ta | E19: 7 | F19: =IF(OR(Boshqaruv!$C$9="",Boshqaruv!$C$10=""),"",SUMIFS(Qabul_kunlik!$C$5:$C$404,Qabul_kunlik!$B$5:$B$404,">="&Boshqaruv!$C$9,Qabul_kunlik!$B$5:$B$404,"<="&Boshqaruv!$C$10)) -> 0 | G19: AVTOMATIK: «Qabul_kunlik»: jami qabul yig‘indisi. / АВТОМАТИЧЕСКИ: «Qabul_kunlik»: сумма приёмов.
A20: 4 | B20: Tibbiy ko'rikdan o'tgan tug'ish yoshidagi ayollar (№154) | C20: Осмотрено женщин фертильного возраста (№154) | D20: nafar | E20: 13 | F20: =IF(OR(Boshqaruv!$C$9="",Boshqaruv!$C$10=""),"",COUNTIFS(Korik_154!$B$5:$B$1504,">="&Boshqaruv!$C$9,Korik_154!$B$5:$B$1504,"<="&Boshqaruv!$C$10,Korik_154!$C$5:$C$1504,"<>")) -> 0 | G20: AVTOMATIK: «Korik_154»: davrda ko‘rikdan o‘tganlar. / АВТОМАТИЧЕСКИ: «Korik_154»: осмотренные за период.
A21: 5 | B21: Aniqlangan ginekologik kasalliklar | C21: Выявлено гинекологических заболеваний | D21: ta | E21: 13 | F21: =IF(OR(Boshqaruv!$C$9="",Boshqaruv!$C$10=""),"",COUNTIFS(Ginekologik!$B$5:$B$804,">="&Boshqaruv!$C$9,Ginekologik!$B$5:$B$804,"<="&Boshqaruv!$C$10,Ginekologik!$C$5:$C$804,"<>")) -> 0 | G21: AVTOMATIK: «Ginekologik»: davrda aniqlanganlar. / АВТОМАТИЧЕСКИ: «Ginekologik»: выявленные за период.
A22: 6 | B22: Sog'lomlashtirilgan ayollar | C22: Оздоровлено женщин | D22: nafar | E22: 13 | F22: =IF(OR(Boshqaruv!$C$9="",Boshqaruv!$C$10=""),"",COUNTIFS(Ginekologik!$K$5:$K$804,">="&Boshqaruv!$C$9,Ginekologik!$K$5:$K$804,"<="&Boshqaruv!$C$10,Ginekologik!$C$5:$C$804,"<>")) -> 0 | G22: AVTOMATIK: «Ginekologik»: sog‘lomlashtirilgan sana davrda. / АВТОМАТИЧЕСКИ: «Ginekologik»: дата оздоровления в периоде.
A23: 7 | B23: Berilgan / qo'yilgan kontratseptiv vositalar | C23: Выдано / установлено контрацептивов | D23: ta | E23: 12 | F23: =IF(OR(Boshqaruv!$C$9="",Boshqaruv!$C$10=""),"",SUMIFS(Kontratseptiv!$H$5:$H$804,Kontratseptiv!$B$5:$B$804,">="&Boshqaruv!$C$9,Kontratseptiv!$B$5:$B$804,"<="&Boshqaruv!$C$10)) -> 0 | G23: AVTOMATIK: «Kontratseptiv»: «Soni» yig‘indisi. / АВТОМАТИЧЕСКИ: «Kontratseptiv»: сумма «Soni».
A24: 8 | B24: Skriningga yuborilgan homiladorlar | C24: Направлено беременных на скрининг | D24: nafar | E24: 11 | F24: =IF(OR(Boshqaruv!$C$9="",Boshqaruv!$C$10=""),"",COUNTIFS(Homiladorlar!$Y$5:$Y$804,">="&Boshqaruv!$C$9,Homiladorlar!$Y$5:$Y$804,"<="&Boshqaruv!$C$10,Homiladorlar!$B$5:$B$804,"<>")) -> 0 | G24: AVTOMATIK: «Homiladorlar»: skriningga yo‘llangan sana davrda. / АВТОМАТИЧЕСКИ: «Homiladorlar»: дата направления на скрининг в периоде.
A25: 9 | B25: Ayollar o'limi holatlari | C25: Случаи смерти женщин | D25: ta | E25: 7 | F25: =IF(OR(Boshqaruv!$C$9="",Boshqaruv!$C$10=""),"",COUNTIFS(Olim_holatlari!$B$5:$B$64,">="&Boshqaruv!$C$9,Olim_holatlari!$B$5:$B$64,"<="&Boshqaruv!$C$10,Olim_holatlari!$C$5:$C$64,"<>")) -> 0 | G25: AVTOMATIK: «Olim_holatlari»: barcha yozuvlar (onalar o‘limi ham kiradi). / АВТОМАТИЧЕСКИ: «Olim_holatlari»: все записи (включая материнскую смертность).
A26: 10 | B26: Onalar o'limi holatlari | C26: Случаи материнской смерти | D26: ta | E26: 15 | F26: =IF(OR(Boshqaruv!$C$9="",Boshqaruv!$C$10=""),"",COUNTIFS(Olim_holatlari!$B$5:$B$64,">="&Boshqaruv!$C$9,Olim_holatlari!$B$5:$B$64,"<="&Boshqaruv!$C$10,Olim_holatlari!$C$5:$C$64,"Ona o'limi")) -> 0 | G26: AVTOMATIK: «Olim_holatlari»: turi = Ona o‘limi. / АВТОМАТИЧЕСКИ: «Olim_holatlari»: вид = Ona o‘limi.
A27: 11 | B27: Yuqori xavfli homiladorlar (nazoratda, davr oxiriga) | C27: Беременные высокого риска под наблюдением (на конец периода) | D27: nafar | E27: 7 | F27: =IF(OR(Boshqaruv!$C$9="",Boshqaruv!$C$10=""),"",(COUNTIFS(Homiladorlar!$H$5:$H$804,"<="&Boshqaruv!$C$10,Homiladorlar!$AE$5:$AE$804,"",Homiladorlar!$N$5:$N$804,"Ha")+COUNTIFS(Homiladorlar!$H$5:$H$804,"<="&Boshqaruv!$C$10,Homiladorlar!$AE$5:$AE$804,">"&Boshqaruv!$C$10,Homiladorlar!$N$5:$N$804,"Ha"))) -> 0 | G27: AVTOMATIK: «Homiladorlar»: xavf guruhi = Ha, davr oxiriga nazoratda. / АВТОМАТИЧЕСКИ: «Homiladorlar»: группа риска = Ha, на наблюдении на конец периода. [Asos: 180-son buyruq (2025), antenatal parvarish standarti]
A28: 12 | B28: Shundan stasionarga yo‘llanganlar | C28: Из них направлено в стационар | D28: nafar | E28: 7 | F28: =IF(OR(Boshqaruv!$C$9="",Boshqaruv!$C$10=""),"",(COUNTIFS(Homiladorlar!$H$5:$H$804,"<="&Boshqaruv!$C$10,Homiladorlar!$AE$5:$AE$804,"",Homiladorlar!$N$5:$N$804,"Ha",Homiladorlar!$T$5:$T$804,"<>")+COUNTIFS(Homiladorlar!$H$5:$H$804,"<="&Boshqaruv!$C$10,Homiladorlar!$AE$5:$AE$804,">"&Boshqaruv!$C$10,Homiladorlar!$N$5:$N$804,"Ha",Homiladorlar!$T$5:$T$804,"<>"))) -> 0 | G28: AVTOMATIK: «Homiladorlar»: shundan stasionarga yo‘llanma sanasi bor. / АВТОМАТИЧЕСКИ: «Homiladorlar»: из них есть дата направления в стационар. [Asos: 180-son buyruq (2025), antenatal parvarish standarti]
A29: 13 | B29: Standartga mos antenatal ko‘riklardan o‘tgan homiladorlar (oilaviy shifokor ≥9, akusher-ginekolog ≥3) | C29: Беременные с антенатальными осмотрами по стандарту (семейный врач ≥9, акушер-гинеколог ≥3) | D29: nafar | E29: 10 | F29: =IF(OR(Boshqaruv!$C$9="",Boshqaruv!$C$10=""),"",COUNTIFS(Homiladorlar!$AE$5:$AE$804,">="&Boshqaruv!$C$9,Homiladorlar!$AE$5:$AE$804,"<="&Boshqaruv!$C$10,Homiladorlar!$X$5:$X$804,"Ha",Homiladorlar!$AD$5:$AD$804,"Tug'di")) -> 0 | G29: AVTOMATIK: «Homiladorlar»: davrda tuqqan va antenatal standart = Ha (oilaviy shifokor ≥9, akusher-ginekolog ≥3 — Spravochnik parametrlari). Ta’rifni o‘rinbosar bilan tasdiqlang. / АВТОМАТИЧЕСКИ: «Homiladorlar»: родившие в периоде и стандарт = Ha (семейный врач ≥9, акушер-гинеколог ≥3 — параметры на Spravochnik). Уточните определение у заместителя. [Asos: 180-son buyruq (2025), antenatal parvarish standarti]
A30: 14 | B30: I trimestr prenatal skriningdan o‘tgan homiladorlar | C30: Прошли пренатальный скрининг I триместра | D30: nafar | E30: 11 | F30: =IF(OR(Boshqaruv!$C$9="",Boshqaruv!$C$10=""),"",COUNTIFS(Homiladorlar!$Z$5:$Z$804,">="&Boshqaruv!$C$9,Homiladorlar!$Z$5:$Z$804,"<="&Boshqaruv!$C$10,Homiladorlar!$B$5:$B$804,"<>")) -> 0 | G30: AVTOMATIK: «Homiladorlar»: I trimestr skrining sanasi davrda. / АВТОМАТИЧЕСКИ: «Homiladorlar»: дата скрининга I триместра в периоде. [Asos: 180-son buyruq (2025), antenatal parvarish standarti]
A31: 15 | B31: Kesarcha kesish amaliyotlari | C31: Операции кесарева сечения | D31: ta | E31: 14 | F31: =IF(OR(Boshqaruv!$C$9="",Boshqaruv!$C$10=""),"",COUNTIFS(Tugruqlar!$B$5:$B$604,">="&Boshqaruv!$C$9,Tugruqlar!$B$5:$B$604,"<="&Boshqaruv!$C$10,Tugruqlar!$K$5:$K$604,"Kesarcha")) -> 0 | G31: AVTOMATIK: «Tugruqlar»: tug‘ruq turi = Kesarcha. / АВТОМАТИЧЕСКИ: «Tugruqlar»: тип родов = Kesarcha. [Asos: 4513-son buyruq (2026), kesarcha kesish ro‘yxati]
A32: 16 | B32: Shundan tibbiy ko‘rsatma asosida (4513-son ro‘yxat) | C32: Из них по медицинским показаниям (перечень, приказ №4513) | D32: ta | E32: 14 | F32: =IF(OR(Boshqaruv!$C$9="",Boshqaruv!$C$10=""),"",COUNTIFS(Tugruqlar!$B$5:$B$604,">="&Boshqaruv!$C$9,Tugruqlar!$B$5:$B$604,"<="&Boshqaruv!$C$10,Tugruqlar!$K$5:$K$604,"Kesarcha",Tugruqlar!$O$5:$O$604,"<>")) -> 0 | G32: AVTOMATIK: «Tugruqlar»: kesarcha va tibbiy ko‘rsatma tanlangan (4513-son buyruq). / АВТОМАТИЧЕСКИ: «Tugruqlar»: кесарево и выбрано показание (приказ № 4513). [Asos: 4513-son buyruq (2026), kesarcha kesish ro‘yxati]
A33: 17 | B33: Ixtiyoriy rozilik arizasi rasmiylashtirilgan kesarcha kesishlar | C33: Кесарево сечение с оформленным заявлением о добровольном согласии | D33: ta | E33: 14 | F33: =IF(OR(Boshqaruv!$C$9="",Boshqaruv!$C$10=""),"",COUNTIFS(Tugruqlar!$B$5:$B$604,">="&Boshqaruv!$C$9,Tugruqlar!$B$5:$B$604,"<="&Boshqaruv!$C$10,Tugruqlar!$K$5:$K$604,"Kesarcha",Tugruqlar!$R$5:$R$604,"Ha")) -> 0 | G33: AVTOMATIK: «Tugruqlar»: kesarcha va ixtiyoriy rozilik arizasi = Ha. / АВТОМАТИЧЕСКИ: «Tugruqlar»: кесарево и заявление о добровольном согласии = Ha. [Asos: 4513-son buyruq (2026), kesarcha kesish ro‘yxati]
A34: 18 | B34: Kesarcha kesishda ixtiyoriy rozilik arizasi ulushi | C34: Доля кесарева с заявлением о согласии | D34: % | E34: 14 | F34: =IF(OR(Boshqaruv!$C$9="",Boshqaruv!$C$10=""),"",IF(N($F$31)=0,"",$F$33/$F$31)) | G34: AVTOMATIK: 17-qator / 15-qator. / АВТОМАТИЧЕСКИ: Строка 17 / строка 15. [Asos: 4513-son buyruq (2026), kesarcha kesish ro‘yxati]
A35: 19 | B35: Bachadon bo‘yni sitologiyasi (surtma) olingan ayollar | C35: Взят цитологический мазок шейки матки | D35: nafar | E35: 13 | F35: =IF(OR(Boshqaruv!$C$9="",Boshqaruv!$C$10=""),"",COUNTIFS(Sitologiya!$B$5:$B$804,">="&Boshqaruv!$C$9,Sitologiya!$B$5:$B$804,"<="&Boshqaruv!$C$10,Sitologiya!$C$5:$C$804,"<>")) -> 0 | G35: AVTOMATIK: «Sitologiya»: davrdagi surtmalar. / АВТОМАТИЧЕСКИ: «Sitologiya»: мазки за период. [Asos: 180-son buyruq (2025), antenatal parvarish standarti]
A36: 20 | B36: [Voyaga yetmaganlar] Nazoratdagi homilador qizlar (18 yoshgacha) | C36: [Несовершеннолетние] Беременные девочки под наблюдением (до 18 лет) | D36: nafar | E36: 7 | F36: =IF(OR(Boshqaruv!$C$9="",Boshqaruv!$C$10=""),"",(COUNTIFS(Homiladorlar!$H$5:$H$804,"<="&Boshqaruv!$C$10,Homiladorlar!$AE$5:$AE$804,"",Homiladorlar!$M$5:$M$804,"Ha")+COUNTIFS(Homiladorlar!$H$5:$H$804,"<="&Boshqaruv!$C$10,Homiladorlar!$AE$5:$AE$804,">"&Boshqaruv!$C$10,Homiladorlar!$M$5:$M$804,"Ha"))) -> 0 | G36: AVTOMATIK: «Homiladorlar»: hisobga olishda 18 yoshgacha, nazoratda. / АВТОМАТИЧЕСКИ: «Homiladorlar»: до 18 лет при постановке, на наблюдении. [Asos: 263-son buyruq (2022), doya vazifalari]
A37: 21 | B37: [Voyaga yetmaganlar] Tug‘ruqlar (18 yoshgacha) | C37: [Несовершеннолетние] Роды (до 18 лет) | D37: ta | E37: 7 | F37: =IF(OR(Boshqaruv!$C$9="",Boshqaruv!$C$10=""),"",COUNTIFS(Tugruqlar!$B$5:$B$604,">="&Boshqaruv!$C$9,Tugruqlar!$B$5:$B$604,"<="&Boshqaruv!$C$10,Tugruqlar!$H$5:$H$604,"Ha")) -> 0 | G37: AVTOMATIK: «Tugruqlar»: tug‘ruq vaqtida 18 yoshgacha. / АВТОМАТИЧЕСКИ: «Tugruqlar»: до 18 лет на момент родов. [Asos: 263-son buyruq (2022), doya vazifalari]
A38: 22 | B38: [Voyaga yetmaganlar] Xavf guruhidagi homilador qizlar | C38: [Несовершеннолетние] Беременные девочки группы риска | D38: nafar | E38: 7 | F38: =IF(OR(Boshqaruv!$C$9="",Boshqaruv!$C$10=""),"",(COUNTIFS(Homiladorlar!$H$5:$H$804,"<="&Boshqaruv!$C$10,Homiladorlar!$AE$5:$AE$804,"",Homiladorlar!$M$5:$M$804,"Ha",Homiladorlar!$N$5:$N$804,"Ha")+COUNTIFS(Homiladorlar!$H$5:$H$804,"<="&Boshqaruv!$C$10,Homiladorlar!$AE$5:$AE$804,">"&Boshqaruv!$C$10,Homiladorlar!$M$5:$M$804,"Ha",Homiladorlar!$N$5:$N$804,"Ha"))) -> 0 | G38: AVTOMATIK: «Homiladorlar»: 18 yoshgacha va xavf guruhi = Ha. / АВТОМАТИЧЕСКИ: «Homiladorlar»: до 18 лет и группа риска = Ha. [Asos: 180-son buyruq (2025), antenatal parvarish standarti]
A40: TEKSHIRUV / ПРОВЕРКА MA’LUMOT SIFATI
B41: Tekshiruv | C41: Проверка | D41: Soni | F41: Holat | G41: Nima qilish kerak / Что делать
B42: Kesarcha: ko‘rsatma ham, rozilik arizasi ham yo‘q | C42: Кесарево: нет ни показания, ни заявления о согласии | D42: =COUNTIF(Tugruqlar!$S$5:$S$604,"YO‘Q") -> 0 | F42: =IF(N(D42)=0,"✔ OK",IF("err"="err","✖ XATO / ОШИБКА","⚠ DIQQAT / ВНИМАНИЕ")) -> ✔ OK | G42: 4513-son buyruq: ko‘rsatma raqamini tanlang yoki rozilik arizasini belgilang / Выберите № показания или отметьте заявление
B43: Ko‘rsatma tanlangan, lekin tug‘ruq turi «Kesarcha» emas | C43: Показание выбрано, но тип родов не «Kesarcha» | D43: =COUNTIFS(Tugruqlar!$O$5:$O$604,"<>",Tugruqlar!$K$5:$K$604,"<>Kesarcha") -> 0 | F43: =IF(N(D43)=0,"✔ OK",IF("warn"="err","✖ XATO / ОШИБКА","⚠ DIQQAT / ВНИМАНИЕ")) -> ✔ OK | G43: Tug‘ruq turini tekshiring / Проверьте тип родов
...

Sheet Tugruqlar
A1: TUG‘RUQLAR JURNALI / ЖУРНАЛ РОДОВ (kesarcha kesish — 4513-son buyruq bo‘yicha)
A2: Har bir tug‘ruq — bitta qator. Kesarcha bo‘lsa — tibbiy ko‘rsatma raqamini tanlang YOKI ixtiyoriy rozilik arizasi «Ha» deb belgilang. / Каждые роды — одна строка. При кесаревом выберите № показания ИЛИ отметьте заявление о добровольном согласии «Ha».
A3: MAXFIY / КОНФИДЕНЦИАЛЬНО — shaxsiy va tibbiy ma’lumotlar (shifokorlik siri). Faylni parol bilan himoyalang, ochiq guruhlarga yubormang. / Персональные и медицинские данные (врачебная тайна). Защитите файл паролем, не отправляйте в открытые группы.
A4: № | B4: Tug‘ruq sanasi Дата родов | C4: F.I.Sh. (to‘liq) Ф.И.О. | D4: Tug‘ilgan sana Дата рождения | E4: PINFL (14 raqam) ПИНФЛ (14 цифр) | F4: Telefon Телефон | G4: Yosh (avto) Возраст | H4: Voyaga yetmagan? (avto) Несоверш.? | I4: Tug‘ilish tarixi № № истории родов | J4: Tug‘ruq muddati (hafta) Срок родов (нед.) | K4: Tug‘ruq turi Тип родов | L4: Asoratli tug‘ruqmi? Осложнённые роды? | M4: Asorat (diagnoz) Осложнение (диагноз) | N4: Natija Исход | O4: Kesarcha uchun tibbiy ko‘rsatma Показание к кесареву | P4: Ko‘rsatma № (avto) № показания | Q4: Ko‘rsatma guruhi (avto) Группа показания | R4: Ixtiyoriy rozilik arizasi rasmiylashtirilganmi? Заявление о добровольном согласии оформлено? | S4: Kesarcha asosi to‘liqmi? (avto) Основание кесарева полное? | T4: Tug‘ruq tarixi / hujjat Документ | U4: Izoh Примечание | V4: Takror? (avto) Дубль?
A5: 1 | G5: =IF(OR($D5="",$B5=""),"",INT(($B5-$D5)/365.25)) | H5: =IF($G5="","",IF($G5<18,"Ha","Yo'q")) | P5: =IF($O5="","",IFERROR(VALUE(LEFT($O5,FIND(".",$O5)-1)),"")) | Q5: =IF($P5="","",IF($P5<=7,"Shoshilinch",IF($P5<=9,"Kechiktirib bo'lmaydigan",IF($P5<=14,"Rejalashtirilgan","Rejali")))) | S5: =IF($K5<>"Kesarcha","",IF(OR($O5<>"",$R5="Ha"),"Ha","YO‘Q")) | V5: =IF(OR($C5="",$D5="",$B5=""),"",IF(COUNTIFS($C$5:$C$604,$C5,$D$5:$D$604,$D5,$B$5:$B$604,$B5)>1,"Takror",""))
A6: 2 | G6: =IF(OR($D6="",$B6=""),"",INT(($B6-$D6)/365.25)) | H6: =IF($G6="","",IF($G6<18,"Ha","Yo'q")) | P6: =IF($O6="","",IFERROR(VALUE(LEFT($O6,FIND(".",$O6)-1)),"")) | Q6: =IF($P6="","",IF($P6<=7,"Shoshilinch",IF($P6<=9,"Kechiktirib bo'lmaydigan",IF($P6<=14,"Rejalashtirilgan","Rejali")))) | S6: =IF($K6<>"Kesarcha","",IF(OR($O6<>"",$R6="Ha"),"Ha","YO‘Q")) | V6: =IF(OR($C6="",$D6="",$B6=""),"",IF(COUNTIFS($C$5:$C$604,$C6,$D$5:$D$604,$D6,$B$5:$B$604,$B6)>1,"Takror",""))
A7: 3 | G7: =IF(OR($D7="",$B7=""),"",INT(($B7-$D7)/365.25)) | H7: =IF($G7="","",IF($G7<18,"Ha","Yo'q")) | P7: =IF($O7="","",IFERROR(VALUE(LEFT($O7,FIND(".",$O7)-1)),"")) | Q7: =IF($P7="","",IF($P7<=7,"Shoshilinch",IF($P7<=9,"Kechiktirib bo'lmaydigan",IF($P7<=14,"Rejalashtirilgan","Rejali")))) | S7: =IF($K7<>"Kesarcha","",IF(OR($O7<>"",$R7="Ha"),"Ha","YO‘Q")) | V7: =IF(OR($C7="",$D7="",$B7=""),"",IF(COUNTIFS($C$5:$C$604,$C7,$D$5:$D$604,$D7,$B$5:$B$604,$B7)>1,"Takror",""))
A8: 4 | G8: =IF(OR($D8="",$B8=""),"",INT(($B8-$D8)/365.25)) | H8: =IF($G8="","",IF($G8<18,"Ha","Yo'q")) | P8: =IF($O8="","",IFERROR(VALUE(LEFT($O8,FIND(".",$O8)-1)),"")) | Q8: =IF($P8="","",IF($P8<=7,"Shoshilinch",IF($P8<=9,"Kechiktirib bo'lmaydigan",IF($P8<=14,"Rejalashtirilgan","Rejali")))) | S8: =IF($K8<>"Kesarcha","",IF(OR($O8<>"",$R8="Ha"),"Ha","YO‘Q")) | V8: =IF(OR($C8="",$D8="",$B8=""),"",IF(COUNTIFS($C$5:$C$604,$C8,$D$5:$D$604,$D8,$B$5:$B$604,$B8)>1,"Takror",""))
A9: 5 | G9: =IF(OR($D9="",$B9=""),"",INT(($B9-$D9)/365.25)) | H9: =IF($G9="","",IF($G9<18,"Ha","Yo'q")) | P9: =IF($O9="","",IFERROR(VALUE(LEFT($O9,FIND(".",$O9)-1)),"")) | Q9: =IF($P9="","",IF($P9<=7,"Shoshilinch",IF($P9<=9,"Kechiktirib bo'lmaydigan",IF($P9<=14,"Rejalashtirilgan","Rejali")))) | S9: =IF($K9<>"Kesarcha","",IF(OR($O9<>"",$R9="Ha"),"Ha","YO‘Q")) | V9: =IF(OR($C9="",$D9="",$B9=""),"",IF(COUNTIFS($C$5:$C$604,$C9,$D$5:$D$604,$D9,$B$5:$B$604,$B9)>1,"Takror",""))
A10: 6 | G10: =IF(OR($D10="",$B10=""),"",INT(($B10-$D10)/365.25)) | H10: =IF($G10="","",IF($G10<18,"Ha","Yo'q")) | P10: =IF($O10="","",IFERROR(VALUE(LEFT($O10,FIND(".",$O10)-1)),"")) | Q10: =IF($P10="","",IF($P10<=7,"Shoshilinch",IF($P10<=9,"Kechiktirib bo'lmaydigan",IF($P10<=14,"Rejalashtirilgan","Rejali")))) | S10: =IF($K10<>"Kesarcha","",IF(OR($O10<>"",$R10="Ha"),"Ha","YO‘Q")) | V10: =IF(OR($C10="",$D10="",$B10=""),"",IF(COUNTIFS($C$5:$C$604,$C10,$D$5:$D$604,$D10,$B$5:$B$604,$B10)>1,"Takror",""))
A11: 7 | G11: =IF(OR($D11="",$B11=""),"",INT(($B11-$D11)/365.25)) | H11: =IF($G11="","",IF($G11<18,"Ha","Yo'q")) | P11: =IF($O11="","",IFERROR(VALUE(LEFT($O11,FIND(".",$O11)-1)),"")) | Q11: =IF($P11="","",IF($P11<=7,"Shoshilinch",IF($P11<=9,"Kechiktirib bo'lmaydigan",IF($P11<=14,"Rejalashtirilgan","Rejali")))) | S11: =IF($K11<>"Kesarcha","",IF(OR($O11<>"",$R11="Ha"),"Ha","YO‘Q")) | V11: =IF(OR($C11="",$D11="",$B11=""),"",IF(COUNTIFS($C$5:$C$604,$C11,$D$5:$D$604,$D11,$B$5:$B$604,$B11)>1,"Takror",""))
A12: 8 | G12: =IF(OR($D12="",$B12=""),"",INT(($B12-$D12)/365.25)) | H12: =IF($G12="","",IF($G12<18,"Ha","Yo'q")) | P12: =IF($O12="","",IFERROR(VALUE(LEFT($O12,FIND(".",$O12)-1)),"")) | Q12: =IF($P12="","",IF($P12<=7,"Shoshilinch",IF($P12<=9,"Kechiktirib bo'lmaydigan",IF($P12<=14,"Rejalashtirilgan","Rejali")))) | S12: =IF($K12<>"Kesarcha","",IF(OR($O12<>"",$R12="Ha"),"Ha","YO‘Q")) | V12: =IF(OR($C12="",$D12="",$B12=""),"",IF(COUNTIFS($C$5:$C$604,$C12,$D$5:$D$604,$D12,$B$5:$B$604,$B12)>1,"Takror",""))
A13: 9 | G13: =IF(OR($D13="",$B13=""),"",INT(($B13-$D13)/365.25)) | H13: =IF($G13="","",IF($G13<18,"Ha","Yo'q")) | P13: =IF($O13="","",IFERROR(VALUE(LEFT($O13,FIND(".",$O13)-1)),"")) | Q13: =IF($P13="","",IF($P13<=7,"Shoshilinch",IF($P13<=9,"Kechiktirib bo'lmaydigan",IF($P13<=14,"Rejalashtirilgan","Rejali")))) | S13: =IF($K13<>"Kesarcha","",IF(OR($O13<>"",$R13="Ha"),"Ha","YO‘Q")) | V13: =IF(OR($C13="",$D13="",$B13=""),"",IF(COUNTIFS($C$5:$C$604,$C13,$D$5:$D$604,$D13,$B$5:$B$604,$B13)>1,"Takror",""))
A14: 10 | G14: =IF(OR($D14="",$B14=""),"",INT(($B14-$D14)/365.25)) | H14: =IF($G14="","",IF($G14<18,"Ha","Yo'q")) | P14: =IF($O14="","",IFERROR(VALUE(LEFT($O14,FIND(".",$O14)-1)),"")) | Q14: =IF($P14="","",IF($P14<=7,"Shoshilinch",IF($P14<=9,"Kechiktirib bo'lmaydigan",IF($P14<=14,"Rejalashtirilgan","Rejali")))) | S14: =IF($K14<>"Kesarcha","",IF(OR($O14<>"",$R14="Ha"),"Ha","YO‘Q")) | V14: =IF(OR($C14="",$D14="",$B14=""),"",IF(COUNTIFS($C$5:$C$604,$C14,$D$5:$D$604,$D14,$B$5:$B$604,$B14)>1,"Takror",""))
A15: 11 | G15: =IF(OR($D15="",$B15=""),"",INT(($B15-$D15)/365.25)) | H15: =IF($G15="","",IF($G15<18,"Ha","Yo'q")) | P15: =IF($O15="","",IFERROR(VALUE(LEFT($O15,FIND(".",$O15)-1)),"")) | Q15: =IF($P15="","",IF($P15<=7,"Shoshilinch",IF($P15<=9,"Kechiktirib bo'lmaydigan",IF($P15<=14,"Rejalashtirilgan","Rejali")))) | S15: =IF($K15<>"Kesarcha","",IF(OR($O15<>"",$R15="Ha"),"Ha","YO‘Q")) | V15: =IF(OR($C15="",$D15="",$B15=""),"",IF(COUNTIFS($C$5:$C$604,$C15,$D$5:$D$604,$D15,$B$5:$B$604,$B15)>1,"Takror",""))
A16: 12 | G16: =IF(OR($D16="",$B16=""),"",INT(($B16-$D16)/365.25)) | H16: =IF($G16="","",IF($G16<18,"Ha","Yo'q")) | P16: =IF($O16="","",IFERROR(VALUE(LEFT($O16,FIND(".",$O16)-1)),"")) | Q16: =IF($P16="","",IF($P16<=7,"Shoshilinch",IF($P16<=9,"Kechiktirib bo'lmaydigan",IF($P16<=14,"Rejalashtirilgan","Rejali")))) | S16: =IF($K16<>"Kesarcha","",IF(OR($O16<>"",$R16="Ha"),"Ha","YO‘Q")) | V16: =IF(OR($C16="",$D16="",$B16=""),"",IF(COUNTIFS($C$5:$C$604,$C16,$D$5:$D$604,$D16,$B$5:$B$604,$B16)>1,"Takror",""))
... A604: 600 | G604: =IF(OR($D604="",$B604=""),"",INT(($B604-$D604)/365.25)) | H604: =IF($G604="","",IF($G604<18,"Ha","Yo'q")) | P604: =IF($O604="","",IFERROR(VALUE(LEFT($O604,FIND(".",$O604)-1)),"")) | Q604: =IF($P604="","",IF($P604<=7,"Shoshilinch",IF($P604<=9,"Kechiktirib bo'lmaydigan",IF($P604<=14,"Rejalashtirilgan","Rejali")))) | S604: =IF($K604<>"Kesarcha","",IF(OR($O604<>"",$R604="Ha"),"Ha","YO‘Q")) | V604: =IF(OR($C604="",$D604="",$B604=""),"",IF(COUNTIFS($C$5:$C$604,$C604,$D$5:$D$604,$D604,$B$5:$B$604,$B604)>1,"Takror",""))

Sheet Homiladorlar
A1: HOMILADORLAR NAZORATI / НАБЛЮДЕНИЕ БЕРЕМЕННЫХ (akusher-ginekolog)
A2: Diagnoz va xavf omilini o‘zingiz qo‘yasiz — hujjat raqamini yozing. Antenatal ko‘riklar sonini oilaviy shifokor va o‘z qabullaringiz bo‘yicha yangilab boring. / Диагноз и фактор риска ставите вы — укажите № документа. Обновляйте число антенатальных осмотров.
A3: MAXFIY / КОНФИДЕНЦИАЛЬНО — shaxsiy va tibbiy ma’lumotlar (shifokorlik siri). Faylni parol bilan himoyalang, ochiq guruhlarga yubormang. / Персональные и медицинские данные (врачебная тайна). Защитите файл паролем, не отправляйте в открытые группы.
A4: № | B4: F.I.Sh. (to‘liq) Ф.И.О. | C4: Tug‘ilgan sana Дата рождения | D4: PINFL (14 raqam) ПИНФЛ (14 цифр) | E4: Telefon Телефон | F4: Mahalla Махалля | G4: Yorliq (avto) — boshqa varaqlarda tanlanadi Метка (авто) | H4: Hisobga olingan sana Дата постановки | I4: Oxirgi hayz 1-kuni Первый день последних месячных | J4: Taxminiy tug‘ruq (avto) Предп. роды | K4: Hozirgi muddat, hafta (avto) Срок, нед. | L4: Hisobga olishdagi yosh (avto) Возраст при постановке | M4: Voyaga yetmagan? (avto) Несоверш.? | N4: Xavf guruhida? Группа риска? | O4: Og‘irlik Тяжесть | P4: Asosiy xavf omili Основной фактор риска | Q4: Diagnoz Диагноз | R4: MKB-10 МКБ-10 | S4: Hujjat № / sana № документа / дата | T4: Stasionarga yo‘llangan sana Дата направления в стационар | U4: Qaysi stasionar Какой стационар | V4: Oilaviy shifokor ko‘riklari (soni) Осмотры семейным врачом (число) | W4: Akusher-ginekolog ko‘riklari (soni) Осмотры акушером-гинекологом (число) | X4: Antenatal standart bajarildimi? (avto) Стандарт выполнен? | Y4: Skriningga yo‘llangan sana Дата направления на скрининг | Z4: I trimestr skrining o‘tgan sana Дата скрининга I триместра | AA4: Oxirgi ko‘rik Посл. осмотр | AB4: Keyingi ko‘rik След. осмотр | AC4: Muddati o‘tgan? (avto) Просрочен? | AD4: Holati Статус | AE4: Chiqish sanasi Дата выбытия | AF4: Izoh Примечание | AG4: Takror? (avto) Дубль? | AH4: № (xavfli) № (риск)
A5: 1 | B5: Тестова Анна Ивановна | C5: 35188 | D5: 32000000000000 | E5: +998930000000 | G5: =IF(OR($B5="",$C5=""),"",$B5&" ("&DAY($C5)&"."&MONTH($C5)&"."&YEAR($C5)&")") -> Тестова Анна Ивановна (3.5.1996) | I5: 46283 | J5: 46213 | K5: =IF(OR($I5="",$AE5<>""),"",INT((Boshqaruv!$C$12-$I5)/7)) -> 4 | L5: =IF(OR($C5="",$H5=""),"",INT(($H5-$C5)/365.25)) | M5: =IF($L5="","",IF($L5<18,"Ha","Yo'q")) | X5: =IF(OR($V5="",$W5=""),"",IF(AND($V5>=Spravochnik!$H$5,$W5>=Spravochnik!$H$6),"Ha","Yo'q")) | AC5: =IF(AND($B5<>"",$AE5="",$AB5<>"",$AB5<Boshqaruv!$C$12),"Ha","") | AG5: =IF(OR($B5="",$C5="",$H5=""),"",IF(COUNTIFS($B$5:$B$804,$B5,$C$5:$C$804,$C5,$H$5:$H$804,$H5)>1,"Takror","")) | AH5: =IF(AND($B5<>"",$N5="Ha",$H5<>"",$H5<=Boshqaruv!$C$12,OR($AE5="",$AE5>Boshqaruv!$C$12)),MAX($AH$4:$AH4)+1,"")
A6: 2 | B6: Пробная Мария Петровна | C6: 35554 | D6: 32000000000001 | E6: +998930000001 | G6: =IF(OR($B6="",$C6=""),"",$B6&" ("&DAY($C6)&"."&MONTH($C6)&"."&YEAR($C6)&")") -> Пробная Мария Петровна (4.5.1997) | I6: 46282 | J6: 46212 | K6: =IF(OR($I6="",$AE6<>""),"",INT((Boshqaruv!$C$12-$I6)/7)) -> 4 | L6: =IF(OR($C6="",$H6=""),"",INT(($H6-$C6)/365.25)) | M6: =IF($L6="","",IF($L6<18,"Ha","Yo'q")) | X6: =IF(OR($V6="",$W6=""),"",IF(AND($V6>=Spravochnik!$H$5,$W6>=Spravochnik!$H$6),"Ha","Yo'q")) | AC6: =IF(AND($B6<>"",$AE6="",$AB6<>"",$AB6<Boshqaruv!$C$12),"Ha","") | AG6: =IF(OR($B6="",$C6="",$H6=""),"",IF(COUNTIFS($B$5:$B$804,$B6,$C$5:$C$804,$C6,$H$5:$H$804,$H6)>1,"Takror","")) | AH6: =IF(AND($B6<>"",$N6="Ha",$H6<>"",$H6<=Boshqaruv!$C$12,OR($AE6="",$AE6>Boshqaruv!$C$12)),MAX($AH$4:$AH5)+1,"")
A7: 3 | B7: Образцова Зилола Каримовна | C7: 35920 | D7: 32000000000002 | E7: +998930000002 | G7: =IF(OR($B7="",$C7=""),"",$B7&" ("&DAY($C7)&"."&MONTH($C7)&"."&YEAR($C7)&")") -> Образцова Зилола Каримовна (5.5.1998) | I7: 46281 | J7: 46211 | K7: =IF(OR($I7="",$AE7<>""),"",INT((Boshqaruv!$C$12-$I7)/7)) -> 4 | L7: =IF(OR($C7="",$H7=""),"",INT(($H7-$C7)/365.25)) | M7: =IF($L7="","",IF($L7<18,"Ha","Yo'q")) | X7: =IF(OR($V7="",$W7=""),"",IF(AND($V7>=Spravochnik!$H$5,$W7>=Spravochnik!$H$6),"Ha","Yo'q")) | AC7: =IF(AND($B7<>"",$AE7="",$AB7<>"",$AB7<Boshqaruv!$C$12),"Ha","") | AG7: =IF(OR($B7="",$C7="",$H7=""),"",IF(COUNTIFS($B$5:$B$804,$B7,$C$5:$C$804,$C7,$H$5:$H$804,$H7)>1,"Takror","")) | AH7: =IF(AND($B7<>"",$N7="Ha",$H7<>"",$H7<=Boshqaruv!$C$12,OR($AE7="",$AE7>Boshqaruv!$C$12)),MAX($AH$4:$AH6)+1,"")
A8: 4 | B8: Вымышленная Нигора Алиевна | C8: 36286 | D8: 32000000000003 | E8: +998930000003 | G8: =IF(OR($B8="",$C8=""),"",$B8&" ("&DAY($C8)&"."&MONTH($C8)&"."&YEAR($C8)&")") -> Вымышленная Нигора Алиевна (6.5.1999) | I8: 46280 | J8: 46210 | K8: =IF(OR($I8="",$AE8<>""),"",INT((Boshqaruv!$C$12-$I8)/7)) -> 4 | L8: =IF(OR($C8="",$H8=""),"",INT(($H8-$C8)/365.25)) | M8: =IF($L8="","",IF($L8<18,"Ha","Yo'q")) | X8: =IF(OR($V8="",$W8=""),"",IF(AND($V8>=Spravochnik!$H$5,$W8>=Spravochnik!$H$6),"Ha","Yo'q")) | AC8: =IF(AND($B8<>"",$AE8="",$AB8<>"",$AB8<Boshqaruv!$C$12),"Ha","") | AG8: =IF(OR($B8="",$C8="",$H8=""),"",IF(COUNTIFS($B$5:$B$804,$B8,$C$5:$C$804,$C8,$H$5:$H$804,$H8)>1,"Takror","")) | AH8: =IF(AND($B8<>"",$N8="Ha",$H8<>"",$H8<=Boshqaruv!$C$12,OR($AE8="",$AE8>Boshqaruv!$C$12)),MAX($AH$4:$AH7)+1,"")
A9: 5 | G9: =IF(OR($B9="",$C9=""),"",$B9&" ("&DAY($C9)&"."&MONTH($C9)&"."&YEAR($C9)&")") | J9: =IF($I9="","",$I9+280) | K9: =IF(OR($I9="",$AE9<>""),"",INT((Boshqaruv!$C$12-$I9)/7)) | L9: =IF(OR($C9="",$H9=""),"",INT(($H9-$C9)/365.25)) | M9: =IF($L9="","",IF($L9<18,"Ha","Yo'q")) | X9: =IF(OR($V9="",$W9=""),"",IF(AND($V9>=Spravochnik!$H$5,$W9>=Spravochnik!$H$6),"Ha","Yo'q")) | AC9: =IF(AND($B9<>"",$AE9="",$AB9<>"",$AB9<Boshqaruv!$C$12),"Ha","") | AG9: =IF(OR($B9="",$C9="",$H9=""),"",IF(COUNTIFS($B$5:$B$804,$B9,$C$5:$C$804,$C9,$H$5:$H$804,$H9)>1,"Takror","")) | AH9: =IF(AND($B9<>"",$N9="Ha",$H9<>"",$H9<=Boshqaruv!$C$12,OR($AE9="",$AE9>Boshqaruv!$C$12)),MAX($AH$4:$AH8)+1,"")
A10: 6 | G10: =IF(OR($B10="",$C10=""),"",$B10&" ("&DAY($C10)&"."&MONTH($C10)&"."&YEAR($C10)&")") | J10: =IF($I10="","",$I10+280) | K10: =IF(OR($I10="",$AE10<>""),"",INT((Boshqaruv!$C$12-$I10)/7)) | L10: =IF(OR($C10="",$H10=""),"",INT(($H10-$C10)/365.25)) | M10: =IF($L10="","",IF($L10<18,"Ha","Yo'q")) | X10: =IF(OR($V10="",$W10=""),"",IF(AND($V10>=Spravochnik!$H$5,$W10>=Spravochnik!$H$6),"Ha","Yo'q")) | AC10: =IF(AND($B10<>"",$AE10="",$AB10<>"",$AB10<Boshqaruv!$C$12),"Ha","") | AG10: =IF(OR($B10="",$C10="",$H10=""),"",IF(COUNTIFS($B$5:$B$804,$B10,$C$5:$C$804,$C10,$H$5:$H$804,$H10)>1,"Takror","")) | AH10: =IF(AND($B10<>"",$N10="Ha",$H10<>"",$H10<=Boshqaruv!$C$12,OR($AE10="",$AE10>Boshqaruv!$C$12)),MAX($AH$4:$AH9)+1,"")
A11: 7 | G11: =IF(OR($B11="",$C11=""),"",$B11&" ("&DAY($C11)&"."&MONTH($C11)&"."&YEAR($C11)&")") | J11: =IF($I11="","",$I11+280) | K11: =IF(OR($I11="",$AE11<>""),"",INT((Boshqaruv!$C$12-$I11)/7)) | L11: =IF(OR($C11="",$H11=""),"",INT(($H11-$C11)/365.25)) | M11: =IF($L11="","",IF($L11<18,"Ha","Yo'q")) | X11: =IF(OR($V11="",$W11=""),"",IF(AND($V11>=Spravochnik!$H$5,$W11>=Spravochnik!$H$6),"Ha","Yo'q")) | AC11: =IF(AND($B11<>"",$AE11="",$AB11<>"",$AB11<Boshqaruv!$C$12),"Ha","") | AG11: =IF(OR($B11="",$C11="",$H11=""),"",IF(COUNTIFS($B$5:$B$804,$B11,$C$5:$C$804,$C11,$H$5:$H$804,$H11)>1,"Takror","")) | AH11: =IF(AND($B11<>"",$N11="Ha",$H11<>"",$H11<=Boshqaruv!$C$12,OR($AE11="",$AE11>Boshqaruv!$C$12)),MAX($AH$4:$AH10)+1,"")
A12: 8 | G12: =IF(OR($B12="",$C12=""),"",$B12&" ("&DAY($C12)&"."&MONTH($C12)&"."&YEAR($C12)&")") | J12: =IF($I12="","",$I12+280) | K12: =IF(OR($I12="",$AE12<>""),"",INT((Boshqaruv!$C$12-$I12)/7)) | L12: =IF(OR($C12="",$H12=""),"",INT(($H12-$C12)/365.25)) | M12: =IF($L12="","",IF($L12<18,"Ha","Yo'q")) | X12: =IF(OR($V12="",$W12=""),"",IF(AND($V12>=Spravochnik!$H$5,$W12>=Spravochnik!$H$6),"Ha","Yo'q")) | AC12: =IF(AND($B12<>"",$AE12="",$AB12<>"",$AB12<Boshqaruv!$C$12),"Ha","") | AG12: =IF(OR($B12="",$C12="",$H12=""),"",IF(COUNTIFS($B$5:$B$804,$B12,$C$5:$C$804,$C12,$H$5:$H$804,$H12)>1,"Takror","")) | AH12: =IF(AND($B12<>"",$N12="Ha",$H12<>"",$H12<=Boshqaruv!$C$12,OR($AE12="",$AE12>Boshqaruv!$C$12)),MAX($AH$4:$AH11)+1,"")
A13: 9 | G13: =IF(OR($B13="",$C13=""),"",$B13&" ("&DAY($C13)&"."&MONTH($C13)&"."&YEAR($C13)&")") | J13: =IF($I13="","",$I13+280) | K13: =IF(OR($I13="",$AE13<>""),"",INT((Boshqaruv!$C$12-$I13)/7)) | L13: =IF(OR($C13="",$H13=""),"",INT(($H13-$C13)/365.25)) | M13: =IF($L13="","",IF($L13<18,"Ha","Yo'q")) | X13: =IF(OR($V13="",$W13=""),"",IF(AND($V13>=Spravochnik!$H$5,$W13>=Spravochnik!$H$6),"Ha","Yo'q")) | AC13: =IF(AND($B13<>"",$AE13="",$AB13<>"",$AB13<Boshqaruv!$C$12),"Ha","") | AG13: =IF(OR($B13="",$C13="",$H13=""),"",IF(COUNTIFS($B$5:$B$804,$B13,$C$5:$C$804,$C13,$H$5:$H$804,$H13)>1,"Takror","")) | AH13: =IF(AND($B13<>"",$N13="Ha",$H13<>"",$H13<=Boshqaruv!$C$12,OR($AE13="",$AE13>Boshqaruv!$C$12)),MAX($AH$4:$AH12)+1,"")
A14: 10 | G14: =IF(OR($B14="",$C14=""),"",$B14&" ("&DAY($C14)&"."&MONTH($C14)&"."&YEAR($C14)&")") | J14: =IF($I14="","",$I14+280) | K14: =IF(OR($I14="",$AE14<>""),"",INT((Boshqaruv!$C$12-$I14)/7)) | L14: =IF(OR($C14="",$H14=""),"",INT(($H14-$C14)/365.25)) | M14: =IF($L14="","",IF($L14<18,"Ha","Yo'q")) | X14: =IF(OR($V14="",$W14=""),"",IF(AND($V14>=Spravochnik!$H$5,$W14>=Spravochnik!$H$6),"Ha","Yo'q")) | AC14: =IF(AND($B14<>"",$AE14="",$AB14<>"",$AB14<Boshqaruv!$C$12),"Ha","") | AG14: =IF(OR($B14="",$C14="",$H14=""),"",IF(COUNTIFS($B$5:$B$804,$B14,$C$5:$C$804,$C14,$H$5:$H$804,$H14)>1,"Takror","")) | AH14: =IF(AND($B14<>"",$N14="Ha",$H14<>"",$H14<=Boshqaruv!$C$12,OR($AE14="",$AE14>Boshqaruv!$C$12)),MAX($AH$4:$AH13)+1,"")
A15: 11 | G15: =IF(OR($B15="",$C15=""),"",$B15&" ("&DAY($C15)&"."&MONTH($C15)&"."&YEAR($C15)&")") | J15: =IF($I15="","",$I15+280) | K15: =IF(OR($I15="",$AE15<>""),"",INT((Boshqaruv!$C$12-$I15)/7)) | L15: =IF(OR($C15="",$H15=""),"",INT(($H15-$C15)/365.25)) | M15: =IF($L15="","",IF($L15<18,"Ha","Yo'q")) | X15: =IF(OR($V15="",$W15=""),"",IF(AND($V15>=Spravochnik!$H$5,$W15>=Spravochnik!$H$6),"Ha","Yo'q")) | AC15: =IF(AND($B15<>"",$AE15="",$AB15<>"",$AB15<Boshqaruv!$C$12),"Ha","") | AG15: =IF(OR($B15="",$C15="",$H15=""),"",IF(COUNTIFS($B$5:$B$804,$B15,$C$5:$C$804,$C15,$H$5:$H$804,$H15)>1,"Takror","")) | AH15: =IF(AND($B15<>"",$N15="Ha",$H15<>"",$H15<=Boshqaruv!$C$12,OR($AE15="",$AE15>Boshqaruv!$C$12)),MAX($AH$4:$AH14)+1,"")
A16: 12 | G16: =IF(OR($B16="",$C16=""),"",$B16&" ("&DAY($C16)&"."&MONTH($C16)&"."&YEAR($C16)&")") | J16: =IF($I16="","",$I16+280) | K16: =IF(OR($I16="",$AE16<>""),"",INT((Boshqaruv!$C$12-$I16)/7)) | L16: =IF(OR($C16="",$H16=""),"",INT(($H16-$C16)/365.25)) | M16: =IF($L16="","",IF($L16<18,"Ha","Yo'q")) | X16: =IF(OR($V16="",$W16=""),"",IF(AND($V16>=Spravochnik!$H$5,$W16>=Spravochnik!$H$6),"Ha","Yo'q")) | AC16: =IF(AND($B16<>"",$AE16="",$AB16<>"",$AB16<Boshqaruv!$C$12),"Ha","") | AG16: =IF(OR($B16="",$C16="",$H16=""),"",IF(COUNTIFS($B$5:$B$804,$B16,$C$5:$C$804,$C16,$H$5:$H$804,$H16)>1,"Takror","")) | AH16: =IF(AND($B16<>"",$N16="Ha",$H16<>"",$H16<=Boshqaruv!$C$12,OR($AE16="",$AE16>Boshqaruv!$C$12)),MAX($AH$4:$AH15)+1,"")
A17: 13 | G17: =IF(OR($B17="",$C17=""),"",$B17&" ("&DAY($C17)&"."&MONTH($C17)&"."&YEAR($C17)&")") | J17: =IF($I17="","",$I17+280) | K17: =IF(OR($I17="",$AE17<>""),"",INT((Boshqaruv!$C$12-$I17)/7)) | L17: =IF(OR($C17="",$H17=""),"",INT(($H17-$C17)/365.25)) | M17: =IF($L17="","",IF($L17<18,"Ha","Yo'q")) | X17: =IF(OR($V17="",$W17=""),"",IF(AND($V17>=Spravochnik!$H$5,$W17>=Spravochnik!$H$6),"Ha","Yo'q")) | AC17: =IF(AND($B17<>"",$AE17="",$AB17<>"",$AB17<Boshqaruv!$C$12),"Ha","") | AG17: =IF(OR($B17="",$C17="",$H17=""),"",IF(COUNTIFS($B$5:$B$804,$B17,$C$5:$C$804,$C17,$H$5:$H$804,$H17)>1,"Takror","")) | AH17: =IF(AND($B17<>"",$N17="Ha",$H17<>"",$H17<=Boshqaruv!$C$12,OR($AE17="",$AE17>Boshqaruv!$C$12)),MAX($AH$4:$AH16)+1,"")
A18: 14 | G18: =IF(OR($B18="",$C18=""),"",$B18&" ("&DAY($C18)&"."&MONTH($C18)&"."&YEAR($C18)&")") | J18: =IF($I18="","",$I18+280) | K18: =IF(OR($I18="",$AE18<>""),"",INT((Boshqaruv!$C$12-$I18)/7)) | L18: =IF(OR($C18="",$H18=""),"",INT(($H18-$C18)/365.25)) | M18: =IF($L18="","",IF($L18<18,"Ha","Yo'q")) | X18: =IF(OR($V18="",$W18=""),"",IF(AND($V18>=Spravochnik!$H$5,$W18>=Spravochnik!$H$6),"Ha","Yo'q")) | AC18: =IF(AND($B18<>"",$AE18="",$AB18<>"",$AB18<Boshqaruv!$C$12),"Ha","") | AG18: =IF(OR($B18="",$C18="",$H18=""),"",IF(COUNTIFS($B$5:$B$804,$B18,$C$5:$C$804,$C18,$H$5:$H$804,$H18)>1,"Takror","")) | AH18: =IF(AND($B18<>"",$N18="Ha",$H18<>"",$H18<=Boshqaruv!$C$12,OR($AE18="",$AE18>Boshqaruv!$C$12)),MAX($AH$4:$AH17)+1,"")
A19: 15 | G19: =IF(OR($B19="",$C19=""),"",$B19&" ("&DAY($C19)&"."&MONTH($C19)&"."&YEAR($C19)&")") | J19: =IF($I19="","",$I19+280) | K19: =IF(OR($I19="",$AE19<>""),"",INT((Boshqaruv!$C$12-$I19)/7)) | L19: =IF(OR($C19="",$H19=""),"",INT(($H19-$C19)/365.25)) | M19: =IF($L19="","",IF($L19<18,"Ha","Yo'q")) | X19: =IF(OR($V19="",$W19=""),"",IF(AND($V19>=Spravochnik!$H$5,$W19>=Spravochnik!$H$6),"Ha","Yo'q")) | AC19: =IF(AND($B19<>"",$AE19="",$AB19<>"",$AB19<Boshqaruv!$C$12),"Ha","") | AG19: =IF(OR($B19="",$C19="",$H19=""),"",IF(COUNTIFS($B$5:$B$804,$B19,$C$5:$C$804,$C19,$H$5:$H$804,$H19)>1,"Takror","")) | AH19: =IF(AND($B19<>"",$N19="Ha",$H19<>"",$H19<=Boshqaruv!$C$12,OR($AE19="",$AE19>Boshqaruv!$C$12)),MAX($AH$4:$AH18)+1,"")
A20: 16 | G20: =IF(OR($B20="",$C20=""),"",$B20&" ("&DAY($C20)&"."&MONTH($C20)&"."&YEAR($C20)&")") | J20: =IF($I20="","",$I20+280) | K20: =IF(OR($I20="",$AE20<>""),"",INT((Boshqaruv!$C$12-$I20)/7)) | L20: =IF(OR($C20="",$H20=""),"",INT(($H20-$C20)/365.25)) | M20: =IF($L20="","",IF($L20<18,"Ha","Yo'q")) | X20: =IF(OR($V20="",$W20=""),"",IF(AND($V20>=Spravochnik!$H$5,$W20>=Spravochnik!$H$6),"Ha","Yo'q")) | AC20: =IF(AND($B20<>"",$AE20="",$AB20<>"",$AB20<Boshqaruv!$C$12),"Ha","") | AG20: =IF(OR($B20="",$C20="",$H20=""),"",IF(COUNTIFS($B$5:$B$804,$B20,$C$5:$C$804,$C20,$H$5:$H$804,$H20)>1,"Takror","")) | AH20: =IF(AND($B20<>"",$N20="Ha",$H20<>"",$H20<=Boshqaruv!$C$12,OR($AE20="",$AE20>Boshqaruv!$C$12)),MAX($AH$4:$AH19)+1,"")
... A804: 800 | G804: =IF(OR($B804="",$C804=""),"",$B804&" ("&DAY($C804)&"."&MONTH($C804)&"."&YEAR($C804)&")") | J804: =IF($I804="","",$I804+280) | K804: =IF(OR($I804="",$AE804<>""),"",INT((Boshqaruv!$C$12-$I804)/7)) | L804: =IF(OR($C804="",$H804=""),"",INT(($H804-$C804)/365.25)) | M804: =IF($L804="","",IF($L804<18,"Ha","Yo'q")) | X804: =IF(OR($V804="",$W804=""),"",IF(AND($V804>=Spravochnik!$H$5,$W804>=Spravochnik!$H$6),"Ha","Yo'q")) | AC804: =IF(AND($B804<>"",$AE804="",$AB804<>"",$AB804<Boshqaruv!$C$12),"Ha","") | AG804: =IF(OR($B804="",$C804="",$H804=""),"",IF(COUNTIFS($B$5:$B$804,$B804,$C$5:$C$804,$C804,$H$5:$H$804,$H804)>1,"Takror","")) | AH804: =IF(AND($B804<>"",$N804="Ha",$H804<>"",$H804<=Boshqaruv!$C$12,OR($AE804="",$AE804>Boshqaruv!$C$12)),MAX($AH$4:$AH803)+1,"")

Sheet Xavfli_homiladorlar
A1: YUQORI XAVFLI HOMILADORLAR / БЕРЕМЕННЫЕ ВЫСОКОГО РИСКА — avtomatik ro‘yxat
A2: Xavf guruhi = Ha va chiqish sanasi yo‘q bo‘lganlar. / Группа риска = Ha и нет даты выбытия.
A3: MAXFIY / КОНФИДЕНЦИАЛЬНО — shaxsiy va tibbiy ma’lumotlar (shifokorlik siri). Faylni parol bilan himoyalang, ochiq guruhlarga yubormang. / Персональные и медицинские данные (врачебная тайна). Защитите файл паролем, не отправляйте в открытые группы.
A4: № | B4: (qator) | C4: F.I.Sh. Ф.И.О. | D4: Tug‘ilgan sana Дата рожд. | E4: Mahalla Махалля | F4: Telefon Телефон | G4: Og‘irlik Тяжесть | H4: Diagnoz Диагноз | I4: MKB-10 | J4: Muddat, hafta Срок, нед. | K4: Taxminiy tug‘ruq Предп. роды | L4: Stasionarga yo‘llangan Направлена в стационар | M4: Keyingi ko‘rik След. осмотр | N4: Muddati o‘tgan? Просрочен?
A5: 1 | B5: =IFERROR(MATCH(A5,Homiladorlar!$AH$5:$AH$804,0),"") | C5: =IF($B5="","",IF(INDEX(Homiladorlar!$B$5:$B$804,$B5)="","",INDEX(Homiladorlar!$B$5:$B$804,$B5))) | D5: =IF($B5="","",IF(INDEX(Homiladorlar!$C$5:$C$804,$B5)="","",INDEX(Homiladorlar!$C$5:$C$804,$B5))) | E5: =IF($B5="","",IF(INDEX(Homiladorlar!$F$5:$F$804,$B5)="","",INDEX(Homiladorlar!$F$5:$F$804,$B5))) | F5: =IF($B5="","",IF(INDEX(Homiladorlar!$E$5:$E$804,$B5)="","",INDEX(Homiladorlar!$E$5:$E$804,$B5))) | G5: =IF($B5="","",IF(INDEX(Homiladorlar!$O$5:$O$804,$B5)="","",INDEX(Homiladorlar!$O$5:$O$804,$B5))) | H5: =IF($B5="","",IF(INDEX(Homiladorlar!$Q$5:$Q$804,$B5)="","",INDEX(Homiladorlar!$Q$5:$Q$804,$B5))) | I5: =IF($B5="","",IF(INDEX(Homiladorlar!$R$5:$R$804,$B5)="","",INDEX(Homiladorlar!$R$5:$R$804,$B5))) | J5: =IF($B5="","",IF(INDEX(Homiladorlar!$K$5:$K$804,$B5)="","",INDEX(Homiladorlar!$K$5:$K$804,$B5))) | K5: =IF($B5="","",IF(INDEX(Homiladorlar!$J$5:$J$804,$B5)="","",INDEX(Homiladorlar!$J$5:$J$804,$B5))) | L5: =IF($B5="","",IF(INDEX(Homiladorlar!$T$5:$T$804,$B5)="","",INDEX(Homiladorlar!$T$5:$T$804,$B5))) | M5: =IF($B5="","",IF(INDEX(Homiladorlar!$AB$5:$AB$804,$B5)="","",INDEX(Homiladorlar!$AB$5:$AB$804,$B5))) | N5: =IF($B5="","",IF(INDEX(Homiladorlar!$AC$5:$AC$804,$B5)="","",INDEX(Homiladorlar!$AC$5:$AC$804,$B5)))
A6: 2 | B6: =IFERROR(MATCH(A6,Homiladorlar!$AH$5:$AH$804,0),"") | C6: =IF($B6="","",IF(INDEX(Homiladorlar!$B$5:$B$804,$B6)="","",INDEX(Homiladorlar!$B$5:$B$804,$B6))) | D6: =IF($B6="","",IF(INDEX(Homiladorlar!$C$5:$C$804,$B6)="","",INDEX(Homiladorlar!$C$5:$C$804,$B6))) | E6: =IF($B6="","",IF(INDEX(Homiladorlar!$F$5:$F$804,$B6)="","",INDEX(Homiladorlar!$F$5:$F$804,$B6))) | F6: =IF($B6="","",IF(INDEX(Homiladorlar!$E$5:$E$804,$B6)="","",INDEX(Homiladorlar!$E$5:$E$804,$B6))) | G6: =IF($B6="","",IF(INDEX(Homiladorlar!$O$5:$O$804,$B6)="","",INDEX(Homiladorlar!$O$5:$O$804,$B6))) | H6: =IF($B6="","",IF(INDEX(Homiladorlar!$Q$5:$Q$804,$B6)="","",INDEX(Homiladorlar!$Q$5:$Q$804,$B6))) | I6: =IF($B6="","",IF(INDEX(Homiladorlar!$R$5:$R$804,$B6)="","",INDEX(Homiladorlar!$R$5:$R$804,$B6))) | J6: =IF($B6="","",IF(INDEX(Homiladorlar!$K$5:$K$804,$B6)="","",INDEX(Homiladorlar!$K$5:$K$804,$B6))) | K6: =IF($B6="","",IF(INDEX(Homiladorlar!$J$5:$J$804,$B6)="","",INDEX(Homiladorlar!$J$5:$J$804,$B6))) | L6: =IF($B6="","",IF(INDEX(Homiladorlar!$T$5:$T$804,$B6)="","",INDEX(Homiladorlar!$T$5:$T$804,$B6))) | M6: =IF($B6="","",IF(INDEX(Homiladorlar!$AB$5:$AB$804,$B6)="","",INDEX(Homiladorlar!$AB$5:$AB$804,$B6))) | N6: =IF($B6="","",IF(INDEX(Homiladorlar!$AC$5:$AC$804,$B6)="","",INDEX(Homiladorlar!$AC$5:$AC$804,$B6)))
A7: 3 | B7: =IFERROR(MATCH(A7,Homiladorlar!$AH$5:$AH$804,0),"") | C7: =IF($B7="","",IF(INDEX(Homiladorlar!$B$5:$B$804,$B7)="","",INDEX(Homiladorlar!$B$5:$B$804,$B7))) | D7: =IF($B7="","",IF(INDEX(Homiladorlar!$C$5:$C$804,$B7)="","",INDEX(Homiladorlar!$C$5:$C$804,$B7))) | E7: =IF($B7="","",IF(INDEX(Homiladorlar!$F$5:$F$804,$B7)="","",INDEX(Homiladorlar!$F$5:$F$804,$B7))) | F7: =IF($B7="","",IF(INDEX(Homiladorlar!$E$5:$E$804,$B7)="","",INDEX(Homiladorlar!$E$5:$E$804,$B7))) | G7: =IF($B7="","",IF(INDEX(Homiladorlar!$O$5:$O$804,$B7)="","",INDEX(Homiladorlar!$O$5:$O$804,$B7))) | H7: =IF($B7="","",IF(INDEX(Homiladorlar!$Q$5:$Q$804,$B7)="","",INDEX(Homiladorlar!$Q$5:$Q$804,$B7))) | I7: =IF($B7="","",IF(INDEX(Homiladorlar!$R$5:$R$804,$B7)="","",INDEX(Homiladorlar!$R$5:$R$804,$B7))) | J7: =IF($B7="","",IF(INDEX(Homiladorlar!$K$5:$K$804,$B7)="","",INDEX(Homiladorlar!$K$5:$K$804,$B7))) | K7: =IF($B7="","",IF(INDEX(Homiladorlar!$J$5:$J$804,$B7)="","",INDEX(Homiladorlar!$J$5:$J$804,$B7))) | L7: =IF($B7="","",IF(INDEX(Homiladorlar!$T$5:$T$804,$B7)="","",INDEX(Homiladorlar!$T$5:$T$804,$B7))) | M7: =IF($B7="","",IF(INDEX(Homiladorlar!$AB$5:$AB$804,$B7)="","",INDEX(Homiladorlar!$AB$5:$AB$804,$B7))) | N7: =IF($B7="","",IF(INDEX(Homiladorlar!$AC$5:$AC$804,$B7)="","",INDEX(Homiladorlar!$AC$5:$AC$804,$B7)))
A8: 4 | B8: =IFERROR(MATCH(A8,Homiladorlar!$AH$5:$AH$804,0),"") | C8: =IF($B8="","",IF(INDEX(Homiladorlar!$B$5:$B$804,$B8)="","",INDEX(Homiladorlar!$B$5:$B$804,$B8))) | D8: =IF($B8="","",IF(INDEX(Homiladorlar!$C$5:$C$804,$B8)="","",INDEX(Homiladorlar!$C$5:$C$804,$B8))) | E8: =IF($B8="","",IF(INDEX(Homiladorlar!$F$5:$F$804,$B8)="","",INDEX(Homiladorlar!$F$5:$F$804,$B8))) | F8: =IF($B8="","",IF(INDEX(Homiladorlar!$E$5:$E$804,$B8)="","",INDEX(Homiladorlar!$E$5:$E$804,$B8))) | G8: =IF($B8="","",IF(INDEX(Homiladorlar!$O$5:$O$804,$B8)="","",INDEX(Homiladorlar!$O$5:$O$804,$B8))) | H8: =IF($B8="","",IF(INDEX(Homiladorlar!$Q$5:$Q$804,$B8)="","",INDEX(Homiladorlar!$Q$5:$Q$804,$B8))) | I8: =IF($B8="","",IF(INDEX(Homiladorlar!$R$5:$R$804,$B8)="","",INDEX(Homiladorlar!$R$5:$R$804,$B8))) | J8: =IF($B8="","",IF(INDEX(Homiladorlar!$K$5:$K$804,$B8)="","",INDEX(Homiladorlar!$K$5:$K$804,$B8))) | K8: =IF($B8="","",IF(INDEX(Homiladorlar!$J$5:$J$804,$B8)="","",INDEX(Homiladorlar!$J$5:$J$804,$B8))) | L8: =IF($B8="","",IF(INDEX(Homiladorlar!$T$5:$T$804,$B8)="","",INDEX(Homiladorlar!$T$5:$T$804,$B8))) | M8: =IF($B8="","",IF(INDEX(Homiladorlar!$AB$5:$AB$804,$B8)="","",INDEX(Homiladorlar!$AB$5:$AB$804,$B8))) | N8: =IF($B8="","",IF(INDEX(Homiladorlar!$AC$5:$AC$804,$B8)="","",INDEX(Homiladorlar!$AC$5:$AC$804,$B8)))
A9: 5 | B9: =IFERROR(MATCH(A9,Homiladorlar!$AH$5:$AH$804,0),"") | C9: =IF($B9="","",IF(INDEX(Homiladorlar!$B$5:$B$804,$B9)="","",INDEX(Homiladorlar!$B$5:$B$804,$B9))) | D9: =IF($B9="","",IF(INDEX(Homiladorlar!$C$5:$C$804,$B9)="","",INDEX(Homiladorlar!$C$5:$C$804,$B9))) | E9: =IF($B9="","",IF(INDEX(Homiladorlar!$F$5:$F$804,$B9)="","",INDEX(Homiladorlar!$F$5:$F$804,$B9))) | F9: =IF($B9="","",IF(INDEX(Homiladorlar!$E$5:$E$804,$B9)="","",INDEX(Homiladorlar!$E$5:$E$804,$B9))) | G9: =IF($B9="","",IF(INDEX(Homiladorlar!$O$5:$O$804,$B9)="","",INDEX(Homiladorlar!$O$5:$O$804,$B9))) | H9: =IF($B9="","",IF(INDEX(Homiladorlar!$Q$5:$Q$804,$B9)="","",INDEX(Homiladorlar!$Q$5:$Q$804,$B9))) | I9: =IF($B9="","",IF(INDEX(Homiladorlar!$R$5:$R$804,$B9)="","",INDEX(Homiladorlar!$R$5:$R$804,$B9))) | J9: =IF($B9="","",IF(INDEX(Homiladorlar!$K$5:$K$804,$B9)="","",INDEX(Homiladorlar!$K$5:$K$804,$B9))) | K9: =IF($B9="","",IF(INDEX(Homiladorlar!$J$5:$J$804,$B9)="","",INDEX(Homiladorlar!$J$5:$J$804,$B9))) | L9: =IF($B9="","",IF(INDEX(Homiladorlar!$T$5:$T$804,$B9)="","",INDEX(Homiladorlar!$T$5:$T$804,$B9))) | M9: =IF($B9="","",IF(INDEX(Homiladorlar!$AB$5:$AB$804,$B9)="","",INDEX(Homiladorlar!$AB$5:$AB$804,$B9))) | N9: =IF($B9="","",IF(INDEX(Homiladorlar!$AC$5:$AC$804,$B9)="","",INDEX(Homiladorlar!$AC$5:$AC$804,$B9)))
A10: 6 | B10: =IFERROR(MATCH(A10,Homiladorlar!$AH$5:$AH$804,0),"") | C10: =IF($B10="","",IF(INDEX(Homiladorlar!$B$5:$B$804,$B10)="","",INDEX(Homiladorlar!$B$5:$B$804,$B10))) | D10: =IF($B10="","",IF(INDEX(Homiladorlar!$C$5:$C$804,$B10)="","",INDEX(Homiladorlar!$C$5:$C$804,$B10))) | E10: =IF($B10="","",IF(INDEX(Homiladorlar!$F$5:$F$804,$B10)="","",INDEX(Homiladorlar!$F$5:$F$804,$B10))) | F10: =IF($B10="","",IF(INDEX(Homiladorlar!$E$5:$E$804,$B10)="","",INDEX(Homiladorlar!$E$5:$E$804,$B10))) | G10: =IF($B10="","",IF(INDEX(Homiladorlar!$O$5:$O$804,$B10)="","",INDEX(Homiladorlar!$O$5:$O$804,$B10))) | H10: =IF($B10="","",IF(INDEX(Homiladorlar!$Q$5:$Q$804,$B10)="","",INDEX(Homiladorlar!$Q$5:$Q$804,$B10))) | I10: =IF($B10="","",IF(INDEX(Homiladorlar!$R$5:$R$804,$B10)="","",INDEX(Homiladorlar!$R$5:$R$804,$B10))) | J10: =IF($B10="","",IF(INDEX(Homiladorlar!$K$5:$K$804,$B10)="","",INDEX(Homiladorlar!$K$5:$K$804,$B10))) | K10: =IF($B10="","",IF(INDEX(Homiladorlar!$J$5:$J$804,$B10)="","",INDEX(Homiladorlar!$J$5:$J$804,$B10))) | L10: =IF($B10="","",IF(INDEX(Homiladorlar!$T$5:$T$804,$B10)="","",INDEX(Homiladorlar!$T$5:$T$804,$B10))) | M10: =IF($B10="","",IF(INDEX(Homiladorlar!$AB$5:$AB$804,$B10)="","",INDEX(Homiladorlar!$AB$5:$AB$804,$B10))) | N10: =IF($B10="","",IF(INDEX(Homiladorlar!$AC$5:$AC$804,$B10)="","",INDEX(Homiladorlar!$AC$5:$AC$804,$B10)))
A11: 7 | B11: =IFERROR(MATCH(A11,Homiladorlar!$AH$5:$AH$804,0),"") | C11: =IF($B11="","",IF(INDEX(Homiladorlar!$B$5:$B$804,$B11)="","",INDEX(Homiladorlar!$B$5:$B$804,$B11))) | D11: =IF($B11="","",IF(INDEX(Homiladorlar!$C$5:$C$804,$B11)="","",INDEX(Homiladorlar!$C$5:$C$804,$B11))) | E11: =IF($B11="","",IF(INDEX(Homiladorlar!$F$5:$F$804,$B11)="","",INDEX(Homiladorlar!$F$5:$F$804,$B11))) | F11: =IF($B11="","",IF(INDEX(Homiladorlar!$E$5:$E$804,$B11)="","",INDEX(Homiladorlar!$E$5:$E$804,$B11))) | G11: =IF($B11="","",IF(INDEX(Homiladorlar!$O$5:$O$804,$B11)="","",INDEX(Homiladorlar!$O$5:$O$804,$B11))) | H11: =IF($B11="","",IF(INDEX(Homiladorlar!$Q$5:$Q$804,$B11)="","",INDEX(Homiladorlar!$Q$5:$Q$804,$B11))) | I11: =IF($B11="","",IF(INDEX(Homiladorlar!$R$5:$R$804,$B11)="","",INDEX(Homiladorlar!$R$5:$R$804,$B11))) | J11: =IF($B11="","",IF(INDEX(Homiladorlar!$K$5:$K$804,$B11)="","",INDEX(Homiladorlar!$K$5:$K$804,$B11))) | K11: =IF($B11="","",IF(INDEX(Homiladorlar!$J$5:$J$804,$B11)="","",INDEX(Homiladorlar!$J$5:$J$804,$B11))) | L11: =IF($B11="","",IF(INDEX(Homiladorlar!$T$5:$T$804,$B11)="","",INDEX(Homiladorlar!$T$5:$T$804,$B11))) | M11: =IF($B11="","",IF(INDEX(Homiladorlar!$AB$5:$AB$804,$B11)="","",INDEX(Homiladorlar!$AB$5:$AB$804,$B11))) | N11: =IF($B11="","",IF(INDEX(Homiladorlar!$AC$5:$AC$804,$B11)="","",INDEX(Homiladorlar!$AC$5:$AC$804,$B11)))
A12: 8 | B12: =IFERROR(MATCH(A12,Homiladorlar!$AH$5:$AH$804,0),"") | C12: =IF($B12="","",IF(INDEX(Homiladorlar!$B$5:$B$804,$B12)="","",INDEX(Homiladorlar!$B$5:$B$804,$B12))) | D12: =IF($B12="","",IF(INDEX(Homiladorlar!$C$5:$C$804,$B12)="","",INDEX(Homiladorlar!$C$5:$C$804,$B12))) | E12: =IF($B12="","",IF(INDEX(Homiladorlar!$F$5:$F$804,$B12)="","",INDEX(Homiladorlar!$F$5:$F$804,$B12))) | F12: =IF($B12="","",IF(INDEX(Homiladorlar!$E$5:$E$804,$B12)="","",INDEX(Homiladorlar!$E$5:$E$804,$B12))) | G12: =IF($B12="","",IF(INDEX(Homiladorlar!$O$5:$O$804,$B12)="","",INDEX(Homiladorlar!$O$5:$O$804,$B12))) | H12: =IF($B12="","",IF(INDEX(Homiladorlar!$Q$5:$Q$804,$B12)="","",INDEX(Homiladorlar!$Q$5:$Q$804,$B12))) | I12: =IF($B12="","",IF(INDEX(Homiladorlar!$R$5:$R$804,$B12)="","",INDEX(Homiladorlar!$R$5:$R$804,$B12))) | J12: =IF($B12="","",IF(INDEX(Homiladorlar!$K$5:$K$804,$B12)="","",INDEX(Homiladorlar!$K$5:$K$804,$B12))) | K12: =IF($B12="","",IF(INDEX(Homiladorlar!$J$5:$J$804,$B12)="","",INDEX(Homiladorlar!$J$5:$J$804,$B12))) | L12: =IF($B12="","",IF(INDEX(Homiladorlar!$T$5:$T$804,$B12)="","",INDEX(Homiladorlar!$T$5:$T$804,$B12))) | M12: =IF($B12="","",IF(INDEX(Homiladorlar!$AB$5:$AB$804,$B12)="","",INDEX(Homiladorlar!$AB$5:$AB$804,$B12))) | N12: =IF($B12="","",IF(INDEX(Homiladorlar!$AC$5:$AC$804,$B12)="","",INDEX(Homiladorlar!$AC$5:$AC$804,$B12)))
A13: 9 | B13: =IFERROR(MATCH(A13,Homiladorlar!$AH$5:$AH$804,0),"") | C13: =IF($B13="","",IF(INDEX(Homiladorlar!$B$5:$B$804,$B13)="","",INDEX(Homiladorlar!$B$5:$B$804,$B13))) | D13: =IF($B13="","",IF(INDEX(Homiladorlar!$C$5:$C$804,$B13)="","",INDEX(Homiladorlar!$C$5:$C$804,$B13))) | E13: =IF($B13="","",IF(INDEX(Homiladorlar!$F$5:$F$804,$B13)="","",INDEX(Homiladorlar!$F$5:$F$804,$B13))) | F13: =IF($B13="","",IF(INDEX(Homiladorlar!$E$5:$E$804,$B13)="","",INDEX(Homiladorlar!$E$5:$E$804,$B13))) | G13: =IF($B13="","",IF(INDEX(Homiladorlar!$O$5:$O$804,$B13)="","",INDEX(Homiladorlar!$O$5:$O$804,$B13))) | H13: =IF($B13="","",IF(INDEX(Homiladorlar!$Q$5:$Q$804,$B13)="","",INDEX(Homiladorlar!$Q$5:$Q$804,$B13))) | I13: =IF($B13="","",IF(INDEX(Homiladorlar!$R$5:$R$804,$B13)="","",INDEX(Homiladorlar!$R$5:$R$804,$B13))) | J13: =IF($B13="","",IF(INDEX(Homiladorlar!$K$5:$K$804,$B13)="","",INDEX(Homiladorlar!$K$5:$K$804,$B13))) | K13: =IF($B13="","",IF(INDEX(Homiladorlar!$J$5:$J$804,$B13)="","",INDEX(Homiladorlar!$J$5:$J$804,$B13))) | L13: =IF($B13="","",IF(INDEX(Homiladorlar!$T$5:$T$804,$B13)="","",INDEX(Homiladorlar!$T$5:$T$804,$B13))) | M13: =IF($B13="","",IF(INDEX(Homiladorlar!$AB$5:$AB$804,$B13)="","",INDEX(Homiladorlar!$AB$5:$AB$804,$B13))) | N13: =IF($B13="","",IF(INDEX(Homiladorlar!$AC$5:$AC$804,$B13)="","",INDEX(Homiladorlar!$AC$5:$AC$804,$B13)))
A14: 10 | B14: =IFERROR(MATCH(A14,Homiladorlar!$AH$5:$AH$804,0),"") | C14: =IF($B14="","",IF(INDEX(Homiladorlar!$B$5:$B$804,$B14)="","",INDEX(Homiladorlar!$B$5:$B$804,$B14))) | D14: =IF($B14="","",IF(INDEX(Homiladorlar!$C$5:$C$804,$B14)="","",INDEX(Homiladorlar!$C$5:$C$804,$B14))) | E14: =IF($B14="","",IF(INDEX(Homiladorlar!$F$5:$F$804,$B14)="","",INDEX(Homiladorlar!$F$5:$F$804,$B14))) | F14: =IF($B14="","",IF(INDEX(Homiladorlar!$E$5:$E$804,$B14)="","",INDEX(Homiladorlar!$E$5:$E$804,$B14))) | G14: =IF($B14="","",IF(INDEX(Homiladorlar!$O$5:$O$804,$B14)="","",INDEX(Homiladorlar!$O$5:$O$804,$B14))) | H14: =IF($B14="","",IF(INDEX(Homiladorlar!$Q$5:$Q$804,$B14)="","",INDEX(Homiladorlar!$Q$5:$Q$804,$B14))) | I14: =IF($B14="","",IF(INDEX(Homiladorlar!$R$5:$R$804,$B14)="","",INDEX(Homiladorlar!$R$5:$R$804,$B14))) | J14: =IF($B14="","",IF(INDEX(Homiladorlar!$K$5:$K$804,$B14)="","",INDEX(Homiladorlar!$K$5:$K$804,$B14))) | K14: =IF($B14="","",IF(INDEX(Homiladorlar!$J$5:$J$804,$B14)="","",INDEX(Homiladorlar!$J$5:$J$804,$B14))) | L14: =IF($B14="","",IF(INDEX(Homiladorlar!$T$5:$T$804,$B14)="","",INDEX(Homiladorlar!$T$5:$T$804,$B14))) | M14: =IF($B14="","",IF(INDEX(Homiladorlar!$AB$5:$AB$804,$B14)="","",INDEX(Homiladorlar!$AB$5:$AB$804,$B14))) | N14: =IF($B14="","",IF(INDEX(Homiladorlar!$AC$5:$AC$804,$B14)="","",INDEX(Homiladorlar!$AC$5:$AC$804,$B14)))
