Workbook

Sheet Yoriqnoma
A1: YO‘RIQNOMA / ИНСТРУКЦИЯ — Vrach-pediatr
A2: Врач-педиатр
A3: MAXFIY / КОНФИДЕНЦИАЛЬНО — bu fayl shaxsiy va tibbiy ma’lumotlarni saqlaydi (shifokorlik siri). Faqat o‘zingizda saqlang, parol qo‘ying; o‘rinbosarga FAQAT «Chop_etish» varag‘i (qog‘oz) va «Eksport» qatori (yig‘ma sonlar) topshiriladi. / Файл хранит персональные и медицинские данные (врачебная тайна). Храните у себя, поставьте пароль; заместителю сдаются ТОЛЬКО лист «Chop_etish» (бумага) и строка «Eksport» (агрегаты).
B4: Kim to‘ldiradi / Кто заполняет | C4: Vrach-pediatr / Врач-педиатр
B5: Kimga topshiriladi / Кому сдаётся | C5: Birlashma boshlig'ining onalik va bolalikni muhofaza qilish bo'yicha o'rinbosari / Заместитель начальника объединения по охране материнства и детства
B6: Muddat / Срок | C6: Har oyning 5-sanasigacha, soat 17:00 gacha / до 5-го числа каждого месяца, до 17:00
B7: Papkalar / Папки | C7: № 3, 5
A9: 1. Qanday ishlash kerak / Как работать
A10: № | B10: Qadam / Шаг | C10: O‘zbekcha (lotin) | D10: Русский
A11: 1 | B11: Bolalar ro‘yxatini tuzing | C11: Uchastkadagi har bir bolani «Bolalar»ga bir marta yozing (F.I.Sh., tug‘ilgan sana, ona). Dispanser va sog‘lomlashtirish ham shu yerda. | D11: Внесите каждого ребёнка участка в «Bolalar» один раз (ФИО, дата рождения, мать). Диспансер и оздоровление — там же.
A12: 2 | B12: Boshqa jurnallarda bolani tanlang | C12: Kasallanish, o‘lim, patronaj, profilaktik ko‘rik — bolani ro‘yxatdan tanlang; yosh va guruhlar o‘zi hisoblanadi. | D12: Заболеваемость, смерть, патронаж, профосмотр — выберите ребёнка из списка; возраст и группы считаются сами.
A13: 3 | B13: Chaqaloqlar patronaji | C13: «Yangi_tugilgan»da tug‘ruqxonadan chiqish va 1-patronaj sanasini yozing — muddat o‘zi tekshiriladi; muddati o‘tganlar qizil bo‘ladi. | D13: В «Yangi_tugilgan» укажите дату выписки и дату 1-го патронажа — срок проверяется сам; просроченные станут красными.
A14: 4 | B14: «Boshqaruv» varag‘i | C14: Davr boshi va oxirini (C9, C10), muassasa va F.I.Sh.ni kiriting. Ko‘rsatkichlar jurnallardan o‘zi hisoblanadi; sariq ko‘rsatkichlarni qo‘lda kiriting. «TAYYORLIK» qatori «✔ TAYYOR» bo‘lishi kerak. | D14: Введите начало и конец периода (C9, C10), учреждение и ФИО. Показатели считаются сами из журналов; жёлтые показатели введите вручную. Строка «ГОТОВНОСТЬ» должна показать «✔ ГОТОВО».
A15: 5 | B15: «Chop_etish» varag‘i | C15: A4 qog‘ozga bir bet qilib chop eting, «Tayyorladi»ga imzo qo‘ying, rahbarga imzolating, M.O. joyiga muhr bosdiring. Qog‘ozdagi raqamlar Excel bilan bir xil bo‘lsin. | D15: Распечатайте на одном листе А4, подпишите («Подготовил(а)»), заверьте у руководителя и поставьте печать в поле М.П. Цифры на бумаге должны совпадать с Excel.
A16: 6 | B16: «Eksport» qatori va yuborish | C16: «Eksport» varag‘ining 4-qatori — yig‘ma sonlar (shaxsiy ma’lumotsiz). Faylni EMAS, faqat shu qatorni (yoki «Chop_etish»ni) yuboring. Fayl nomi: Rol_Muassasa_Davr.xlsx. | D16: Строка 4 листа «Eksport» — агрегированные числа (без персональных данных). Отправляйте не файл, а только эту строку (или «Chop_etish»). Имя файла: Роль_Учреждение_Период.xlsx.
A18: 2. Varaqlar va jurnallar / Листы и журналы
A19: № | B19: Varaq / Лист | C19: Nima uchun / Для чего (uz) | D19: Для чего (ru)
A20: 1 | B20: Bolalar | C20: Uchastka bolalari: yoshi (avto), hisobda turishi, dispanser, sog‘lomlashtirilgan sana. Ko‘rsatkichlar 1, 5, 6. Boshqa jurnallarda bola shu ro‘yxatdan tanlanadi. | D20: Дети участка: возраст (авто), учёт, диспансер, дата оздоровления. Показатели 1, 5, 6. В других журналах ребёнок выбирается из этого списка.
A21: 2 | B21: Kasallanish | C21: Bolalar kasallanishi: 5 yoshgacha (ko‘rsatkich 2) va 0–17 yosh (12). | D21: Заболеваемость детей: до 5 лет (показатель 2) и 0–17 лет (12).
A22: 3 | B22: Olim_bolalar | C22: 5 yoshgacha (ko‘rsatkich 3) va 0–17 yosh (13) bolalar o‘limi. | D22: Смертность детей до 5 лет (показатель 3) и 0–17 лет (13).
A23: 4 | B23: Yangi_tugilgan | C23: Chaqaloqlarning 1-patronaji: tug‘ruqxonadan chiqqach muddat ichida qamrab olinganmi (ko‘rsatkichlar 4 va 10). | D23: Первый патронаж новорождённых: охвачены ли в срок после выписки (показатели 4 и 10).
A24: 5 | B24: Patronaj_0_5 | C24: 0–5 yoshli bolalarning patronaj tashriflari (ko‘rsatkich 11; chaqaloqlarning 1-patronaji «Yangi_tugilgan»dan qo‘shiladi). | D24: Патронажные визиты к детям 0–5 лет (показатель 11; первый патронаж новорождённых добавляется из «Yangi_tugilgan»).
A25: 6 | B25: Emlash | C25: Emlash rejasi va bajarilishi: rejadagi bolalar, emlanganlar, qamrov (hammasi bolalar bo‘yicha), 2 yoshgacha va 7–17 yosh kesimida. | D25: План и выполнение прививок: плановые, привитые, охват (по детям), в разрезе до 2 лет и 7–17 лет.
A26: 7 | B26: Profilaktik_korik | C26: Profilaktik ko‘rikdan o‘tgan bolalar va o‘smirlar (ko‘rsatkich 14). | D26: Дети и подростки, прошедшие профилактический осмотр (показатель 14).
A27: 8 | B27: Skrining_bolalar | C27: Gelmintoz (2–10) va onkogematologik (2–18) skrining — ko‘rsatkichlar 15, 16. | D27: Гельминтозы (2–10) и онкогематологический скрининг (2–18) — показатели 15, 16.
A28: 9 | B28: Boshqaruv | C28: Davr, ko‘rsatkichlar (avto), tekshiruvlar, tayyorlik. | D28: Период, показатели (авто), проверки, готовность.
A29: 10 | B29: Hujjatlar | C29: Topshiriladigan hujjatlar ro‘yxati va ularning holati. | D29: Перечень сдаваемых документов и их статус.
A30: 11 | B30: Chop_etish | C30: Qog‘oz nusxa (imzo va muhr uchun). | D30: Бумажный экземпляр (для подписи и печати).
A31: 12 | B31: Eksport | C31: O‘rinbosarga yuboriladigan bir qator. | D31: Строка для отправки заместителю.
A33: 3. Qoidalar / Правила
A34: № | B34: Qoida / Правило | C34: O‘zbekcha (lotin) | D34: Русский
A35: 1 | B35: Ranglar | C35: Sariq katak — kiritiladi. Yashil — avtomatik (tegmang). Kulrang — yordamchi ustun. Qizil — xato/muddat o‘tgan. Ustun sarlavhasi: ko‘k — kiritish, yashil — avtomatik. | D35: Жёлтая — ввод. Зелёная — авто (не трогать). Серая — вспомогательная. Красная — ошибка/просрочка. Заголовок: синий — ввод, зелёный — авто.
A36: 2 | B36: Bir marta yozing | C36: Har bir shaxs/hodisa bitta qatorga yoziladi; takror yozuv qizil bo‘ladi. Sanani kun.oy.yil ko‘rinishida kiriting. | D36: Каждый человек/событие — одна строка; дубль подсвечивается красным. Даты вводите как дд.мм.гггг.
A37: 3 | B37: Tashxis va xavf | C37: Tashxis va xavf sababini faqat davolovchi shifokor hujjatidan (karta, xulosa) ko‘chiring — o‘zingizdan yozmang; hujjat raqamini ham yozing. | D37: Диагноз и причину риска переписывайте только из документа лечащего врача (карта, заключение), не от себя; укажите № документа.
A38: 4 | B38: Maxfiylik | C38: Fayl faqat sizda; guruhga yubormang. PINFL — 14 ta raqam, «PINFL» ustuniga; faylni parol bilan himoyalang. Yig‘ma ma’lumot — «Eksport» va «Chop_etish». | D38: Файл только у вас; в группы не отправлять. ПИНФЛ — 14 цифр, в столбец «ПИНФЛ»; защитите файл паролем. Агрегаты — «Eksport» и «Chop_etish».
A39: 5 | B39: Nusxa | C39: Har oy oxirida faylning zaxira nusxasini saqlang (Fayl → Boshqacha saqlash). | D39: В конце каждого месяца сохраняйте резервную копию файла.
A40: 6 | B40: Eng ko‘p xatolar | C40: Sanani matn qilib yozish; yashil katakni o‘zgartirish; ro‘yxatdan tashqari qiymat; davrni (C9, C10) kiritmaslik; qog‘oz va Excel raqamlari mos kelmasligi; imzo/muhrsiz topshirish. | D40: Дата текстом; правка зелёных ячеек; значение не из списка; не введён период (C9, C10); цифры на бумаге и в Excel не совпадают; сдача без подписи/печати.

Sheet Boshqaruv
A1: BOSHQARUV VA KO‘RSATKICHLAR / УПРАВЛЕНИЕ И ПОКАЗАТЕЛИ — Vrach-pediatr
A2: Врач-педиатр
A3: Bu yerda faqat davr va ma’lumotlarni kiriting; ko‘rsatkichlar jurnallardan O‘ZI hisoblanadi (yashil). Sariq katak — qo‘lda kiritiladi. / Здесь вводятся период и реквизиты; показатели считаются САМИ из журналов (зелёные). Жёлтая ячейка — вводится вручную.
B5: Muassasa (nomi, №) / Учреждение | C5: СВП №3 (тест)
B6: F.I.Sh. (to‘ldiruvchi) / Ф.И.О. (заполняющий) | C6: Детская Тест Ольга
B7: Lavozimi / Должность | C7: Vrach-pediatr / Врач-педиатр
B8: Telefon / Телефон | C8: +998900000003
B9: Davr boshi (sana) / Начало периода (дата) | C9: 46266 | D9: ← masalan / напр.: 01.09.2026
B10: Davr oxiri (sana) / Конец периода (дата) | C10: 46295 | D10: ← masalan / напр.: 30.09.2026
B11: Davr (avto) / Период (авто) | C11: =IF(OR(C9="",C10=""),"",DAY(C9)&"."&MONTH(C9)&"."&YEAR(C9)&" – "&DAY(C10)&"."&MONTH(C10)&"."&YEAR(C10)) -> 1.9.2026 – 30.9.2026
B12: Hisob sanasi (avto: davr oxiri, bo‘sh bo‘lsa — bugun) / Дата расчёта (авто: конец периода, иначе сегодня) | C12: =IF(C10="",TODAY(),C10) -> 46295
B13: TAYYORLIK / ГОТОВНОСТЬ | C13: =IF(IF(OR(C9="",C10=""),"davrni kiriting (C9, C10); ","")&IF(AND(C9<>"",C10<>"",C10<C9),"davr oxiri boshidan oldin; ","")&IF(OR(C5="",C6=""),"muassasa va F.I.Sh.; ","")&IF(SUM(D36,D37,D38,D39,D40,D43,D44,D45,D46,D48,D50,D51)>0,"jurnallarda xatolar bor (pastga qarang); ","")="","✔ TAYYOR / ГОТОВО","✖ TO‘LIQ EMAS / НЕ ПОЛНО: "&IF(OR(C9="",C10=""),"davrni kiriting (C9, C10); ","")&IF(AND(C9<>"",C10<>"",C10<C9),"davr oxiri boshidan oldin; ","")&IF(OR(C5="",C6=""),"muassasa va F.I.Sh.; ","")&IF(SUM(D36,D37,D38,D39,D40,D43,D44,D45,D46,D48,D50,D51)>0,"jurnallarda xatolar bor (pastga qarang); ","")) -> ✔ TAYYOR / ГОТОВО
B14: HUJJATLAR / ДОКУМЕНТЫ | C14: =IF(COUNTBLANK(Hujjatlar!E5:E9)=0,"✔ Hammasi belgilangan / Всё отмечено","✖ Hujjatlar varag‘ida belgilanmagan: "&COUNTBLANK(Hujjatlar!E5:E9)&" ta") -> ✖ Hujjatlar varag‘ida belgilanmagan: 5 ta
A16: T/r | B16: Ko‘rsatkich | C16: Показатель | D16: Birlik | E16: Papka | F16: Qiymat / Значение | G16: Manba / Источник и как считается
A17: 1 | B17: 0–14 yoshdagi bolalar soni | C17: Число детей 0–14 лет | D17: nafar | E17: 3 | F17: =IF(OR(Boshqaruv!$C$9="",Boshqaruv!$C$10=""),"",COUNTIFS(Bolalar!$N$5:$N$1804,"Ha",Bolalar!$K$5:$K$1804,"Ha")) -> 6 | G17: AVTOMATIK: «Bolalar»: hisobda va 0–14 yosh (davr oxiriga). / АВТОМАТИЧЕСКИ: «Bolalar»: на учёте и 0–14 лет (на конец периода).
A18: 2 | B18: 5 yoshgacha bolalar kasallanishi | C18: Заболеваемость детей до 5 лет | D18: ta | E18: 3 | F18: =IF(OR(Boshqaruv!$C$9="",Boshqaruv!$C$10=""),"",COUNTIFS(Kasallanish!$B$5:$B$2504,">="&Boshqaruv!$C$9,Kasallanish!$B$5:$B$2504,"<="&Boshqaruv!$C$10,Kasallanish!$H$5:$H$2504,"Ha")) -> 0 | G18: AVTOMATIK: «Kasallanish»: 5 yoshgacha, davrda. / АВТОМАТИЧЕСКИ: «Kasallanish»: до 5 лет, за период.
A19: 3 | B19: 5 yoshgacha bolalar o'limi | C19: Смертность детей до 5 лет | D19: ta | E19: 3 | F19: =IF(OR(Boshqaruv!$C$9="",Boshqaruv!$C$10=""),"",COUNTIFS(Olim_bolalar!$B$5:$B$104,">="&Boshqaruv!$C$9,Olim_bolalar!$B$5:$B$104,"<="&Boshqaruv!$C$10,Olim_bolalar!$H$5:$H$104,"Ha")) -> 0 | G19: AVTOMATIK: «Olim_bolalar»: 5 yoshgacha. / АВТОМАТИЧЕСКИ: «Olim_bolalar»: до 5 лет.
A20: 4 | B20: Yangi tug'ilganlarni patronaj bilan qamrab olish | C20: Охват новорождённых патронажем | D20: nafar | E20: 3 | F20: =IF(OR(Boshqaruv!$C$9="",Boshqaruv!$C$10=""),"",COUNTIFS(Yangi_tugilgan!$I$5:$I$604,">="&Boshqaruv!$C$9,Yangi_tugilgan!$I$5:$I$604,"<="&Boshqaruv!$C$10,Yangi_tugilgan!$B$5:$B$604,"<>")) -> 0 | G20: AVTOMATIK: «Yangi_tugilgan»: 1-patronaj sanasi davrda. / АВТОМАТИЧЕСКИ: «Yangi_tugilgan»: дата 1-го патронажа в периоде.
A21: 5 | B21: Dispanser hisobidagi bolalar | C21: Дети на диспансерном учёте | D21: nafar | E21: 3 | F21: =IF(OR(Boshqaruv!$C$9="",Boshqaruv!$C$10=""),"",COUNTIFS(Bolalar!$T$5:$T$1804,"Ha")) -> 0 | G21: AVTOMATIK: «Bolalar»: dispanser hisobida (davr oxiriga). / АВТОМАТИЧЕСКИ: «Bolalar»: на диспансерном учёте (на конец периода).
A22: 6 | B22: Sog'lomlashtirilgan bolalar | C22: Оздоровлено детей | D22: nafar | E22: 3 | F22: =IF(OR(Boshqaruv!$C$9="",Boshqaruv!$C$10=""),"",COUNTIFS(Bolalar!$U$5:$U$1804,">="&Boshqaruv!$C$9,Bolalar!$U$5:$U$1804,"<="&Boshqaruv!$C$10,Bolalar!$B$5:$B$1804,"<>")) -> 0 | G22: AVTOMATIK: «Bolalar»: sog‘lomlashtirilgan sana davrda. / АВТОМАТИЧЕСКИ: «Bolalar»: дата оздоровления в периоде.
A23: 7 | B23: Emlanishi kerak bo'lgan bolalar (reja) | C23: Подлежит прививкам (план) | D23: nafar | E23: 5 | F23: =IF(OR(Boshqaruv!$C$9="",Boshqaruv!$C$10=""),"",COUNTIFS(Emlash!$Q$5:$Q$2004,1)) -> 0 | G23: AVTOMATIK: «Emlash»: davrda rejadagi bolalar (har bir bola bir marta). / АВТОМАТИЧЕСКИ: «Emlash»: плановые дети за период (каждый ребёнок один раз).
A24: 8 | B24: Emlangan bolalar | C24: Привито детей | D24: nafar | E24: 5 | F24: =IF(OR(Boshqaruv!$C$9="",Boshqaruv!$C$10=""),"",COUNTIFS(Emlash!$R$5:$R$2004,1)) -> 0 | G24: AVTOMATIK: Rejadagilardan emlanganlar (bolalar). / АВТОМАТИЧЕСКИ: Из плановых — привитые (дети).
A25: 9 | B25: Emlash qamrovi | C25: Охват прививками | D25: % | E25: 5 | F25: =IF(OR(Boshqaruv!$C$9="",Boshqaruv!$C$10=""),"",IF(N($F$23)=0,"",$F$24/$F$23)) | G25: AVTOMATIK: 8-qator / 7-qator. / АВТОМАТИЧЕСКИ: Строка 8 / строка 7.
A26: 10 | B26: 3 kun ichida patronaj bilan qamrab olingan chaqaloqlar (tug‘ruqxonadan chiqqach) | C26: Новорождённые, охваченные патронажем в течение 3 дней после выписки | D26: nafar | E26: 3 | F26: =IF(OR(Boshqaruv!$C$9="",Boshqaruv!$C$10=""),"",COUNTIFS(Yangi_tugilgan!$I$5:$I$604,">="&Boshqaruv!$C$9,Yangi_tugilgan!$I$5:$I$604,"<="&Boshqaruv!$C$10,Yangi_tugilgan!$K$5:$K$604,"Ha")) -> 0 | G26: AVTOMATIK: «Yangi_tugilgan»: chiqqandan keyin ≤ patronaj muddati (Spravochnik: kun). / АВТОМАТИЧЕСКИ: «Yangi_tugilgan»: ≤ срока патронажа после выписки (параметр: дни). [Asos: 178-son buyruq (2023), reyting mezonlari]
A27: 11 | B27: 0–5 yoshli bolalar patronaj bilan qamrab olinganlar | C27: Дети 0–5 лет, охваченные патронажем | D27: nafar | E27: 3 | F27: =IF(OR(Boshqaruv!$C$9="",Boshqaruv!$C$10=""),"",COUNTIFS(Patronaj_0_5!$K$5:$K$2504,1)+COUNTIFS(Yangi_tugilgan!$O$5:$O$604,1)) -> 0 | G27: AVTOMATIK: «Patronaj_0_5» (har bir bola 1 marta) + «Yangi_tugilgan»da 1-patronaji bor, lekin patronaj jurnalida yo‘q chaqaloqlar. / АВТОМАТИЧЕСКИ: «Patronaj_0_5» (каждый ребёнок 1 раз) + новорождённые с 1-м патронажем, которых нет в журнале патронажа. [Asos: 178-son buyruq (2023), reyting mezonlari]
A28: 12 | B28: [Voyaga yetmaganlar] 0–17 yoshdagi bolalar kasallanishi | C28: [Несовершеннолетние] Заболеваемость детей 0–17 лет | D28: ta | E28: 3 | F28: =IF(OR(Boshqaruv!$C$9="",Boshqaruv!$C$10=""),"",COUNTIFS(Kasallanish!$B$5:$B$2504,">="&Boshqaruv!$C$9,Kasallanish!$B$5:$B$2504,"<="&Boshqaruv!$C$10,Kasallanish!$I$5:$I$2504,"Ha")) -> 0 | G28: AVTOMATIK: «Kasallanish»: 0–17 yosh, davrda. / АВТОМАТИЧЕСКИ: «Kasallanish»: 0–17 лет, за период. [Asos: 363-son buyruq (2020), tibbiy hisob shakllari]
A29: 13 | B29: [Voyaga yetmaganlar] 0–17 yoshdagi bolalar o‘limi | C29: [Несовершеннолетние] Смертность детей 0–17 лет | D29: ta | E29: 3 | F29: =IF(OR(Boshqaruv!$C$9="",Boshqaruv!$C$10=""),"",COUNTIFS(Olim_bolalar!$B$5:$B$104,">="&Boshqaruv!$C$9,Olim_bolalar!$B$5:$B$104,"<="&Boshqaruv!$C$10,Olim_bolalar!$I$5:$I$104,"Ha")) -> 0 | G29: AVTOMATIK: «Olim_bolalar»: 0–17 yosh. / АВТОМАТИЧЕСКИ: «Olim_bolalar»: 0–17 лет. [Asos: 363-son buyruq (2020), tibbiy hisob shakllari]
A30: 14 | B30: [Voyaga yetmaganlar] Profilaktik ko‘rikdan o‘tgan bolalar va o‘smirlar | C30: [Несовершеннолетние] Прошли профилактический осмотр дети и подростки | D30: nafar | E30: 3 | F30: =IF(OR(Boshqaruv!$C$9="",Boshqaruv!$C$10=""),"",COUNTIFS(Profilaktik_korik!$J$5:$J$2504,1)) -> 0 | G30: AVTOMATIK: «Profilaktik_korik»: ko‘rikdan o‘tgan bolalar (har biri 1 marta). / АВТОМАТИЧЕСКИ: «Profilaktik_korik»: осмотренные дети (каждый 1 раз). [Asos: 3-XS buyrug‘i (2024), BTSY yondashuvlari]
A31: 15 | B31: [Voyaga yetmaganlar] 2–10 yoshli bolalar gelmintoz skriningi | C31: [Несовершеннолетние] Скрининг гельминтозов у детей 2–10 лет | D31: nafar | E31: 3 | F31: =IF(OR(Boshqaruv!$C$9="",Boshqaruv!$C$10=""),"",COUNTIFS(Skrining_bolalar!$B$5:$B$2504,">="&Boshqaruv!$C$9,Skrining_bolalar!$B$5:$B$2504,"<="&Boshqaruv!$C$10,Skrining_bolalar!$J$5:$J$2504,"Gelmintoz",Skrining_bolalar!$K$5:$K$2504,"Ha")) -> 0 | G31: AVTOMATIK: «Skrining_bolalar»: gelmintoz, 2–10 yosh. / АВТОМАТИЧЕСКИ: «Skrining_bolalar»: гельминтозы, 2–10 лет. [Asos: 47-T buyrug‘i (Surxondaryo, 2024), skrining shtabi]
A32: 16 | B32: [Voyaga yetmaganlar] 2–18 yoshli bolalar onkogematologik skriningi | C32: [Несовершеннолетние] Онкогематологический скрининг детей 2–18 лет | D32: nafar | E32: 3 | F32: =IF(OR(Boshqaruv!$C$9="",Boshqaruv!$C$10=""),"",COUNTIFS(Skrining_bolalar!$B$5:$B$2504,">="&Boshqaruv!$C$9,Skrining_bolalar!$B$5:$B$2504,"<="&Boshqaruv!$C$10,Skrining_bolalar!$J$5:$J$2504,"Onkogematologik",Skrining_bolalar!$K$5:$K$2504,"Ha")) -> 0 | G32: AVTOMATIK: «Skrining_bolalar»: onkogematologik, 2–18 yosh. / АВТОМАТИЧЕСКИ: «Skrining_bolalar»: онкогематологический, 2–18 лет. [Asos: 47-T buyrug‘i (Surxondaryo, 2024), skrining shtabi]
A34: TEKSHIRUV / ПРОВЕРКА MA’LUMOT SIFATI
B35: Tekshiruv | C35: Проверка | D35: Soni | F35: Holat | G35: Nima qilish kerak / Что делать
B36: Tug‘ilgan sanasi yo‘q — Bolalar | C36: Нет даты рождения — Bolalar | D36: =COUNTIFS(Bolalar!$B$5:$B$1804,"<>",Bolalar!$C$5:$C$1804,"") -> 0 | F36: =IF(N(D36)=0,"✔ OK",IF("err"="err","✖ XATO / ОШИБКА","⚠ DIQQAT / ВНИМАНИЕ")) -> ✔ OK | G36: Sanani kiriting / Введите дату
B37: Dispanser = Ha, lekin diagnoz yo‘q | C37: Диспансер = Ha, но нет диагноза | D37: =COUNTIFS(Bolalar!$P$5:$P$1804,"Ha",Bolalar!$Q$5:$Q$1804,"") -> 0 | F37: =IF(N(D37)=0,"✔ OK",IF("err"="err","✖ XATO / ОШИБКА","⚠ DIQQAT / ВНИМАНИЕ")) -> ✔ OK | G37: Diagnozni hujjat bo‘yicha yozing / Впишите диагноз по документу
B38: Takror yozuvlar — Bolalar | C38: Дубли — Bolalar | D38: =COUNTIF(Bolalar!$W$5:$W$1804,"Takror") -> 0 | F38: =IF(N(D38)=0,"✔ OK",IF("err"="err","✖ XATO / ОШИБКА","⚠ DIQQAT / ВНИМАНИЕ")) -> ✔ OK | G38: Qizil qatorni toping va takrorni o‘chiring / Найдите красные строки и удалите дубль
B39: Sanasi yo‘q yozuvlar — Kasallanish | C39: Записи без даты — Kasallanish | D39: =COUNTIFS(Kasallanish!$C$5:$C$2504,"<>",Kasallanish!$B$5:$B$2504,"") -> 0 | F39: =IF(N(D39)=0,"✔ OK",IF("err"="err","✖ XATO / ОШИБКА","⚠ DIQQAT / ВНИМАНИЕ")) -> ✔ OK | G39: Sanani kiriting / Введите дату
B40: Sanasi yo‘q yozuvlar — Olim_bolalar | C40: Записи без даты | D40: =COUNTIFS(Olim_bolalar!$C$5:$C$104,"<>",Olim_bolalar!$B$5:$B$104,"") -> 0 | F40: =IF(N(D40)=0,"✔ OK",IF("err"="err","✖ XATO / ОШИБКА","⚠ DIQQAT / ВНИМАНИЕ")) -> ✔ OK | G40: Sanani kiriting / Введите дату
B41: Muddatida patronaj qilinmagan chaqaloqlar | C41: Новорождённые без патронажа в срок | D41: =COUNTIF(Yangi_tugilgan!$L$5:$L$604,"Ha") -> 0 | F41: =IF(N(D41)=0,"✔ OK",IF("warn"="err","✖ XATO / ОШИБКА","⚠ DIQQAT / ВНИМАНИЕ")) -> ✔ OK | G41: Qizil qatorlar: tezda tashrif / Красные строки: срочно посетить
B42: Chiqish sanasi yo‘q — Yangi_tugilgan | C42: Нет даты выписки | D42: =COUNTIFS(Yangi_tugilgan!$B$5:$B$604,"<>",Yangi_tugilgan!$H$5:$H$604,"") -> 0 | F42: =IF(N(D42)=0,"✔ OK",IF("warn"="err","✖ XATO / ОШИБКА","⚠ DIQQAT / ВНИМАНИЕ")) -> ✔ OK | G42: Sanani kiriting / Введите дату
B43: Takror yozuvlar — Yangi_tugilgan | C43: Дубли — Yangi_tugilgan | D43: =COUNTIF(Yangi_tugilgan!$N$5:$N$604,"Takror") -> 0 | F43: =IF(N(D43)=0,"✔ OK",IF("err"="err","✖ XATO / ОШИБКА","⚠ DIQQAT / ВНИМАНИЕ")) -> ✔ OK | G43: Qizil qatorni toping va takrorni o‘chiring / Найдите красные строки и удалите дубль
...

Sheet Bolalar
A1: BOLALAR RO‘YXATI / СПИСОК ДЕТЕЙ УЧАСТКА (pediatr)
A2: Uchastkadagi har bir bola bir marta yoziladi. Dispanser va sog‘lomlashtirish ham shu yerda. / Каждый ребёнок участка вносится один раз. Диспансер и оздоровление — здесь же.
A3: MAXFIY / КОНФИДЕНЦИАЛЬНО — shaxsiy va tibbiy ma’lumotlar (shifokorlik siri). Faylni parol bilan himoyalang, ochiq guruhlarga yubormang. / Персональные и медицинские данные (врачебная тайна). Защитите файл паролем, не отправляйте в открытые группы.
A4: № | B4: Bola F.I.Sh. Ф.И.О. ребёнка | C4: Tug‘ilgan sana Дата рождения | D4: PINFL (14 raqam) ПИНФЛ (14 цифр) | E4: Jinsi Пол | F4: Ona / vakil F.I.Sh. Мать / представитель | G4: Telefon Телефон | H4: Mahalla Махалля | I4: Yorliq (avto) — boshqa varaqlarda tanlanadi Метка (авто) | J4: Yosh (avto, davr oxiriga) Возраст (на конец периода) | K4: 0–14 yosh? (avto) 0–14 лет? | L4: Kuzatuvga olingan sana (ixtiyoriy) Дата взятия под наблюдение (необяз.) | M4: Chiqish sanasi (ko‘chdi / vafot) Дата выбытия | N4: Hisobda? (avto) На учёте? (авто) | O4: Sog‘lomlik guruhi Группа здоровья | P4: Dispanser hisobidami? На диспансерном учёте? | Q4: Dispanser diagnozi (hujjat bo‘yicha) Диагноз диспансерного учёта (по документам) | R4: Dispanserga olingan sana Дата взятия на диспансер | S4: Dispanserdan chiqarilgan sana Дата снятия с диспансера | T4: Dispanser hisobida (avto) На диспансере (авто) | U4: Sog‘lomlashtirilgan sana Дата оздоровления | V4: Izoh Примечание | W4: Takror? (avto) Дубль?
A5: 1 | B5: Детский Тест 0 Иванович | C5: 45296 | D5: 31000000000000 | E5: +998910000000 | I5: =IF(OR($B5="",$C5=""),"",$B5&" ("&DAY($C5)&"."&MONTH($C5)&"."&YEAR($C5)&")") -> Детский Тест 0 Иванович (5.1.2024) | J5: =IF($C5="","",INT((Boshqaruv!$C$12-$C5)/365.25)) -> 2 | K5: =IF($J5="","",IF($J5<=14,"Ha","Yo'q")) -> Ha | N5: =IF($B5="","",IF(AND(OR($L5="",$L5<=Boshqaruv!$C$12),OR($M5="",$M5>Boshqaruv!$C$12)),"Ha","")) -> Ha | T5: =IF($B5="","",IF(AND($P5="Ha",$N5="Ha",OR($R5="",$R5<=Boshqaruv!$C$12),OR($S5="",$S5>Boshqaruv!$C$12)),"Ha","")) | W5: =IF(OR($B5="",$C5=""),"",IF(COUNTIFS($B$5:$B$1804,$B5,$C$5:$C$1804,$C5)>1,"Takror",""))
A6: 2 | B6: Детский Тест 1 Иванович | C6: 45327 | D6: 31000000000001 | E6: +998910000001 | I6: =IF(OR($B6="",$C6=""),"",$B6&" ("&DAY($C6)&"."&MONTH($C6)&"."&YEAR($C6)&")") -> Детский Тест 1 Иванович (5.2.2024) | J6: =IF($C6="","",INT((Boshqaruv!$C$12-$C6)/365.25)) -> 2 | K6: =IF($J6="","",IF($J6<=14,"Ha","Yo'q")) -> Ha | N6: =IF($B6="","",IF(AND(OR($L6="",$L6<=Boshqaruv!$C$12),OR($M6="",$M6>Boshqaruv!$C$12)),"Ha","")) -> Ha | T6: =IF($B6="","",IF(AND($P6="Ha",$N6="Ha",OR($R6="",$R6<=Boshqaruv!$C$12),OR($S6="",$S6>Boshqaruv!$C$12)),"Ha","")) | W6: =IF(OR($B6="",$C6=""),"",IF(COUNTIFS($B$5:$B$1804,$B6,$C$5:$C$1804,$C6)>1,"Takror",""))
A7: 3 | B7: Детский Тест 2 Иванович | C7: 45356 | D7: 31000000000002 | E7: +998910000002 | I7: =IF(OR($B7="",$C7=""),"",$B7&" ("&DAY($C7)&"."&MONTH($C7)&"."&YEAR($C7)&")") -> Детский Тест 2 Иванович (5.3.2024) | J7: =IF($C7="","",INT((Boshqaruv!$C$12-$C7)/365.25)) -> 2 | K7: =IF($J7="","",IF($J7<=14,"Ha","Yo'q")) -> Ha | N7: =IF($B7="","",IF(AND(OR($L7="",$L7<=Boshqaruv!$C$12),OR($M7="",$M7>Boshqaruv!$C$12)),"Ha","")) -> Ha | T7: =IF($B7="","",IF(AND($P7="Ha",$N7="Ha",OR($R7="",$R7<=Boshqaruv!$C$12),OR($S7="",$S7>Boshqaruv!$C$12)),"Ha","")) | W7: =IF(OR($B7="",$C7=""),"",IF(COUNTIFS($B$5:$B$1804,$B7,$C$5:$C$1804,$C7)>1,"Takror",""))
A8: 4 | B8: Детский Тест 3 Иванович | C8: 45387 | D8: 31000000000003 | E8: +998910000003 | I8: =IF(OR($B8="",$C8=""),"",$B8&" ("&DAY($C8)&"."&MONTH($C8)&"."&YEAR($C8)&")") -> Детский Тест 3 Иванович (5.4.2024) | J8: =IF($C8="","",INT((Boshqaruv!$C$12-$C8)/365.25)) -> 2 | K8: =IF($J8="","",IF($J8<=14,"Ha","Yo'q")) -> Ha | N8: =IF($B8="","",IF(AND(OR($L8="",$L8<=Boshqaruv!$C$12),OR($M8="",$M8>Boshqaruv!$C$12)),"Ha","")) -> Ha | T8: =IF($B8="","",IF(AND($P8="Ha",$N8="Ha",OR($R8="",$R8<=Boshqaruv!$C$12),OR($S8="",$S8>Boshqaruv!$C$12)),"Ha","")) | W8: =IF(OR($B8="",$C8=""),"",IF(COUNTIFS($B$5:$B$1804,$B8,$C$5:$C$1804,$C8)>1,"Takror",""))
A9: 5 | B9: Детский Тест 4 Иванович | C9: 45417 | D9: 31000000000004 | E9: +998910000004 | I9: =IF(OR($B9="",$C9=""),"",$B9&" ("&DAY($C9)&"."&MONTH($C9)&"."&YEAR($C9)&")") -> Детский Тест 4 Иванович (5.5.2024) | J9: =IF($C9="","",INT((Boshqaruv!$C$12-$C9)/365.25)) -> 2 | K9: =IF($J9="","",IF($J9<=14,"Ha","Yo'q")) -> Ha | N9: =IF($B9="","",IF(AND(OR($L9="",$L9<=Boshqaruv!$C$12),OR($M9="",$M9>Boshqaruv!$C$12)),"Ha","")) -> Ha | T9: =IF($B9="","",IF(AND($P9="Ha",$N9="Ha",OR($R9="",$R9<=Boshqaruv!$C$12),OR($S9="",$S9>Boshqaruv!$C$12)),"Ha","")) | W9: =IF(OR($B9="",$C9=""),"",IF(COUNTIFS($B$5:$B$1804,$B9,$C$5:$C$1804,$C9)>1,"Takror",""))
A10: 6 | B10: Детский Тест 5 Иванович | C10: 45448 | D10: 31000000000005 | E10: +998910000005 | I10: =IF(OR($B10="",$C10=""),"",$B10&" ("&DAY($C10)&"."&MONTH($C10)&"."&YEAR($C10)&")") -> Детский Тест 5 Иванович (5.6.2024) | J10: =IF($C10="","",INT((Boshqaruv!$C$12-$C10)/365.25)) -> 2 | K10: =IF($J10="","",IF($J10<=14,"Ha","Yo'q")) -> Ha | N10: =IF($B10="","",IF(AND(OR($L10="",$L10<=Boshqaruv!$C$12),OR($M10="",$M10>Boshqaruv!$C$12)),"Ha","")) -> Ha | T10: =IF($B10="","",IF(AND($P10="Ha",$N10="Ha",OR($R10="",$R10<=Boshqaruv!$C$12),OR($S10="",$S10>Boshqaruv!$C$12)),"Ha","")) | W10: =IF(OR($B10="",$C10=""),"",IF(COUNTIFS($B$5:$B$1804,$B10,$C$5:$C$1804,$C10)>1,"Takror",""))
A11: 7 | I11: =IF(OR($B11="",$C11=""),"",$B11&" ("&DAY($C11)&"."&MONTH($C11)&"."&YEAR($C11)&")") | J11: =IF($C11="","",INT((Boshqaruv!$C$12-$C11)/365.25)) | K11: =IF($J11="","",IF($J11<=14,"Ha","Yo'q")) | N11: =IF($B11="","",IF(AND(OR($L11="",$L11<=Boshqaruv!$C$12),OR($M11="",$M11>Boshqaruv!$C$12)),"Ha","")) | T11: =IF($B11="","",IF(AND($P11="Ha",$N11="Ha",OR($R11="",$R11<=Boshqaruv!$C$12),OR($S11="",$S11>Boshqaruv!$C$12)),"Ha","")) | W11: =IF(OR($B11="",$C11=""),"",IF(COUNTIFS($B$5:$B$1804,$B11,$C$5:$C$1804,$C11)>1,"Takror",""))
A12: 8 | I12: =IF(OR($B12="",$C12=""),"",$B12&" ("&DAY($C12)&"."&MONTH($C12)&"."&YEAR($C12)&")") | J12: =IF($C12="","",INT((Boshqaruv!$C$12-$C12)/365.25)) | K12: =IF($J12="","",IF($J12<=14,"Ha","Yo'q")) | N12: =IF($B12="","",IF(AND(OR($L12="",$L12<=Boshqaruv!$C$12),OR($M12="",$M12>Boshqaruv!$C$12)),"Ha","")) | T12: =IF($B12="","",IF(AND($P12="Ha",$N12="Ha",OR($R12="",$R12<=Boshqaruv!$C$12),OR($S12="",$S12>Boshqaruv!$C$12)),"Ha","")) | W12: =IF(OR($B12="",$C12=""),"",IF(COUNTIFS($B$5:$B$1804,$B12,$C$5:$C$1804,$C12)>1,"Takror",""))
A13: 9 | I13: =IF(OR($B13="",$C13=""),"",$B13&" ("&DAY($C13)&"."&MONTH($C13)&"."&YEAR($C13)&")") | J13: =IF($C13="","",INT((Boshqaruv!$C$12-$C13)/365.25)) | K13: =IF($J13="","",IF($J13<=14,"Ha","Yo'q")) | N13: =IF($B13="","",IF(AND(OR($L13="",$L13<=Boshqaruv!$C$12),OR($M13="",$M13>Boshqaruv!$C$12)),"Ha","")) | T13: =IF($B13="","",IF(AND($P13="Ha",$N13="Ha",OR($R13="",$R13<=Boshqaruv!$C$12),OR($S13="",$S13>Boshqaruv!$C$12)),"Ha","")) | W13: =IF(OR($B13="",$C13=""),"",IF(COUNTIFS($B$5:$B$1804,$B13,$C$5:$C$1804,$C13)>1,"Takror",""))
A14: 10 | I14: =IF(OR($B14="",$C14=""),"",$B14&" ("&DAY($C14)&"."&MONTH($C14)&"."&YEAR($C14)&")") | J14: =IF($C14="","",INT((Boshqaruv!$C$12-$C14)/365.25)) | K14: =IF($J14="","",IF($J14<=14,"Ha","Yo'q")) | N14: =IF($B14="","",IF(AND(OR($L14="",$L14<=Boshqaruv!$C$12),OR($M14="",$M14>Boshqaruv!$C$12)),"Ha","")) | T14: =IF($B14="","",IF(AND($P14="Ha",$N14="Ha",OR($R14="",$R14<=Boshqaruv!$C$12),OR($S14="",$S14>Boshqaruv!$C$12)),"Ha","")) | W14: =IF(OR($B14="",$C14=""),"",IF(COUNTIFS($B$5:$B$1804,$B14,$C$5:$C$1804,$C14)>1,"Takror",""))
A15: 11 | I15: =IF(OR($B15="",$C15=""),"",$B15&" ("&DAY($C15)&"."&MONTH($C15)&"."&YEAR($C15)&")") | J15: =IF($C15="","",INT((Boshqaruv!$C$12-$C15)/365.25)) | K15: =IF($J15="","",IF($J15<=14,"Ha","Yo'q")) | N15: =IF($B15="","",IF(AND(OR($L15="",$L15<=Boshqaruv!$C$12),OR($M15="",$M15>Boshqaruv!$C$12)),"Ha","")) | T15: =IF($B15="","",IF(AND($P15="Ha",$N15="Ha",OR($R15="",$R15<=Boshqaruv!$C$12),OR($S15="",$S15>Boshqaruv!$C$12)),"Ha","")) | W15: =IF(OR($B15="",$C15=""),"",IF(COUNTIFS($B$5:$B$1804,$B15,$C$5:$C$1804,$C15)>1,"Takror",""))
A16: 12 | I16: =IF(OR($B16="",$C16=""),"",$B16&" ("&DAY($C16)&"."&MONTH($C16)&"."&YEAR($C16)&")") | J16: =IF($C16="","",INT((Boshqaruv!$C$12-$C16)/365.25)) | K16: =IF($J16="","",IF($J16<=14,"Ha","Yo'q")) | N16: =IF($B16="","",IF(AND(OR($L16="",$L16<=Boshqaruv!$C$12),OR($M16="",$M16>Boshqaruv!$C$12)),"Ha","")) | T16: =IF($B16="","",IF(AND($P16="Ha",$N16="Ha",OR($R16="",$R16<=Boshqaruv!$C$12),OR($S16="",$S16>Boshqaruv!$C$12)),"Ha","")) | W16: =IF(OR($B16="",$C16=""),"",IF(COUNTIFS($B$5:$B$1804,$B16,$C$5:$C$1804,$C16)>1,"Takror",""))
A17: 13 | I17: =IF(OR($B17="",$C17=""),"",$B17&" ("&DAY($C17)&"."&MONTH($C17)&"."&YEAR($C17)&")") | J17: =IF($C17="","",INT((Boshqaruv!$C$12-$C17)/365.25)) | K17: =IF($J17="","",IF($J17<=14,"Ha","Yo'q")) | N17: =IF($B17="","",IF(AND(OR($L17="",$L17<=Boshqaruv!$C$12),OR($M17="",$M17>Boshqaruv!$C$12)),"Ha","")) | T17: =IF($B17="","",IF(AND($P17="Ha",$N17="Ha",OR($R17="",$R17<=Boshqaruv!$C$12),OR($S17="",$S17>Boshqaruv!$C$12)),"Ha","")) | W17: =IF(OR($B17="",$C17=""),"",IF(COUNTIFS($B$5:$B$1804,$B17,$C$5:$C$1804,$C17)>1,"Takror",""))
A18: 14 | I18: =IF(OR($B18="",$C18=""),"",$B18&" ("&DAY($C18)&"."&MONTH($C18)&"."&YEAR($C18)&")") | J18: =IF($C18="","",INT((Boshqaruv!$C$12-$C18)/365.25)) | K18: =IF($J18="","",IF($J18<=14,"Ha","Yo'q")) | N18: =IF($B18="","",IF(AND(OR($L18="",$L18<=Boshqaruv!$C$12),OR($M18="",$M18>Boshqaruv!$C$12)),"Ha","")) | T18: =IF($B18="","",IF(AND($P18="Ha",$N18="Ha",OR($R18="",$R18<=Boshqaruv!$C$12),OR($S18="",$S18>Boshqaruv!$C$12)),"Ha","")) | W18: =IF(OR($B18="",$C18=""),"",IF(COUNTIFS($B$5:$B$1804,$B18,$C$5:$C$1804,$C18)>1,"Takror",""))
A19: 15 | I19: =IF(OR($B19="",$C19=""),"",$B19&" ("&DAY($C19)&"."&MONTH($C19)&"."&YEAR($C19)&")") | J19: =IF($C19="","",INT((Boshqaruv!$C$12-$C19)/365.25)) | K19: =IF($J19="","",IF($J19<=14,"Ha","Yo'q")) | N19: =IF($B19="","",IF(AND(OR($L19="",$L19<=Boshqaruv!$C$12),OR($M19="",$M19>Boshqaruv!$C$12)),"Ha","")) | T19: =IF($B19="","",IF(AND($P19="Ha",$N19="Ha",OR($R19="",$R19<=Boshqaruv!$C$12),OR($S19="",$S19>Boshqaruv!$C$12)),"Ha","")) | W19: =IF(OR($B19="",$C19=""),"",IF(COUNTIFS($B$5:$B$1804,$B19,$C$5:$C$1804,$C19)>1,"Takror",""))
A20: 16 | I20: =IF(OR($B20="",$C20=""),"",$B20&" ("&DAY($C20)&"."&MONTH($C20)&"."&YEAR($C20)&")") | J20: =IF($C20="","",INT((Boshqaruv!$C$12-$C20)/365.25)) | K20: =IF($J20="","",IF($J20<=14,"Ha","Yo'q")) | N20: =IF($B20="","",IF(AND(OR($L20="",$L20<=Boshqaruv!$C$12),OR($M20="",$M20>Boshqaruv!$C$12)),"Ha","")) | T20: =IF($B20="","",IF(AND($P20="Ha",$N20="Ha",OR($R20="",$R20<=Boshqaruv!$C$12),OR($S20="",$S20>Boshqaruv!$C$12)),"Ha","")) | W20: =IF(OR($B20="",$C20=""),"",IF(COUNTIFS($B$5:$B$1804,$B20,$C$5:$C$1804,$C20)>1,"Takror",""))
A21: 17 | I21: =IF(OR($B21="",$C21=""),"",$B21&" ("&DAY($C21)&"."&MONTH($C21)&"."&YEAR($C21)&")") | J21: =IF($C21="","",INT((Boshqaruv!$C$12-$C21)/365.25)) | K21: =IF($J21="","",IF($J21<=14,"Ha","Yo'q")) | N21: =IF($B21="","",IF(AND(OR($L21="",$L21<=Boshqaruv!$C$12),OR($M21="",$M21>Boshqaruv!$C$12)),"Ha","")) | T21: =IF($B21="","",IF(AND($P21="Ha",$N21="Ha",OR($R21="",$R21<=Boshqaruv!$C$12),OR($S21="",$S21>Boshqaruv!$C$12)),"Ha","")) | W21: =IF(OR($B21="",$C21=""),"",IF(COUNTIFS($B$5:$B$1804,$B21,$C$5:$C$1804,$C21)>1,"Takror",""))
A22: 18 | I22: =IF(OR($B22="",$C22=""),"",$B22&" ("&DAY($C22)&"."&MONTH($C22)&"."&YEAR($C22)&")") | J22: =IF($C22="","",INT((Boshqaruv!$C$12-$C22)/365.25)) | K22: =IF($J22="","",IF($J22<=14,"Ha","Yo'q")) | N22: =IF($B22="","",IF(AND(OR($L22="",$L22<=Boshqaruv!$C$12),OR($M22="",$M22>Boshqaruv!$C$12)),"Ha","")) | T22: =IF($B22="","",IF(AND($P22="Ha",$N22="Ha",OR($R22="",$R22<=Boshqaruv!$C$12),OR($S22="",$S22>Boshqaruv!$C$12)),"Ha","")) | W22: =IF(OR($B22="",$C22=""),"",IF(COUNTIFS($B$5:$B$1804,$B22,$C$5:$C$1804,$C22)>1,"Takror",""))
... A1804: 1800 | I1804: =IF(OR($B1804="",$C1804=""),"",$B1804&" ("&DAY($C1804)&"."&MONTH($C1804)&"."&YEAR($C1804)&")") | J1804: =IF($C1804="","",INT((Boshqaruv!$C$12-$C1804)/365.25)) | K1804: =IF($J1804="","",IF($J1804<=14,"Ha","Yo'q")) | N1804: =IF($B1804="","",IF(AND(OR($L1804="",$L1804<=Boshqaruv!$C$12),OR($M1804="",$M1804>Boshqaruv!$C$12)),"Ha","")) | T1804: =IF($B1804="","",IF(AND($P1804="Ha",$N1804="Ha",OR($R1804="",$R1804<=Boshqaruv!$C$12),OR($S1804="",$S1804>Boshqaruv!$C$12)),"Ha","")) | W1804: =IF(OR($B1804="",$C1804=""),"",IF(COUNTIFS($B$5:$B$1804,$B1804,$C$5:$C$1804,$C1804)>1,"Takror",""))

Sheet Kasallanish
A1: KASALLANISH JURNALI / ЖУРНАЛ ЗАБОЛЕВАЕМОСТИ (bolalar)
A2: Har bir kasallanish — bitta qator; bola «Bolalar» ro‘yxatidan tanlanadi. / Каждый случай — одна строка; ребёнок выбирается из «Bolalar».
A3: MAXFIY / КОНФИДЕНЦИАЛЬНО — shaxsiy va tibbiy ma’lumotlar (shifokorlik siri). Faylni parol bilan himoyalang, ochiq guruhlarga yubormang. / Персональные и медицинские данные (врачебная тайна). Защитите файл паролем, не отправляйте в открытые группы.
A4: № | B4: Sana Дата | C4: Shaxs (ro‘yxatdan tanlang) Человек (выбрать из списка) | D4: Bola F.I.Sh. (avto) Ф.И.О. (авто) | E4: Tug‘ilgan sana (avto) Дата рожд. (авто) | F4: PINFL (14 raqam) ПИНФЛ (14 цифр) | G4: Yosh (avto) Возраст | H4: 5 yoshgacha? (avto) До 5 лет? | I4: 0–17 yosh? (avto) 0–17 лет? | J4: Diagnoz (hujjat bo‘yicha) Диагноз (по документам) | K4: MKB-10 МКБ-10 | L4: Statsionarga yotqizildimi? Госпитализирован? | M4: Izoh Примечание
A5: 1 | D5: =IF($C5="","",IFERROR(IF(INDEX(Bolalar!$B$5:$B$1804,MATCH($C5,Bolalar!$I$5:$I$1804,0))="","",INDEX(Bolalar!$B$5:$B$1804,MATCH($C5,Bolalar!$I$5:$I$1804,0))),"")) | E5: =IF($C5="","",IFERROR(IF(INDEX(Bolalar!$C$5:$C$1804,MATCH($C5,Bolalar!$I$5:$I$1804,0))="","",INDEX(Bolalar!$C$5:$C$1804,MATCH($C5,Bolalar!$I$5:$I$1804,0))),"")) | G5: =IF(OR($E5="",$B5=""),"",INT(($B5-$E5)/365.25)) | H5: =IF($G5="","",IF($G5<5,"Ha","Yo'q")) | I5: =IF($G5="","",IF($G5<18,"Ha","Yo'q"))
A6: 2 | D6: =IF($C6="","",IFERROR(IF(INDEX(Bolalar!$B$5:$B$1804,MATCH($C6,Bolalar!$I$5:$I$1804,0))="","",INDEX(Bolalar!$B$5:$B$1804,MATCH($C6,Bolalar!$I$5:$I$1804,0))),"")) | E6: =IF($C6="","",IFERROR(IF(INDEX(Bolalar!$C$5:$C$1804,MATCH($C6,Bolalar!$I$5:$I$1804,0))="","",INDEX(Bolalar!$C$5:$C$1804,MATCH($C6,Bolalar!$I$5:$I$1804,0))),"")) | G6: =IF(OR($E6="",$B6=""),"",INT(($B6-$E6)/365.25)) | H6: =IF($G6="","",IF($G6<5,"Ha","Yo'q")) | I6: =IF($G6="","",IF($G6<18,"Ha","Yo'q"))
A7: 3 | D7: =IF($C7="","",IFERROR(IF(INDEX(Bolalar!$B$5:$B$1804,MATCH($C7,Bolalar!$I$5:$I$1804,0))="","",INDEX(Bolalar!$B$5:$B$1804,MATCH($C7,Bolalar!$I$5:$I$1804,0))),"")) | E7: =IF($C7="","",IFERROR(IF(INDEX(Bolalar!$C$5:$C$1804,MATCH($C7,Bolalar!$I$5:$I$1804,0))="","",INDEX(Bolalar!$C$5:$C$1804,MATCH($C7,Bolalar!$I$5:$I$1804,0))),"")) | G7: =IF(OR($E7="",$B7=""),"",INT(($B7-$E7)/365.25)) | H7: =IF($G7="","",IF($G7<5,"Ha","Yo'q")) | I7: =IF($G7="","",IF($G7<18,"Ha","Yo'q"))
A8: 4 | D8: =IF($C8="","",IFERROR(IF(INDEX(Bolalar!$B$5:$B$1804,MATCH($C8,Bolalar!$I$5:$I$1804,0))="","",INDEX(Bolalar!$B$5:$B$1804,MATCH($C8,Bolalar!$I$5:$I$1804,0))),"")) | E8: =IF($C8="","",IFERROR(IF(INDEX(Bolalar!$C$5:$C$1804,MATCH($C8,Bolalar!$I$5:$I$1804,0))="","",INDEX(Bolalar!$C$5:$C$1804,MATCH($C8,Bolalar!$I$5:$I$1804,0))),"")) | G8: =IF(OR($E8="",$B8=""),"",INT(($B8-$E8)/365.25)) | H8: =IF($G8="","",IF($G8<5,"Ha","Yo'q")) | I8: =IF($G8="","",IF($G8<18,"Ha","Yo'q"))
A9: 5 | D9: =IF($C9="","",IFERROR(IF(INDEX(Bolalar!$B$5:$B$1804,MATCH($C9,Bolalar!$I$5:$I$1804,0))="","",INDEX(Bolalar!$B$5:$B$1804,MATCH($C9,Bolalar!$I$5:$I$1804,0))),"")) | E9: =IF($C9="","",IFERROR(IF(INDEX(Bolalar!$C$5:$C$1804,MATCH($C9,Bolalar!$I$5:$I$1804,0))="","",INDEX(Bolalar!$C$5:$C$1804,MATCH($C9,Bolalar!$I$5:$I$1804,0))),"")) | G9: =IF(OR($E9="",$B9=""),"",INT(($B9-$E9)/365.25)) | H9: =IF($G9="","",IF($G9<5,"Ha","Yo'q")) | I9: =IF($G9="","",IF($G9<18,"Ha","Yo'q"))
A10: 6 | D10: =IF($C10="","",IFERROR(IF(INDEX(Bolalar!$B$5:$B$1804,MATCH($C10,Bolalar!$I$5:$I$1804,0))="","",INDEX(Bolalar!$B$5:$B$1804,MATCH($C10,Bolalar!$I$5:$I$1804,0))),"")) | E10: =IF($C10="","",IFERROR(IF(INDEX(Bolalar!$C$5:$C$1804,MATCH($C10,Bolalar!$I$5:$I$1804,0))="","",INDEX(Bolalar!$C$5:$C$1804,MATCH($C10,Bolalar!$I$5:$I$1804,0))),"")) | G10: =IF(OR($E10="",$B10=""),"",INT(($B10-$E10)/365.25)) | H10: =IF($G10="","",IF($G10<5,"Ha","Yo'q")) | I10: =IF($G10="","",IF($G10<18,"Ha","Yo'q"))
A11: 7 | D11: =IF($C11="","",IFERROR(IF(INDEX(Bolalar!$B$5:$B$1804,MATCH($C11,Bolalar!$I$5:$I$1804,0))="","",INDEX(Bolalar!$B$5:$B$1804,MATCH($C11,Bolalar!$I$5:$I$1804,0))),"")) | E11: =IF($C11="","",IFERROR(IF(INDEX(Bolalar!$C$5:$C$1804,MATCH($C11,Bolalar!$I$5:$I$1804,0))="","",INDEX(Bolalar!$C$5:$C$1804,MATCH($C11,Bolalar!$I$5:$I$1804,0))),"")) | G11: =IF(OR($E11="",$B11=""),"",INT(($B11-$E11)/365.25)) | H11: =IF($G11="","",IF($G11<5,"Ha","Yo'q")) | I11: =IF($G11="","",IF($G11<18,"Ha","Yo'q"))
A12: 8 | D12: =IF($C12="","",IFERROR(IF(INDEX(Bolalar!$B$5:$B$1804,MATCH($C12,Bolalar!$I$5:$I$1804,0))="","",INDEX(Bolalar!$B$5:$B$1804,MATCH($C12,Bolalar!$I$5:$I$1804,0))),"")) | E12: =IF($C12="","",IFERROR(IF(INDEX(Bolalar!$C$5:$C$1804,MATCH($C12,Bolalar!$I$5:$I$1804,0))="","",INDEX(Bolalar!$C$5:$C$1804,MATCH($C12,Bolalar!$I$5:$I$1804,0))),"")) | G12: =IF(OR($E12="",$B12=""),"",INT(($B12-$E12)/365.25)) | H12: =IF($G12="","",IF($G12<5,"Ha","Yo'q")) | I12: =IF($G12="","",IF($G12<18,"Ha","Yo'q"))
A13: 9 | D13: =IF($C13="","",IFERROR(IF(INDEX(Bolalar!$B$5:$B$1804,MATCH($C13,Bolalar!$I$5:$I$1804,0))="","",INDEX(Bolalar!$B$5:$B$1804,MATCH($C13,Bolalar!$I$5:$I$1804,0))),"")) | E13: =IF($C13="","",IFERROR(IF(INDEX(Bolalar!$C$5:$C$1804,MATCH($C13,Bolalar!$I$5:$I$1804,0))="","",INDEX(Bolalar!$C$5:$C$1804,MATCH($C13,Bolalar!$I$5:$I$1804,0))),"")) | G13: =IF(OR($E13="",$B13=""),"",INT(($B13-$E13)/365.25)) | H13: =IF($G13="","",IF($G13<5,"Ha","Yo'q")) | I13: =IF($G13="","",IF($G13<18,"Ha","Yo'q"))
A14: 10 | D14: =IF($C14="","",IFERROR(IF(INDEX(Bolalar!$B$5:$B$1804,MATCH($C14,Bolalar!$I$5:$I$1804,0))="","",INDEX(Bolalar!$B$5:$B$1804,MATCH($C14,Bolalar!$I$5:$I$1804,0))),"")) | E14: =IF($C14="","",IFERROR(IF(INDEX(Bolalar!$C$5:$C$1804,MATCH($C14,Bolalar!$I$5:$I$1804,0))="","",INDEX(Bolalar!$C$5:$C$1804,MATCH($C14,Bolalar!$I$5:$I$1804,0))),"")) | G14: =IF(OR($E14="",$B14=""),"",INT(($B14-$E14)/365.25)) | H14: =IF($G14="","",IF($G14<5,"Ha","Yo'q")) | I14: =IF($G14="","",IF($G14<18,"Ha","Yo'q"))
A15: 11 | D15: =IF($C15="","",IFERROR(IF(INDEX(Bolalar!$B$5:$B$1804,MATCH($C15,Bolalar!$I$5:$I$1804,0))="","",INDEX(Bolalar!$B$5:$B$1804,MATCH($C15,Bolalar!$I$5:$I$1804,0))),"")) | E15: =IF($C15="","",IFERROR(IF(INDEX(Bolalar!$C$5:$C$1804,MATCH($C15,Bolalar!$I$5:$I$1804,0))="","",INDEX(Bolalar!$C$5:$C$1804,MATCH($C15,Bolalar!$I$5:$I$1804,0))),"")) | G15: =IF(OR($E15="",$B15=""),"",INT(($B15-$E15)/365.25)) | H15: =IF($G15="","",IF($G15<5,"Ha","Yo'q")) | I15: =IF($G15="","",IF($G15<18,"Ha","Yo'q"))
A16: 12 | D16: =IF($C16="","",IFERROR(IF(INDEX(Bolalar!$B$5:$B$1804,MATCH($C16,Bolalar!$I$5:$I$1804,0))="","",INDEX(Bolalar!$B$5:$B$1804,MATCH($C16,Bolalar!$I$5:$I$1804,0))),"")) | E16: =IF($C16="","",IFERROR(IF(INDEX(Bolalar!$C$5:$C$1804,MATCH($C16,Bolalar!$I$5:$I$1804,0))="","",INDEX(Bolalar!$C$5:$C$1804,MATCH($C16,Bolalar!$I$5:$I$1804,0))),"")) | G16: =IF(OR($E16="",$B16=""),"",INT(($B16-$E16)/365.25)) | H16: =IF($G16="","",IF($G16<5,"Ha","Yo'q")) | I16: =IF($G16="","",IF($G16<18,"Ha","Yo'q"))
... A2504: 2500 | D2504: =IF($C2504="","",IFERROR(IF(INDEX(Bolalar!$B$5:$B$1804,MATCH($C2504,Bolalar!$I$5:$I$1804,0))="","",INDEX(Bolalar!$B$5:$B$1804,MATCH($C2504,Bolalar!$I$5:$I$1804,0))),"")) | E2504: =IF($C2504="","",IFERROR(IF(INDEX(Bolalar!$C$5:$C$1804,MATCH($C2504,Bolalar!$I$5:$I$1804,0))="","",INDEX(Bolalar!$C$5:$C$1804,MATCH($C2504,Bolalar!$I$5:$I$1804,0))),"")) | G2504: =IF(OR($E2504="",$B2504=""),"",INT(($B2504-$E2504)/365.25)) | H2504: =IF($G2504="","",IF($G2504<5,"Ha","Yo'q")) | I2504: =IF($G2504="","",IF($G2504<18,"Ha","Yo'q"))

Sheet Olim_bolalar
A1: BOLALAR O‘LIMI / СМЕРТНОСТЬ ДЕТЕЙ
A2: Har bir holat — bitta qator; bola «Bolalar» ro‘yxatidan tanlanadi. Sababi hujjat bo‘yicha. / Каждый случай — одна строка; причина — по документу.
A3: MAXFIY / КОНФИДЕНЦИАЛЬНО — shaxsiy va tibbiy ma’lumotlar (shifokorlik siri). Faylni parol bilan himoyalang, ochiq guruhlarga yubormang. / Персональные и медицинские данные (врачебная тайна). Защитите файл паролем, не отправляйте в открытые группы.
A4: № | B4: O‘lim sanasi Дата смерти | C4: Shaxs (ro‘yxatdan tanlang) Человек (выбрать из списка) | D4: Bola F.I.Sh. (avto) Ф.И.О. (авто) | E4: Tug‘ilgan sana (avto) Дата рожд. (авто) | F4: PINFL (14 raqam) ПИНФЛ (14 цифр) | G4: Yosh (avto) Возраст | H4: 5 yoshgacha? (avto) До 5 лет? | I4: 0–17 yosh? (avto) 0–17 лет? | J4: Sabab (hujjat bo‘yicha) Причина (по документу) | K4: Guvohnoma / hujjat № № свидетельства / документа | L4: Izoh Примечание
A5: 1 | D5: =IF($C5="","",IFERROR(IF(INDEX(Bolalar!$B$5:$B$1804,MATCH($C5,Bolalar!$I$5:$I$1804,0))="","",INDEX(Bolalar!$B$5:$B$1804,MATCH($C5,Bolalar!$I$5:$I$1804,0))),"")) | E5: =IF($C5="","",IFERROR(IF(INDEX(Bolalar!$C$5:$C$1804,MATCH($C5,Bolalar!$I$5:$I$1804,0))="","",INDEX(Bolalar!$C$5:$C$1804,MATCH($C5,Bolalar!$I$5:$I$1804,0))),"")) | G5: =IF(OR($E5="",$B5=""),"",INT(($B5-$E5)/365.25)) | H5: =IF($G5="","",IF($G5<5,"Ha","Yo'q")) | I5: =IF($G5="","",IF($G5<18,"Ha","Yo'q"))
A6: 2 | D6: =IF($C6="","",IFERROR(IF(INDEX(Bolalar!$B$5:$B$1804,MATCH($C6,Bolalar!$I$5:$I$1804,0))="","",INDEX(Bolalar!$B$5:$B$1804,MATCH($C6,Bolalar!$I$5:$I$1804,0))),"")) | E6: =IF($C6="","",IFERROR(IF(INDEX(Bolalar!$C$5:$C$1804,MATCH($C6,Bolalar!$I$5:$I$1804,0))="","",INDEX(Bolalar!$C$5:$C$1804,MATCH($C6,Bolalar!$I$5:$I$1804,0))),"")) | G6: =IF(OR($E6="",$B6=""),"",INT(($B6-$E6)/365.25)) | H6: =IF($G6="","",IF($G6<5,"Ha","Yo'q")) | I6: =IF($G6="","",IF($G6<18,"Ha","Yo'q"))
A7: 3 | D7: =IF($C7="","",IFERROR(IF(INDEX(Bolalar!$B$5:$B$1804,MATCH($C7,Bolalar!$I$5:$I$1804,0))="","",INDEX(Bolalar!$B$5:$B$1804,MATCH($C7,Bolalar!$I$5:$I$1804,0))),"")) | E7: =IF($C7="","",IFERROR(IF(INDEX(Bolalar!$C$5:$C$1804,MATCH($C7,Bolalar!$I$5:$I$1804,0))="","",INDEX(Bolalar!$C$5:$C$1804,MATCH($C7,Bolalar!$I$5:$I$1804,0))),"")) | G7: =IF(OR($E7="",$B7=""),"",INT(($B7-$E7)/365.25)) | H7: =IF($G7="","",IF($G7<5,"Ha","Yo'q")) | I7: =IF($G7="","",IF($G7<18,"Ha","Yo'q"))
A8: 4 | D8: =IF($C8="","",IFERROR(IF(INDEX(Bolalar!$B$5:$B$1804,MATCH($C8,Bolalar!$I$5:$I$1804,0))="","",INDEX(Bolalar!$B$5:$B$1804,MATCH($C8,Bolalar!$I$5:$I$1804,0))),"")) | E8: =IF($C8="","",IFERROR(IF(INDEX(Bolalar!$C$5:$C$1804,MATCH($C8,Bolalar!$I$5:$I$1804,0))="","",INDEX(Bolalar!$C$5:$C$1804,MATCH($C8,Bolalar!$I$5:$I$1804,0))),"")) | G8: =IF(OR($E8="",$B8=""),"",INT(($B8-$E8)/365.25)) | H8: =IF($G8="","",IF($G8<5,"Ha","Yo'q")) | I8: =IF($G8="","",IF($G8<18,"Ha","Yo'q"))
A9: 5 | D9: =IF($C9="","",IFERROR(IF(INDEX(Bolalar!$B$5:$B$1804,MATCH($C9,Bolalar!$I$5:$I$1804,0))="","",INDEX(Bolalar!$B$5:$B$1804,MATCH($C9,Bolalar!$I$5:$I$1804,0))),"")) | E9: =IF($C9="","",IFERROR(IF(INDEX(Bolalar!$C$5:$C$1804,MATCH($C9,Bolalar!$I$5:$I$1804,0))="","",INDEX(Bolalar!$C$5:$C$1804,MATCH($C9,Bolalar!$I$5:$I$1804,0))),"")) | G9: =IF(OR($E9="",$B9=""),"",INT(($B9-$E9)/365.25)) | H9: =IF($G9="","",IF($G9<5,"Ha","Yo'q")) | I9: =IF($G9="","",IF($G9<18,"Ha","Yo'q"))
A10: 6 | D10: =IF($C10="","",IFERROR(IF(INDEX(Bolalar!$B$5:$B$1804,MATCH($C10,Bolalar!$I$5:$I$1804,0))="","",INDEX(Bolalar!$B$5:$B$1804,MATCH($C10,Bolalar!$I$5:$I$1804,0))),"")) | E10: =IF($C10="","",IFERROR(IF(INDEX(Bolalar!$C$5:$C$1804,MATCH($C10,Bolalar!$I$5:$I$1804,0))="","",INDEX(Bolalar!$C$5:$C$1804,MATCH($C10,Bolalar!$I$5:$I$1804,0))),"")) | G10: =IF(OR($E10="",$B10=""),"",INT(($B10-$E10)/365.25)) | H10: =IF($G10="","",IF($G10<5,"Ha","Yo'q")) | I10: =IF($G10="","",IF($G10<18,"Ha","Yo'q"))
A11: 7 | D11: =IF($C11="","",IFERROR(IF(INDEX(Bolalar!$B$5:$B$1804,MATCH($C11,Bolalar!$I$5:$I$1804,0))="","",INDEX(Bolalar!$B$5:$B$1804,MATCH($C11,Bolalar!$I$5:$I$1804,0))),"")) | E11: =IF($C11="","",IFERROR(IF(INDEX(Bolalar!$C$5:$C$1804,MATCH($C11,Bolalar!$I$5:$I$1804,0))="","",INDEX(Bolalar!$C$5:$C$1804,MATCH($C11,Bolalar!$I$5:$I$1804,0))),"")) | G11: =IF(OR($E11="",$B11=""),"",INT(($B11-$E11)/365.25)) | H11: =IF($G11="","",IF($G11<5,"Ha","Yo'q")) | I11: =IF($G11="","",IF($G11<18,"Ha","Yo'q"))
A12: 8 | D12: =IF($C12="","",IFERROR(IF(INDEX(Bolalar!$B$5:$B$1804,MATCH($C12,Bolalar!$I$5:$I$1804,0))="","",INDEX(Bolalar!$B$5:$B$1804,MATCH($C12,Bolalar!$I$5:$I$1804,0))),"")) | E12: =IF($C12="","",IFERROR(IF(INDEX(Bolalar!$C$5:$C$1804,MATCH($C12,Bolalar!$I$5:$I$1804,0))="","",INDEX(Bolalar!$C$5:$C$1804,MATCH($C12,Bolalar!$I$5:$I$1804,0))),"")) | G12: =IF(OR($E12="",$B12=""),"",INT(($B12-$E12)/365.25)) | H12: =IF($G12="","",IF($G12<5,"Ha","Yo'q")) | I12: =IF($G12="","",IF($G12<18,"Ha","Yo'q"))
A13: 9 | D13: =IF($C13="","",IFERROR(IF(INDEX(Bolalar!$B$5:$B$1804,MATCH($C13,Bolalar!$I$5:$I$1804,0))="","",INDEX(Bolalar!$B$5:$B$1804,MATCH($C13,Bolalar!$I$5:$I$1804,0))),"")) | E13: =IF($C13="","",IFERROR(IF(INDEX(Bolalar!$C$5:$C$1804,MATCH($C13,Bolalar!$I$5:$I$1804,0))="","",INDEX(Bolalar!$C$5:$C$1804,MATCH($C13,Bolalar!$I$5:$I$1804,0))),"")) | G13: =IF(OR($E13="",$B13=""),"",INT(($B13-$E13)/365.25)) | H13: =IF($G13="","",IF($G13<5,"Ha","Yo'q")) | I13: =IF($G13="","",IF($G13<18,"Ha","Yo'q"))
A14: 10 | D14: =IF($C14="","",IFERROR(IF(INDEX(Bolalar!$B$5:$B$1804,MATCH($C14,Bolalar!$I$5:$I$1804,0))="","",INDEX(Bolalar!$B$5:$B$1804,MATCH($C14,Bolalar!$I$5:$I$1804,0))),"")) | E14: =IF($C14="","",IFERROR(IF(INDEX(Bolalar!$C$5:$C$1804,MATCH($C14,Bolalar!$I$5:$I$1804,0))="","",INDEX(Bolalar!$C$5:$C$1804,MATCH($C14,Bolalar!$I$5:$I$1804,0))),"")) | G14: =IF(OR($E14="",$B14=""),"",INT(($B14-$E14)/365.25)) | H14: =IF($G14="","",IF($G14<5,"Ha","Yo'q")) | I14: =IF($G14="","",IF($G14<18,"Ha","Yo'q"))
A15: 11 | D15: =IF($C15="","",IFERROR(IF(INDEX(Bolalar!$B$5:$B$1804,MATCH($C15,Bolalar!$I$5:$I$1804,0))="","",INDEX(Bolalar!$B$5:$B$1804,MATCH($C15,Bolalar!$I$5:$I$1804,0))),"")) | E15: =IF($C15="","",IFERROR(IF(INDEX(Bolalar!$C$5:$C$1804,MATCH($C15,Bolalar!$I$5:$I$1804,0))="","",INDEX(Bolalar!$C$5:$C$1804,MATCH($C15,Bolalar!$I$5:$I$1804,0))),"")) | G15: =IF(OR($E15="",$B15=""),"",INT(($B15-$E15)/365.25)) | H15: =IF($G15="","",IF($G15<5,"Ha","Yo'q")) | I15: =IF($G15="","",IF($G15<18,"Ha","Yo'q"))
A16: 12 | D16: =IF($C16="","",IFERROR(IF(INDEX(Bolalar!$B$5:$B$1804,MATCH($C16,Bolalar!$I$5:$I$1804,0))="","",INDEX(Bolalar!$B$5:$B$1804,MATCH($C16,Bolalar!$I$5:$I$1804,0))),"")) | E16: =IF($C16="","",IFERROR(IF(INDEX(Bolalar!$C$5:$C$1804,MATCH($C16,Bolalar!$I$5:$I$1804,0))="","",INDEX(Bolalar!$C$5:$C$1804,MATCH($C16,Bolalar!$I$5:$I$1804,0))),"")) | G16: =IF(OR($E16="",$B16=""),"",INT(($B16-$E16)/365.25)) | H16: =IF($G16="","",IF($G16<5,"Ha","Yo'q")) | I16: =IF($G16="","",IF($G16<18,"Ha","Yo'q"))
... A104: 100 | D104: =IF($C104="","",IFERROR(IF(INDEX(Bolalar!$B$5:$B$1804,MATCH($C104,Bolalar!$I$5:$I$1804,0))="","",INDEX(Bolalar!$B$5:$B$1804,MATCH($C104,Bolalar!$I$5:$I$1804,0))),"")) | E104: =IF($C104="","",IFERROR(IF(INDEX(Bolalar!$C$5:$C$1804,MATCH($C104,Bolalar!$I$5:$I$1804,0))="","",INDEX(Bolalar!$C$5:$C$1804,MATCH($C104,Bolalar!$I$5:$I$1804,0))),"")) | G104: =IF(OR($E104="",$B104=""),"",INT(($B104-$E104)/365.25)) | H104: =IF($G104="","",IF($G104<5,"Ha","Yo'q")) | I104: =IF($G104="","",IF($G104<18,"Ha","Yo'q"))

Sheet Yangi_tugilgan
A1: YANGI TUG‘ILGANLAR PATRONAJI / ПАТРОНАЖ НОВОРОЖДЁННЫХ
A2: Tug‘ruqxonadan chiqish sanasi va 1-patronaj sanasini yozing — muddat (kun) avto tekshiriladi. / Укажите дату выписки и дату 1-го патронажа — срок (дни) проверяется автоматически.
A3: MAXFIY / КОНФИДЕНЦИАЛЬНО — shaxsiy va tibbiy ma’lumotlar (shifokorlik siri). Faylni parol bilan himoyalang, ochiq guruhlarga yubormang. / Персональные и медицинские данные (врачебная тайна). Защитите файл паролем, не отправляйте в открытые группы.
A4: № | B4: Chaqaloq F.I.Sh. Ф.И.О. новорождённого | C4: Tug‘ilgan sana Дата рождения | D4: PINFL (14 raqam) ПИНФЛ (14 цифр) | E4: Ona F.I.Sh. Ф.И.О. матери | F4: Telefon Телефон | G4: Mahalla Махалля | H4: Tug‘ruqxonadan chiqqan sana Дата выписки из роддома | I4: 1-patronaj sanasi Дата 1-го патронажа | J4: Chiqqandan keyin necha kun? (avto) Дней после выписки (авто) | K4: Muddatida? (avto) В срок? (авто) | L4: Patronaj qilinmagan (muddat o‘tgan)? (avto) Патронаж не проведён (срок прошёл)? | M4: Izoh Примечание | N4: Takror? (avto) Дубль? | O4: Patronaj jurnalida yo‘q (1) Нет в журнале патронажа (1)
A5: 1 | J5: =IF(OR($H5="",$I5=""),"",$I5-$H5) | K5: =IF(OR($H5="",$I5=""),"",IF($I5-$H5<=Spravochnik!$E$5,"Ha","Yo'q")) | L5: =IF(AND($B5<>"",$H5<>"",$I5="",Boshqaruv!$C$12-$H5>Spravochnik!$E$5),"Ha","") | N5: =IF(OR($B5="",$C5=""),"",IF(COUNTIFS($B$5:$B$604,$B5,$C$5:$C$604,$C5)>1,"Takror","")) | O5: =IF(AND($B5<>"",$I5>=Boshqaruv!$C$9,$I5<=Boshqaruv!$C$10),IF(COUNTIFS(Patronaj_0_5!$D$5:$D$2504,$B5,Patronaj_0_5!$E$5:$E$2504,$C5,Patronaj_0_5!$H$5:$H$2504,"Ha",Patronaj_0_5!$B$5:$B$2504,">="&Boshqaruv!$C$9,Patronaj_0_5!$B$5:$B$2504,"<="&Boshqaruv!$C$10)=0,1,0),0) -> 0
A6: 2 | J6: =IF(OR($H6="",$I6=""),"",$I6-$H6) | K6: =IF(OR($H6="",$I6=""),"",IF($I6-$H6<=Spravochnik!$E$5,"Ha","Yo'q")) | L6: =IF(AND($B6<>"",$H6<>"",$I6="",Boshqaruv!$C$12-$H6>Spravochnik!$E$5),"Ha","") | N6: =IF(OR($B6="",$C6=""),"",IF(COUNTIFS($B$5:$B$604,$B6,$C$5:$C$604,$C6)>1,"Takror","")) | O6: =IF(AND($B6<>"",$I6>=Boshqaruv!$C$9,$I6<=Boshqaruv!$C$10),IF(COUNTIFS(Patronaj_0_5!$D$5:$D$2504,$B6,Patronaj_0_5!$E$5:$E$2504,$C6,Patronaj_0_5!$H$5:$H$2504,"Ha",Patronaj_0_5!$B$5:$B$2504,">="&Boshqaruv!$C$9,Patronaj_0_5!$B$5:$B$2504,"<="&Boshqaruv!$C$10)=0,1,0),0) -> 0
A7: 3 | J7: =IF(OR($H7="",$I7=""),"",$I7-$H7) | K7: =IF(OR($H7="",$I7=""),"",IF($I7-$H7<=Spravochnik!$E$5,"Ha","Yo'q")) | L7: =IF(AND($B7<>"",$H7<>"",$I7="",Boshqaruv!$C$12-$H7>Spravochnik!$E$5),"Ha","") | N7: =IF(OR($B7="",$C7=""),"",IF(COUNTIFS($B$5:$B$604,$B7,$C$5:$C$604,$C7)>1,"Takror","")) | O7: =IF(AND($B7<>"",$I7>=Boshqaruv!$C$9,$I7<=Boshqaruv!$C$10),IF(COUNTIFS(Patronaj_0_5!$D$5:$D$2504,$B7,Patronaj_0_5!$E$5:$E$2504,$C7,Patronaj_0_5!$H$5:$H$2504,"Ha",Patronaj_0_5!$B$5:$B$2504,">="&Boshqaruv!$C$9,Patronaj_0_5!$B$5:$B$2504,"<="&Boshqaruv!$C$10)=0,1,0),0) -> 0
A8: 4 | J8: =IF(OR($H8="",$I8=""),"",$I8-$H8) | K8: =IF(OR($H8="",$I8=""),"",IF($I8-$H8<=Spravochnik!$E$5,"Ha","Yo'q")) | L8: =IF(AND($B8<>"",$H8<>"",$I8="",Boshqaruv!$C$12-$H8>Spravochnik!$E$5),"Ha","") | N8: =IF(OR($B8="",$C8=""),"",IF(COUNTIFS($B$5:$B$604,$B8,$C$5:$C$604,$C8)>1,"Takror","")) | O8: =IF(AND($B8<>"",$I8>=Boshqaruv!$C$9,$I8<=Boshqaruv!$C$10),IF(COUNTIFS(Patronaj_0_5!$D$5:$D$2504,$B8,Patronaj_0_5!$E$5:$E$2504,$C8,Patronaj_0_5!$H$5:$H$2504,"Ha",Patronaj_0_5!$B$5:$B$2504,">="&Boshqaruv!$C$9,Patronaj_0_5!$B$5:$B$2504,"<="&Boshqaruv!$C$10)=0,1,0),0) -> 0
A9: 5 | J9: =IF(OR($H9="",$I9=""),"",$I9-$H9) | K9: =IF(OR($H9="",$I9=""),"",IF($I9-$H9<=Spravochnik!$E$5,"Ha","Yo'q")) | L9: =IF(AND($B9<>"",$H9<>"",$I9="",Boshqaruv!$C$12-$H9>Spravochnik!$E$5),"Ha","") | N9: =IF(OR($B9="",$C9=""),"",IF(COUNTIFS($B$5:$B$604,$B9,$C$5:$C$604,$C9)>1,"Takror","")) | O9: =IF(AND($B9<>"",$I9>=Boshqaruv!$C$9,$I9<=Boshqaruv!$C$10),IF(COUNTIFS(Patronaj_0_5!$D$5:$D$2504,$B9,Patronaj_0_5!$E$5:$E$2504,$C9,Patronaj_0_5!$H$5:$H$2504,"Ha",Patronaj_0_5!$B$5:$B$2504,">="&Boshqaruv!$C$9,Patronaj_0_5!$B$5:$B$2504,"<="&Boshqaruv!$C$10)=0,1,0),0) -> 0
A10: 6 | J10: =IF(OR($H10="",$I10=""),"",$I10-$H10) | K10: =IF(OR($H10="",$I10=""),"",IF($I10-$H10<=Spravochnik!$E$5,"Ha","Yo'q")) | L10: =IF(AND($B10<>"",$H10<>"",$I10="",Boshqaruv!$C$12-$H10>Spravochnik!$E$5),"Ha","") | N10: =IF(OR($B10="",$C10=""),"",IF(COUNTIFS($B$5:$B$604,$B10,$C$5:$C$604,$C10)>1,"Takror","")) | O10: =IF(AND($B10<>"",$I10>=Boshqaruv!$C$9,$I10<=Boshqaruv!$C$10),IF(COUNTIFS(Patronaj_0_5!$D$5:$D$2504,$B10,Patronaj_0_5!$E$5:$E$2504,$C10,Patronaj_0_5!$H$5:$H$2504,"Ha",Patronaj_0_5!$B$5:$B$2504,">="&Boshqaruv!$C$9,Patronaj_0_5!$B$5:$B$2504,"<="&Boshqaruv!$C$10)=0,1,0),0) -> 0
A11: 7 | J11: =IF(OR($H11="",$I11=""),"",$I11-$H11) | K11: =IF(OR($H11="",$I11=""),"",IF($I11-$H11<=Spravochnik!$E$5,"Ha","Yo'q")) | L11: =IF(AND($B11<>"",$H11<>"",$I11="",Boshqaruv!$C$12-$H11>Spravochnik!$E$5),"Ha","") | N11: =IF(OR($B11="",$C11=""),"",IF(COUNTIFS($B$5:$B$604,$B11,$C$5:$C$604,$C11)>1,"Takror","")) | O11: =IF(AND($B11<>"",$I11>=Boshqaruv!$C$9,$I11<=Boshqaruv!$C$10),IF(COUNTIFS(Patronaj_0_5!$D$5:$D$2504,$B11,Patronaj_0_5!$E$5:$E$2504,$C11,Patronaj_0_5!$H$5:$H$2504,"Ha",Patronaj_0_5!$B$5:$B$2504,">="&Boshqaruv!$C$9,Patronaj_0_5!$B$5:$B$2504,"<="&Boshqaruv!$C$10)=0,1,0),0) -> 0
A12: 8 | J12: =IF(OR($H12="",$I12=""),"",$I12-$H12) | K12: =IF(OR($H12="",$I12=""),"",IF($I12-$H12<=Spravochnik!$E$5,"Ha","Yo'q")) | L12: =IF(AND($B12<>"",$H12<>"",$I12="",Boshqaruv!$C$12-$H12>Spravochnik!$E$5),"Ha","") | N12: =IF(OR($B12="",$C12=""),"",IF(COUNTIFS($B$5:$B$604,$B12,$C$5:$C$604,$C12)>1,"Takror","")) | O12: =IF(AND($B12<>"",$I12>=Boshqaruv!$C$9,$I12<=Boshqaruv!$C$10),IF(COUNTIFS(Patronaj_0_5!$D$5:$D$2504,$B12,Patronaj_0_5!$E$5:$E$2504,$C12,Patronaj_0_5!$H$5:$H$2504,"Ha",Patronaj_0_5!$B$5:$B$2504,">="&Boshqaruv!$C$9,Patronaj_0_5!$B$5:$B$2504,"<="&Boshqaruv!$C$10)=0,1,0),0) -> 0
A13: 9 | J13: =IF(OR($H13="",$I13=""),"",$I13-$H13) | K13: =IF(OR($H13="",$I13=""),"",IF($I13-$H13<=Spravochnik!$E$5,"Ha","Yo'q")) | L13: =IF(AND($B13<>"",$H13<>"",$I13="",Boshqaruv!$C$12-$H13>Spravochnik!$E$5),"Ha","") | N13: =IF(OR($B13="",$C13=""),"",IF(COUNTIFS($B$5:$B$604,$B13,$C$5:$C$604,$C13)>1,"Takror","")) | O13: =IF(AND($B13<>"",$I13>=Boshqaruv!$C$9,$I13<=Boshqaruv!$C$10),IF(COUNTIFS(Patronaj_0_5!$D$5:$D$2504,$B13,Patronaj_0_5!$E$5:$E$2504,$C13,Patronaj_0_5!$H$5:$H$2504,"Ha",Patronaj_0_5!$B$5:$B$2504,">="&Boshqaruv!$C$9,Patronaj_0_5!$B$5:$B$2504,"<="&Boshqaruv!$C$10)=0,1,0),0) -> 0
A14: 10 | J14: =IF(OR($H14="",$I14=""),"",$I14-$H14) | K14: =IF(OR($H14="",$I14=""),"",IF($I14-$H14<=Spravochnik!$E$5,"Ha","Yo'q")) | L14: =IF(AND($B14<>"",$H14<>"",$I14="",Boshqaruv!$C$12-$H14>Spravochnik!$E$5),"Ha","") | N14: =IF(OR($B14="",$C14=""),"",IF(COUNTIFS($B$5:$B$604,$B14,$C$5:$C$604,$C14)>1,"Takror","")) | O14: =IF(AND($B14<>"",$I14>=Boshqaruv!$C$9,$I14<=Boshqaruv!$C$10),IF(COUNTIFS(Patronaj_0_5!$D$5:$D$2504,$B14,Patronaj_0_5!$E$5:$E$2504,$C14,Patronaj_0_5!$H$5:$H$2504,"Ha",Patronaj_0_5!$B$5:$B$2504,">="&Boshqaruv!$C$9,Patronaj_0_5!$B$5:$B$2504,"<="&Boshqaruv!$C$10)=0,1,0),0) -> 0
A15: 11 | J15: =IF(OR($H15="",$I15=""),"",$I15-$H15) | K15: =IF(OR($H15="",$I15=""),"",IF($I15-$H15<=Spravochnik!$E$5,"Ha","Yo'q")) | L15: =IF(AND($B15<>"",$H15<>"",$I15="",Boshqaruv!$C$12-$H15>Spravochnik!$E$5),"Ha","") | N15: =IF(OR($B15="",$C15=""),"",IF(COUNTIFS($B$5:$B$604,$B15,$C$5:$C$604,$C15)>1,"Takror","")) | O15: =IF(AND($B15<>"",$I15>=Boshqaruv!$C$9,$I15<=Boshqaruv!$C$10),IF(COUNTIFS(Patronaj_0_5!$D$5:$D$2504,$B15,Patronaj_0_5!$E$5:$E$2504,$C15,Patronaj_0_5!$H$5:$H$2504,"Ha",Patronaj_0_5!$B$5:$B$2504,">="&Boshqaruv!$C$9,Patronaj_0_5!$B$5:$B$2504,"<="&Boshqaruv!$C$10)=0,1,0),0) -> 0
A16: 12 | J16: =IF(OR($H16="",$I16=""),"",$I16-$H16) | K16: =IF(OR($H16="",$I16=""),"",IF($I16-$H16<=Spravochnik!$E$5,"Ha","Yo'q")) | L16: =IF(AND($B16<>"",$H16<>"",$I16="",Boshqaruv!$C$12-$H16>Spravochnik!$E$5),"Ha","") | N16: =IF(OR($B16="",$C16=""),"",IF(COUNTIFS($B$5:$B$604,$B16,$C$5:$C$604,$C16)>1,"Takror","")) | O16: =IF(AND($B16<>"",$I16>=Boshqaruv!$C$9,$I16<=Boshqaruv!$C$10),IF(COUNTIFS(Patronaj_0_5!$D$5:$D$2504,$B16,Patronaj_0_5!$E$5:$E$2504,$C16,Patronaj_0_5!$H$5:$H$2504,"Ha",Patronaj_0_5!$B$5:$B$2504,">="&Boshqaruv!$C$9,Patronaj_0_5!$B$5:$B$2504,"<="&Boshqaruv!$C$10)=0,1,0),0) -> 0
... A604: 600 | J604: =IF(OR($H604="",$I604=""),"",$I604-$H604) | K604: =IF(OR($H604="",$I604=""),"",IF($I604-$H604<=Spravochnik!$E$5,"Ha","Yo'q")) | L604: =IF(AND($B604<>"",$H604<>"",$I604="",Boshqaruv!$C$12-$H604>Spravochnik!$E$5),"Ha","") | N604: =IF(OR($B604="",$C604=""),"",IF(COUNTIFS($B$5:$B$604,$B604,$C$5:$C$604,$C604)>1,"Takror","")) | O604: =IF(AND($B604<>"",$I604>=Boshqaruv!$C$9,$I604<=Boshqaruv!$C$10),IF(COUNTIFS(Patronaj_0_5!$D$5:$D$2504,$B604,Patronaj_0_5!$E$5:$E$2504,$C604,Patronaj_0_5!$H$5:$H$2504,"Ha",Patronaj_0_5!$B$5:$B$2504,">="&Boshqaruv!$C$9,Patronaj_0_5!$B$5:$B$2504,"<="&Boshqaruv!$C$10)=0,1,0),0) -> 0

Sheet Patronaj_0_5
A1: 0–5 YOSHLI BOLALAR PATRONAJI / ПАТРОНАЖ ДЕТЕЙ 0–5 ЛЕТ
A2: Har bir patronaj tashrifi — bitta qator; bola «Bolalar» ro‘yxatidan tanlanadi. Har bir bola bir marta sanaladi. / Каждое посещение — одна строка; ребёнок из «Bolalar». Каждый ребёнок считается один раз.
A3: MAXFIY / КОНФИДЕНЦИАЛЬНО — shaxsiy va tibbiy ma’lumotlar (shifokorlik siri). Faylni parol bilan himoyalang, ochiq guruhlarga yubormang. / Персональные и медицинские данные (врачебная тайна). Защитите файл паролем, не отправляйте в открытые группы.
A4: № | B4: Tashrif sanasi Дата посещения | C4: Shaxs (ro‘yxatdan tanlang) Человек (выбрать из списка) | D4: Bola F.I.Sh. (avto) Ф.И.О. (авто) | E4: Tug‘ilgan sana (avto) Дата рожд. (авто) | F4: PINFL (14 raqam) ПИНФЛ (14 цифр) | G4: Yosh (avto) Возраст | H4: 0–5 yosh? (avto) 0–5 лет? | I4: Topilmalar / maslahat Находки / советы | J4: Izoh Примечание | K4: Davrda birinchi (1) Первый в периоде (1)
A5: 1 | D5: =IF($C5="","",IFERROR(IF(INDEX(Bolalar!$B$5:$B$1804,MATCH($C5,Bolalar!$I$5:$I$1804,0))="","",INDEX(Bolalar!$B$5:$B$1804,MATCH($C5,Bolalar!$I$5:$I$1804,0))),"")) | E5: =IF($C5="","",IFERROR(IF(INDEX(Bolalar!$C$5:$C$1804,MATCH($C5,Bolalar!$I$5:$I$1804,0))="","",INDEX(Bolalar!$C$5:$C$1804,MATCH($C5,Bolalar!$I$5:$I$1804,0))),"")) | G5: =IF(OR($E5="",$B5=""),"",INT(($B5-$E5)/365.25)) | H5: =IF($G5="","",IF($G5<=5,"Ha","Yo'q")) | K5: =IF(AND($C5<>"",$H5="Ha",$B5>=Boshqaruv!$C$9,$B5<=Boshqaruv!$C$10),IF(COUNTIFS($C$4:$C4,$C5,$H$4:$H4,"Ha",$B$4:$B4,">="&Boshqaruv!$C$9,$B$4:$B4,"<="&Boshqaruv!$C$10)=0,1,0),0) -> 0
A6: 2 | D6: =IF($C6="","",IFERROR(IF(INDEX(Bolalar!$B$5:$B$1804,MATCH($C6,Bolalar!$I$5:$I$1804,0))="","",INDEX(Bolalar!$B$5:$B$1804,MATCH($C6,Bolalar!$I$5:$I$1804,0))),"")) | E6: =IF($C6="","",IFERROR(IF(INDEX(Bolalar!$C$5:$C$1804,MATCH($C6,Bolalar!$I$5:$I$1804,0))="","",INDEX(Bolalar!$C$5:$C$1804,MATCH($C6,Bolalar!$I$5:$I$1804,0))),"")) | G6: =IF(OR($E6="",$B6=""),"",INT(($B6-$E6)/365.25)) | H6: =IF($G6="","",IF($G6<=5,"Ha","Yo'q")) | K6: =IF(AND($C6<>"",$H6="Ha",$B6>=Boshqaruv!$C$9,$B6<=Boshqaruv!$C$10),IF(COUNTIFS($C$4:$C5,$C6,$H$4:$H5,"Ha",$B$4:$B5,">="&Boshqaruv!$C$9,$B$4:$B5,"<="&Boshqaruv!$C$10)=0,1,0),0) -> 0
A7: 3 | D7: =IF($C7="","",IFERROR(IF(INDEX(Bolalar!$B$5:$B$1804,MATCH($C7,Bolalar!$I$5:$I$1804,0))="","",INDEX(Bolalar!$B$5:$B$1804,MATCH($C7,Bolalar!$I$5:$I$1804,0))),"")) | E7: =IF($C7="","",IFERROR(IF(INDEX(Bolalar!$C$5:$C$1804,MATCH($C7,Bolalar!$I$5:$I$1804,0))="","",INDEX(Bolalar!$C$5:$C$1804,MATCH($C7,Bolalar!$I$5:$I$1804,0))),"")) | G7: =IF(OR($E7="",$B7=""),"",INT(($B7-$E7)/365.25)) | H7: =IF($G7="","",IF($G7<=5,"Ha","Yo'q")) | K7: =IF(AND($C7<>"",$H7="Ha",$B7>=Boshqaruv!$C$9,$B7<=Boshqaruv!$C$10),IF(COUNTIFS($C$4:$C6,$C7,$H$4:$H6,"Ha",$B$4:$B6,">="&Boshqaruv!$C$9,$B$4:$B6,"<="&Boshqaruv!$C$10)=0,1,0),0) -> 0
A8: 4 | D8: =IF($C8="","",IFERROR(IF(INDEX(Bolalar!$B$5:$B$1804,MATCH($C8,Bolalar!$I$5:$I$1804,0))="","",INDEX(Bolalar!$B$5:$B$1804,MATCH($C8,Bolalar!$I$5:$I$1804,0))),"")) | E8: =IF($C8="","",IFERROR(IF(INDEX(Bolalar!$C$5:$C$1804,MATCH($C8,Bolalar!$I$5:$I$1804,0))="","",INDEX(Bolalar!$C$5:$C$1804,MATCH($C8,Bolalar!$I$5:$I$1804,0))),"")) | G8: =IF(OR($E8="",$B8=""),"",INT(($B8-$E8)/365.25)) | H8: =IF($G8="","",IF($G8<=5,"Ha","Yo'q")) | K8: =IF(AND($C8<>"",$H8="Ha",$B8>=Boshqaruv!$C$9,$B8<=Boshqaruv!$C$10),IF(COUNTIFS($C$4:$C7,$C8,$H$4:$H7,"Ha",$B$4:$B7,">="&Boshqaruv!$C$9,$B$4:$B7,"<="&Boshqaruv!$C$10)=0,1,0),0) -> 0
A9: 5 | D9: =IF($C9="","",IFERROR(IF(INDEX(Bolalar!$B$5:$B$1804,MATCH($C9,Bolalar!$I$5:$I$1804,0))="","",INDEX(Bolalar!$B$5:$B$1804,MATCH($C9,Bolalar!$I$5:$I$1804,0))),"")) | E9: =IF($C9="","",IFERROR(IF(INDEX(Bolalar!$C$5:$C$1804,MATCH($C9,Bolalar!$I$5:$I$1804,0))="","",INDEX(Bolalar!$C$5:$C$1804,MATCH($C9,Bolalar!$I$5:$I$1804,0))),"")) | G9: =IF(OR($E9="",$B9=""),"",INT(($B9-$E9)/365.25)) | H9: =IF($G9="","",IF($G9<=5,"Ha","Yo'q")) | K9: =IF(AND($C9<>"",$H9="Ha",$B9>=Boshqaruv!$C$9,$B9<=Boshqaruv!$C$10),IF(COUNTIFS($C$4:$C8,$C9,$H$4:$H8,"Ha",$B$4:$B8,">="&Boshqaruv!$C$9,$B$4:$B8,"<="&Boshqaruv!$C$10)=0,1,0),0) -> 0
A10: 6 | D10: =IF($C10="","",IFERROR(IF(INDEX(Bolalar!$B$5:$B$1804,MATCH($C10,Bolalar!$I$5:$I$1804,0))="","",INDEX(Bolalar!$B$5:$B$1804,MATCH($C10,Bolalar!$I$5:$I$1804,0))),"")) | E10: =IF($C10="","",IFERROR(IF(INDEX(Bolalar!$C$5:$C$1804,MATCH($C10,Bolalar!$I$5:$I$1804,0))="","",INDEX(Bolalar!$C$5:$C$1804,MATCH($C10,Bolalar!$I$5:$I$1804,0))),"")) | G10: =IF(OR($E10="",$B10=""),"",INT(($B10-$E10)/365.25)) | H10: =IF($G10="","",IF($G10<=5,"Ha","Yo'q")) | K10: =IF(AND($C10<>"",$H10="Ha",$B10>=Boshqaruv!$C$9,$B10<=Boshqaruv!$C$10),IF(COUNTIFS($C$4:$C9,$C10,$H$4:$H9,"Ha",$B$4:$B9,">="&Boshqaruv!$C$9,$B$4:$B9,"<="&Boshqaruv!$C$10)=0,1,0),0) -> 0
